<?xml version="1.0" encoding="utf-8"?>
<!-- This URDF was automatically created by SolidWorks to URDF Exporter! Originally created by Stephen Brawner (brawner@gmail.com) 
     Commit Version: 1.6.0-4-g7f85cfe  Build Version: 1.6.7995.38578
     For more information, please see http://wiki.ros.org/sw_urdf_exporter -->
<robot
  name="jointT-l.SLDASM">
  <link
    name="tj_out">
    <inertial>
      <origin
        xyz="-0.0026095 1.0123E-08 -0.0735"
        rpy="0 0 0" />
      <mass
        value="1.5884" />
      <inertia
        ixx="0.004117"
        ixy="2.097E-09"
        ixz="-8.5243E-19"
        iyy="0.0041567"
        iyz="-4.7613E-10"
        izz="0.0027805" />
    </inertial>
    <visual>
      <origin
        xyz="0 0 0"
        rpy="0 0 0" />
      <geometry>
        <mesh
          filename="package://jointT-l.SLDASM/meshes/tj_out.STL" />
      </geometry>
      <material
        name="red">
        <color
          rgba="0.5 0 0 1" />
      </material>
    </visual>
    <collision>
      <origin
        xyz="0 0 0"
        rpy="0 0 0" />
      <geometry>
        <mesh
          filename="package://jointT-l.SLDASM/meshes/tj_out.STL" />
      </geometry>
    </collision>
  </link>
  <link
    name="tj_body">
    <inertial>
      <origin
        xyz="-0.0026078 -7.1138E-08 -0.0735"
        rpy="0 0 0" />
      <mass
        value="1.5884" />
      <inertia
        ixx="0.004117"
        ixy="2.097E-09"
        ixz="-8.5243E-19"
        iyy="0.0041567"
        iyz="-4.7613E-10"
        izz="0.0027805" />
    </inertial>
    <visual>
      <origin
        xyz="0 0 0"
        rpy="0 0 0" />
      <geometry>
        <mesh
          filename="package://jointT-l.SLDASM/meshes/tj_body.STL" />
      </geometry>
      <material
        name="body">
        <color
          rgba="0.5 0.5 0.5 1" />
      </material>
    </visual>
    <collision>
      <origin
        xyz="0 0 0"
        rpy="0 0 0" />
      <geometry>
        <mesh
          filename="package://jointT-l.SLDASM/meshes/tj_body.STL" />
      </geometry>
    </collision>
  </link>
  <joint
    name="tj_large_1"
    type="revolute">
    <origin
      xyz="0 0 0"
      rpy="0 0 0" />
    <parent
      link="tj_out" />
    <child
      link="tj_body" />
    <axis
      xyz="0 0 1" />
    <limit
      lower="-3.1416"
      upper="3.1416"
      effort="60.5"
      velocity="0.33" />
  </joint>
  <link
    name="tj_in">
    <inertial>
      <origin
        xyz="-1.904E-18 1.0123E-08 0.05439"
        rpy="0 0 0" />
      <mass
        value="1.5884" />
      <inertia
        ixx="0.0027805"
        ixy="4.7613E-10"
        ixz="8.5243E-19"
        iyy="0.0041567"
        iyz="2.097E-09"
        izz="0.004117" />
    </inertial>
    <visual>
      <origin
        xyz="0 0 0"
        rpy="0 0 0" />
      <geometry>
        <mesh
          filename="package://jointT-l.SLDASM/meshes/tj_in.STL" />
      </geometry>
      <material
        name="blue">
        <color
          rgba="0 0 0.5 1" />
      </material>
    </visual>
    <collision>
      <origin
        xyz="0 0 0"
        rpy="0 0 0" />
      <geometry>
        <mesh
          filename="package://jointT-l.SLDASM/meshes/tj_in.STL" />
      </geometry>
    </collision>
  </link>
  <joint
    name="tj_large_2"
    type="fixed">
    <origin
      xyz="-0.057 0 -0.0735"
      rpy="0 1.5707963267949 0" />
    <parent
      link="tj_body" />
    <child
      link="tj_in" />
    <axis
      xyz="0 0 0" />
  </joint>
</robot>