<?xml version="1.0"?>
<robot  name="UNNAMED_224" >
 <link  name="BASEM4147_BASEM23594_BASEM23594_BASEM23594_BASEM23594_BASEM23594_BASEM23594_BASEM23594_b_body" >
  <inertial >
   <origin  xyz="-1.2862E-17 -2.139E-18 0.018175"  rpy="0 0 0" />
   <mass  value="0.5" />
   <inertia  iyz="-2.2352E-19"  izz="0.0060699"  iyy="0.0034892"  ixy="-6.7063E-20"  ixz="-2.7087E-19"  ixx="0.0034892" />
  </inertial>
  <visual >
   <origin  xyz="0 0 0"  rpy="0 0 0" />
   <geometry >
    <mesh  filename="package://base-m.SLDASM/meshes/b_body.STL" />
   </geometry>
   <material  name="body" >
    <color  rgba="0.5 0.5 0.5 1" />
   </material>
  </visual>
  <collision >
   <origin  xyz="0 0 0"  rpy="0 0 0" />
   <geometry >
    <mesh  filename="package://base-m.SLDASM/meshes/b_body.STL" />
   </geometry>
  </collision>
 </link>
 <link  name="BASEM4147_BASEM23594_BASEM23594_BASEM23594_BASEM23594_BASEM23594_BASEM23594_BASEM23594_b_in" >
  <inertial >
   <origin  xyz="-1.2862E-17 1.7762E-17 0.024125"  rpy="0 0 0" />
   <mass  value="3.3499" />
   <inertia  iyz="-2.2352E-19"  izz="0.0060699"  iyy="0.0034892"  ixy="6.7063E-20"  ixz="2.7087E-19"  ixx="0.0034892" />
  </inertial>
  <visual >
   <origin  xyz="0 0 0"  rpy="0 0 0" />
   <geometry >
    <mesh  filename="package://base-m.SLDASM/meshes/b_in.STL" />
   </geometry>
   <material  name="blue" >
    <color  rgba="0 0 0.5 1" />
   </material>
  </visual>
  <collision >
   <origin  xyz="0 0 0"  rpy="0 0 0" />
   <geometry >
    <mesh  filename="package://base-m.SLDASM/meshes/b_in.STL" />
   </geometry>
  </collision>
 </link>
 <link  name="BASEM4147_BASEM23594_BASEM23594_BASEM23594_BASEM23594_BASEM23594_BASEM23594_CONNECTORM114404_ic_body" >
  <inertial >
   <origin  xyz="0 -4.8218E-18 -0.0047"  rpy="0 0 0" />
   <mass  value="0" />
   <inertia  iyz="0"  izz="0.000562"  iyy="0.00028474"  ixy="0"  ixz="2.1721E-37"  ixx="0.00028474" />
  </inertial>
  <visual >
   <origin  xyz="0 0 0"  rpy="0 0 0" />
   <geometry >
    <mesh  filename="package://input_connector_m.SLDASM/meshes/ic_body.STL" />
   </geometry>
   <material  name="blue" >
    <color  rgba="0 0 0.5 1" />
   </material>
  </visual>
  <collision >
   <origin  xyz="0 0 0"  rpy="0 0 0" />
   <geometry >
    <mesh  filename="package://input_connector_m.SLDASM/meshes/ic_body.STL" />
   </geometry>
  </collision>
 </link>
 <link  name="BASEM4147_BASEM23594_BASEM23594_BASEM23594_BASEM23594_BASEM23594_BASEM23594_CONNECTORM114404_ic_in" >
  <inertial >
   <origin  xyz="-4.5413E-34 1.0801E-17 0.0047"  rpy="0 0 0" />
   <mass  value="0.50882" />
   <inertia  iyz="0"  izz="0.000562"  iyy="0.00028474"  ixy="0"  ixz="2.1721E-37"  ixx="0.00028474" />
  </inertial>
  <visual >
   <origin  xyz="0 0 0"  rpy="0 0 0" />
   <geometry >
    <mesh  filename="package://input_connector_m.SLDASM/meshes/ic_in.STL" />
   </geometry>
   <material  name="blue" >
    <color  rgba="0 0 0.5 1" />
   </material>
  </visual>
  <collision >
   <origin  xyz="0 0 0"  rpy="0 0 0" />
   <geometry >
    <mesh  filename="package://input_connector_m.SLDASM/meshes/ic_in.STL" />
   </geometry>
  </collision>
 </link>
 <link  name="BASEM4147_BASEM23594_BASEM23594_BASEM23594_BASEM23594_BASEM23594_JOINTM64603_tj_body" >
  <inertial >
   <origin  xyz="-0.0020574 -5.8806E-08 -0.0635"  rpy="0 0 0" />
   <mass  value="0.93065" />
   <inertia  iyz="-1.9911E-10"  izz="0.0011044"  iyy="0.0017615"  ixy="8.3821E-10"  ixz="1.078E-20"  ixx="0.0017462" />
  </inertial>
  <visual >
   <origin  xyz="0 0 0"  rpy="0 0 0" />
   <geometry >
    <mesh  filename="package://jointT-m.SLDASM/meshes/tj_body.STL" />
   </geometry>
   <material  name="body" >
    <color  rgba="0.5 0.5 0.5 1" />
   </material>
  </visual>
  <collision >
   <origin  xyz="0 0 0"  rpy="0 0 0" />
   <geometry >
    <mesh  filename="package://jointT-m.SLDASM/meshes/tj_body.STL" />
   </geometry>
  </collision>
 </link>
 <link  name="BASEM4147_BASEM23594_BASEM23594_BASEM23594_BASEM23594_BASEM23594_JOINTM64603_tj_in" >
  <inertial >
   <origin  xyz="-6.5585E-18 8.3685E-09 0.044941"  rpy="0 0 0" />
   <mass  value="0.93066" />
   <inertia  iyz="8.3821E-10"  izz="0.0017462"  iyy="0.0017615"  ixy="1.9911E-10"  ixz="1.0711E-19"  ixx="0.0011044" />
  </inertial>
  <visual >
   <origin  xyz="0 0 0"  rpy="0 0 0" />
   <geometry >
    <mesh  filename="package://jointT-m.SLDASM/meshes/tj_in.STL" />
   </geometry>
   <material  name="blue" >
    <color  rgba="0 0 0.5 1" />
   </material>
  </visual>
  <collision >
   <origin  xyz="0 0 0"  rpy="0 0 0" />
   <geometry >
    <mesh  filename="package://jointT-m.SLDASM/meshes/tj_in.STL" />
   </geometry>
  </collision>
 </link>
 <link  name="BASEM4147_BASEM23594_BASEM23594_BASEM23594_BASEM23594_CONNECTORM114405_ic_body" >
  <inertial >
   <origin  xyz="0 -4.8218E-18 -0.0047"  rpy="0 0 0" />
   <mass  value="0" />
   <inertia  iyz="0"  izz="0.000562"  iyy="0.00028474"  ixy="0"  ixz="2.1721E-37"  ixx="0.00028474" />
  </inertial>
  <visual >
   <origin  xyz="0 0 0"  rpy="0 0 0" />
   <geometry >
    <mesh  filename="package://input_connector_m.SLDASM/meshes/ic_body.STL" />
   </geometry>
   <material  name="blue" >
    <color  rgba="0 0 0.5 1" />
   </material>
  </visual>
  <collision >
   <origin  xyz="0 0 0"  rpy="0 0 0" />
   <geometry >
    <mesh  filename="package://input_connector_m.SLDASM/meshes/ic_body.STL" />
   </geometry>
  </collision>
 </link>
 <link  name="BASEM4147_BASEM23594_BASEM23594_BASEM23594_BASEM23594_CONNECTORM114405_ic_in" >
  <inertial >
   <origin  xyz="-4.5413E-34 1.0801E-17 0.0047"  rpy="0 0 0" />
   <mass  value="0.50882" />
   <inertia  iyz="0"  izz="0.000562"  iyy="0.00028474"  ixy="0"  ixz="2.1721E-37"  ixx="0.00028474" />
  </inertial>
  <visual >
   <origin  xyz="0 0 0"  rpy="0 0 0" />
   <geometry >
    <mesh  filename="package://input_connector_m.SLDASM/meshes/ic_in.STL" />
   </geometry>
   <material  name="blue" >
    <color  rgba="0 0 0.5 1" />
   </material>
  </visual>
  <collision >
   <origin  xyz="0 0 0"  rpy="0 0 0" />
   <geometry >
    <mesh  filename="package://input_connector_m.SLDASM/meshes/ic_in.STL" />
   </geometry>
  </collision>
 </link>
 <link  name="BASEM4147_BASEM23594_BASEM23594_BASEM23594_STRAIGHTLINKMS15785_sl_body" >
  <inertial >
   <origin  xyz="-2.61E-07 7.571E-07 -0.097144"  rpy="0 0 0" />
   <mass  value="0.86346" />
   <inertia  iyz="9.5259E-09"  izz="0.00060028"  iyy="0.0033145"  ixy="3.4516E-09"  ixz="-3.4917E-09"  ixx="0.0033145" />
  </inertial>
  <visual >
   <origin  xyz="0 0 0"  rpy="0 0 0" />
   <geometry >
    <mesh  filename="package://straight_link-ms.SLDASM/meshes/sl_body.STL" />
   </geometry>
   <material  name="body" >
    <color  rgba="0.5 0.5 0.5 1" />
   </material>
  </visual>
  <collision >
   <origin  xyz="0 0 0"  rpy="0 0 0" />
   <geometry >
    <mesh  filename="package://straight_link-ms.SLDASM/meshes/sl_body.STL" />
   </geometry>
  </collision>
 </link>
 <link  name="BASEM4147_BASEM23594_BASEM23594_CONNECTORS21493_reverse_CONNECTORS21493_ic_in" >
  <inertial >
   <origin  xyz="-3.5268E-34 -1.0426E-17 0.00365"  rpy="0 0 0" />
   <mass  value="0.23832" />
   <inertia  iyz="0"  izz="0.00015875"  iyy="8.0432E-05"  ixy="0"  ixz="6.1355E-38"  ixx="8.0432E-05" />
  </inertial>
  <visual >
   <origin  xyz="0 0 0"  rpy="0 0 0" />
   <geometry >
    <mesh  filename="package://input_connector_s.SLDASM/meshes/ic_in.STL" />
   </geometry>
   <material  name="blue" >
    <color  rgba="0 0 0.5 1" />
   </material>
  </visual>
  <collision >
   <origin  xyz="0 0 0"  rpy="0 0 0" />
   <geometry >
    <mesh  filename="package://input_connector_s.SLDASM/meshes/ic_in.STL" />
   </geometry>
  </collision>
 </link>
 <link  name="BASEM4147_BASEM23594_BASEM23594_CONNECTORS21493_reverse_CONNECTORS21493_ic_body" >
  <inertial >
   <origin  xyz="0 2.5266E-18 -0.00365"  rpy="0 0 0" />
   <mass  value="0" />
   <inertia  iyz="0"  izz="0.00015875"  iyy="8.0432E-05"  ixy="0"  ixz="6.1355E-38"  ixx="8.0432E-05" />
  </inertial>
  <visual >
   <origin  xyz="0 0 0"  rpy="0 0 0" />
   <geometry >
    <mesh  filename="package://input_connector_s.SLDASM/meshes/ic_body.STL" />
   </geometry>
   <material  name="blue" >
    <color  rgba="0 0 0.5 1" />
   </material>
  </visual>
  <collision >
   <origin  xyz="0 0 0"  rpy="0 0 0" />
   <geometry >
    <mesh  filename="package://input_connector_s.SLDASM/meshes/ic_body.STL" />
   </geometry>
  </collision>
 </link>
 <link  name="BASEM4147_BASEM23594_ENDEFFECTORS1328_ee_in" >
  <inertial >
   <origin  rpy="0 0 0"  xyz="-3.3818E-35 8.2297E-19 5E-05" />
   <mass  value="0.0019211" />
   <inertia  iyz="-6.9194E-23"  izz="7.5309E-07"  iyy="3.7655E-07"  ixy="2.1397E-39"  ixz="2.5988E-42"  ixx="3.7655E-07" />
  </inertial>
  <visual >
   <origin  xyz="0 0 0"  rpy="0 0 0" />
   <geometry >
    <mesh  filename="package://jointT-s.SLDASM/meshes/tj_in.STL" />
   </geometry>
   <material  name="blue" >
    <color  rgba="0 0 0.5 1" />
   </material>
  </visual>
  <collision >
   <origin  xyz="0 0 0"  rpy="0 0 0" />
   <geometry >
    <mesh  filename="package://jointT-s.SLDASM/meshes/tj_in.STL" />
   </geometry>
  </collision>
 </link>
 <link  name="BASEM4147_BASEM23594_ENDEFFECTORS1328_ee_body" >
  <inertial >
   <origin  rpy="0 0 0"  xyz="-3.3818E-35 8.2297E-19 5E-05" />
   <mass  value="0.0019211" />
   <inertia  iyz="-6.9194E-23"  izz="7.5309E-07"  iyy="3.7655E-07"  ixy="2.1397E-39"  ixz="2.5988E-42"  ixx="3.7655E-07" />
  </inertial>
  <visual >
   <origin  xyz="0 0 0"  rpy="0 0 0" />
   <geometry >
    <mesh  filename="package://jointT-s.SLDASM/meshes/tj_body.STL" />
   </geometry>
   <material  name="body" >
    <color  rgba="0.5 0.5 0.5 1" />
   </material>
  </visual>
  <collision >
   <origin  rpy="0 0 0"  xyz="0 0 0" />
   <geometry >
    <mesh  filename="package://jointT-s.SLDASM/meshes/tj_out.STL" />
   </geometry>
  </collision>
 </link>
 <joint  name="BASEM4147_BASEM23594_BASEM23594_BASEM23594_BASEM23594_BASEM23594_BASEM23594_BASEM23594_b_medium"  type="fixed" >
  <origin  rpy="3.14159265358979 0 0"  xyz="0 0 0.0423" />
  <parent  link="BASEM4147_BASEM23594_BASEM23594_BASEM23594_BASEM23594_BASEM23594_BASEM23594_BASEM23594_b_body" />
  <child  link="BASEM4147_BASEM23594_BASEM23594_BASEM23594_BASEM23594_BASEM23594_BASEM23594_BASEM23594_b_in" />
  <axis  xyz="0 0 0" />
 </joint>
 <joint  name="BASEM4147_BASEM23594_BASEM23594_BASEM23594_BASEM23594_BASEM23594_BASEM23594_CONNECTORM114404_ic_medium_1"  type="fixed" >
  <origin  rpy="0 0 0"  xyz="0 0 0" />
  <parent  link="BASEM4147_BASEM23594_BASEM23594_BASEM23594_BASEM23594_BASEM23594_BASEM23594_BASEM23594_b_in" />
  <child  link="BASEM4147_BASEM23594_BASEM23594_BASEM23594_BASEM23594_BASEM23594_BASEM23594_CONNECTORM114404_ic_body" />
  <axis  xyz="0 0 0" />
 </joint>
 <joint  name="BASEM4147_BASEM23594_BASEM23594_BASEM23594_BASEM23594_BASEM23594_BASEM23594_CONNECTORM114404_ic_medium_2"  type="fixed" >
  <origin  rpy="0 0 0"  xyz="0 0 -0.0094" />
  <parent  link="BASEM4147_BASEM23594_BASEM23594_BASEM23594_BASEM23594_BASEM23594_BASEM23594_CONNECTORM114404_ic_body" />
  <child  link="BASEM4147_BASEM23594_BASEM23594_BASEM23594_BASEM23594_BASEM23594_BASEM23594_CONNECTORM114404_ic_in" />
  <axis  xyz="0 0 0" />
 </joint>
 <joint  name="BASEM4147_BASEM23594_BASEM23594_BASEM23594_BASEM23594_BASEM23594_JOINTM64603_tj_medium_1"  type="revolute" >
  <origin  rpy="0.0 0.0 3.141592653589793"  xyz="0.0 0.0 0.0" />
  <parent  link="BASEM4147_BASEM23594_BASEM23594_BASEM23594_BASEM23594_BASEM23594_BASEM23594_CONNECTORM114404_ic_in" />
  <child  link="BASEM4147_BASEM23594_BASEM23594_BASEM23594_BASEM23594_BASEM23594_JOINTM64603_tj_body" />
  <axis  xyz="0 0 1" />
  <limit  effort="25.5"  upper="3.1416"  lower="-3.1416"  velocity="0.33" />
 </joint>
 <joint  name="BASEM4147_BASEM23594_BASEM23594_BASEM23594_BASEM23594_BASEM23594_JOINTM64603_tj_medium_2"  type="fixed" >
  <origin  rpy="0 1.5707963267949 0"  xyz="-0.047 0 -0.0635" />
  <parent  link="BASEM4147_BASEM23594_BASEM23594_BASEM23594_BASEM23594_BASEM23594_JOINTM64603_tj_body" />
  <child  link="BASEM4147_BASEM23594_BASEM23594_BASEM23594_BASEM23594_BASEM23594_JOINTM64603_tj_in" />
  <axis  xyz="0 -1 0" />
 </joint>
 <joint  name="BASEM4147_BASEM23594_BASEM23594_BASEM23594_BASEM23594_CONNECTORM114405_ic_medium_1"  type="fixed" >
  <origin  rpy="0 0 0"  xyz="0 0 0" />
  <parent  link="BASEM4147_BASEM23594_BASEM23594_BASEM23594_BASEM23594_BASEM23594_JOINTM64603_tj_in" />
  <child  link="BASEM4147_BASEM23594_BASEM23594_BASEM23594_BASEM23594_CONNECTORM114405_ic_body" />
  <axis  xyz="0 0 0" />
 </joint>
 <joint  name="BASEM4147_BASEM23594_BASEM23594_BASEM23594_BASEM23594_CONNECTORM114405_ic_medium_2"  type="fixed" >
  <origin  rpy="0 0 0"  xyz="0 0 -0.0094" />
  <parent  link="BASEM4147_BASEM23594_BASEM23594_BASEM23594_BASEM23594_CONNECTORM114405_ic_body" />
  <child  link="BASEM4147_BASEM23594_BASEM23594_BASEM23594_BASEM23594_CONNECTORM114405_ic_in" />
  <axis  xyz="0 0 0" />
 </joint>
 <joint  name="BASEM4147_BASEM23594_BASEM23594_BASEM23594_STRAIGHTLINKMS15785_sl_medium"  type="fixed" >
  <origin  rpy="0 0 0"  xyz="0 0 0" />
  <parent  link="BASEM4147_BASEM23594_BASEM23594_BASEM23594_BASEM23594_CONNECTORM114405_ic_in" />
  <child  link="BASEM4147_BASEM23594_BASEM23594_BASEM23594_STRAIGHTLINKMS15785_sl_body" />
  <axis  xyz="0 0 0" />
 </joint>
 <joint  name="BASEM4147_BASEM23594_BASEM23594_BASEM23594_STRAIGHTLINKMS15785_sl_small"  type="fixed" >
  <origin  rpy="3.1416 0 0"  xyz="0 0 -0.2" />
  <parent  link="BASEM4147_BASEM23594_BASEM23594_BASEM23594_STRAIGHTLINKMS15785_sl_body" />
  <child  link="BASEM4147_BASEM23594_BASEM23594_CONNECTORS21493_reverse_CONNECTORS21493_ic_in" />
  <axis  xyz="0 0 0" />
 </joint>
 <joint  name="BASEM4147_BASEM23594_BASEM23594_CONNECTORS21493_reverse_CONNECTORS21493_ic_small_2"  type="fixed" >
  <origin  rpy="0.0 0.0 0.0"  xyz="-0.0 -0.0 0.0073" />
  <parent  link="BASEM4147_BASEM23594_BASEM23594_CONNECTORS21493_reverse_CONNECTORS21493_ic_in" />
  <child  link="BASEM4147_BASEM23594_BASEM23594_CONNECTORS21493_reverse_CONNECTORS21493_ic_body" />
  <axis  xyz="0 0 0" />
 </joint>
 <joint  name="BASEM4147_BASEM23594_BASEM23594_CONNECTORS21493_reverse_CONNECTORS21493_ic_small_1"  type="fixed" >
  <origin  rpy="0.0 0.0 0.0"  xyz="-0.0 -0.0 -0.0" />
  <parent  link="BASEM4147_BASEM23594_BASEM23594_CONNECTORS21493_reverse_CONNECTORS21493_ic_body" />
  <child  link="BASEM4147_BASEM23594_ENDEFFECTORS1328_ee_in" />
  <axis  xyz="0 0 0" />
 </joint>
 <joint  name="BASEM4147_BASEM23594_ENDEFFECTORS1328_ee_small"  type="fixed" >
  <origin  rpy="0 0 0"  xyz="0 0 0" />
  <parent  link="BASEM4147_BASEM23594_ENDEFFECTORS1328_ee_in" />
  <child  link="BASEM4147_BASEM23594_ENDEFFECTORS1328_ee_body" />
  <axis  xyz="0 0 0" />
 </joint>
 <joint  type="revolute"  name="BASEM19_BASEM543_JOINTS328_reverse_tj_small_1" >
  <origin  xyz="-0.0 -0.0 -0.0"  rpy="0.0 0.0 0.0" />
  <parent  link="BASEM19_BASEM543_JOINTS328_reverse_tj_body" />
  <child  link="BASEM19_BASEM543_JOINTS328_reverse_tj_out" />
  <axis  xyz="0 0 1" />
  <limit  effort="4.5"  velocity="0.4"  upper="3.1416"  lower="-3.1416" />
 </joint>
</robot>
