<?xml version="1.0"?>
<robot  name="UNNAMED_17" >
 <link  name="BASEM9_BASEM312_BASEM312_BASEM312_BASEM312_BASEM312_BASEM312_BASEM312_BASEM312_BASEM312_BASEM312_BASEM312_BASEM312_BASEM312_BASEM312_BASEM312_BASEM312_BASEM312_b_body" >
  <inertial >
   <origin  xyz="-1.2862E-17 -2.139E-18 0.018175"  rpy="0 0 0" />
   <mass  value="0.5" />
   <inertia  iyz="-2.2352E-19"  iyy="0.0034892"  izz="0.0060699"  ixy="-6.7063E-20"  ixx="0.0034892"  ixz="-2.7087E-19" />
  </inertial>
  <visual >
   <origin  xyz="0 0 0"  rpy="0 0 0" />
   <geometry >
    <mesh  filename="package://base-m.SLDASM/meshes/b_body.STL" />
   </geometry>
   <material  name="body" >
    <color  rgba="0.5 0.5 0.5 1" />
   </material>
  </visual>
  <collision >
   <origin  xyz="0 0 0"  rpy="0 0 0" />
   <geometry >
    <mesh  filename="package://base-m.SLDASM/meshes/b_body.STL" />
   </geometry>
  </collision>
 </link>
 <link  name="BASEM9_BASEM312_BASEM312_BASEM312_BASEM312_BASEM312_BASEM312_BASEM312_BASEM312_BASEM312_BASEM312_BASEM312_BASEM312_BASEM312_BASEM312_BASEM312_BASEM312_BASEM312_b_in" >
  <inertial >
   <origin  xyz="-1.2862E-17 1.7762E-17 0.024125"  rpy="0 0 0" />
   <mass  value="3.3499" />
   <inertia  iyz="-2.2352E-19"  iyy="0.0034892"  izz="0.0060699"  ixy="6.7063E-20"  ixx="0.0034892"  ixz="2.7087E-19" />
  </inertial>
  <visual >
   <origin  xyz="0 0 0"  rpy="0 0 0" />
   <geometry >
    <mesh  filename="package://base-m.SLDASM/meshes/b_in.STL" />
   </geometry>
   <material  name="blue" >
    <color  rgba="0 0 0.5 1" />
   </material>
  </visual>
  <collision >
   <origin  xyz="0 0 0"  rpy="0 0 0" />
   <geometry >
    <mesh  filename="package://base-m.SLDASM/meshes/b_in.STL" />
   </geometry>
  </collision>
 </link>
 <link  name="BASEM9_BASEM312_BASEM312_BASEM312_BASEM312_BASEM312_BASEM312_BASEM312_BASEM312_BASEM312_BASEM312_BASEM312_BASEM312_BASEM312_BASEM312_BASEM312_BASEM312_CONNECTORM1004_ic_body" >
  <inertial >
   <origin  xyz="0 -4.8218E-18 -0.0047"  rpy="0 0 0" />
   <mass  value="0" />
   <inertia  iyz="0"  iyy="0.00028474"  izz="0.000562"  ixy="0"  ixx="0.00028474"  ixz="2.1721E-37" />
  </inertial>
  <visual >
   <origin  xyz="0 0 0"  rpy="0 0 0" />
   <geometry >
    <mesh  filename="package://input_connector_m.SLDASM/meshes/ic_body.STL" />
   </geometry>
   <material  name="blue" >
    <color  rgba="0 0 0.5 1" />
   </material>
  </visual>
  <collision >
   <origin  xyz="0 0 0"  rpy="0 0 0" />
   <geometry >
    <mesh  filename="package://input_connector_m.SLDASM/meshes/ic_body.STL" />
   </geometry>
  </collision>
 </link>
 <link  name="BASEM9_BASEM312_BASEM312_BASEM312_BASEM312_BASEM312_BASEM312_BASEM312_BASEM312_BASEM312_BASEM312_BASEM312_BASEM312_BASEM312_BASEM312_BASEM312_BASEM312_CONNECTORM1004_ic_in" >
  <inertial >
   <origin  xyz="-4.5413E-34 1.0801E-17 0.0047"  rpy="0 0 0" />
   <mass  value="0.50882" />
   <inertia  iyz="0"  iyy="0.00028474"  izz="0.000562"  ixy="0"  ixx="0.00028474"  ixz="2.1721E-37" />
  </inertial>
  <visual >
   <origin  xyz="0 0 0"  rpy="0 0 0" />
   <geometry >
    <mesh  filename="package://input_connector_m.SLDASM/meshes/ic_in.STL" />
   </geometry>
   <material  name="blue" >
    <color  rgba="0 0 0.5 1" />
   </material>
  </visual>
  <collision >
   <origin  xyz="0 0 0"  rpy="0 0 0" />
   <geometry >
    <mesh  filename="package://input_connector_m.SLDASM/meshes/ic_in.STL" />
   </geometry>
  </collision>
 </link>
 <link  name="BASEM9_BASEM312_BASEM312_BASEM312_BASEM312_BASEM312_BASEM312_BASEM312_BASEM312_BASEM312_BASEM312_BASEM312_BASEM312_BASEM312_BASEM312_BASEM312_JOINTM688_tj_body" >
  <inertial >
   <origin  xyz="-0.0020574 -5.8806E-08 -0.0635"  rpy="0 0 0" />
   <mass  value="0.93065" />
   <inertia  iyz="-1.9911E-10"  iyy="0.0017615"  izz="0.0011044"  ixy="8.3821E-10"  ixx="0.0017462"  ixz="1.078E-20" />
  </inertial>
  <visual >
   <origin  xyz="0 0 0"  rpy="0 0 0" />
   <geometry >
    <mesh  filename="package://jointT-m.SLDASM/meshes/tj_body.STL" />
   </geometry>
   <material  name="body" >
    <color  rgba="0.5 0.5 0.5 1" />
   </material>
  </visual>
  <collision >
   <origin  xyz="0 0 0"  rpy="0 0 0" />
   <geometry >
    <mesh  filename="package://jointT-m.SLDASM/meshes/tj_body.STL" />
   </geometry>
  </collision>
 </link>
 <link  name="BASEM9_BASEM312_BASEM312_BASEM312_BASEM312_BASEM312_BASEM312_BASEM312_BASEM312_BASEM312_BASEM312_BASEM312_BASEM312_BASEM312_BASEM312_BASEM312_JOINTM688_tj_in" >
  <inertial >
   <origin  xyz="-6.5585E-18 8.3685E-09 0.044941"  rpy="0 0 0" />
   <mass  value="0.93066" />
   <inertia  iyz="8.3821E-10"  iyy="0.0017615"  izz="0.0017462"  ixy="1.9911E-10"  ixx="0.0011044"  ixz="1.0711E-19" />
  </inertial>
  <visual >
   <origin  xyz="0 0 0"  rpy="0 0 0" />
   <geometry >
    <mesh  filename="package://jointT-m.SLDASM/meshes/tj_in.STL" />
   </geometry>
   <material  name="blue" >
    <color  rgba="0 0 0.5 1" />
   </material>
  </visual>
  <collision >
   <origin  xyz="0 0 0"  rpy="0 0 0" />
   <geometry >
    <mesh  filename="package://jointT-m.SLDASM/meshes/tj_in.STL" />
   </geometry>
  </collision>
 </link>
 <link  name="BASEM9_BASEM312_BASEM312_BASEM312_BASEM312_BASEM312_BASEM312_BASEM312_BASEM312_BASEM312_BASEM312_BASEM312_BASEM312_BASEM312_BASEM312_CONNECTORM1005_ic_body" >
  <inertial >
   <origin  xyz="0 -4.8218E-18 -0.0047"  rpy="0 0 0" />
   <mass  value="0" />
   <inertia  iyz="0"  iyy="0.00028474"  izz="0.000562"  ixy="0"  ixx="0.00028474"  ixz="2.1721E-37" />
  </inertial>
  <visual >
   <origin  xyz="0 0 0"  rpy="0 0 0" />
   <geometry >
    <mesh  filename="package://input_connector_m.SLDASM/meshes/ic_body.STL" />
   </geometry>
   <material  name="blue" >
    <color  rgba="0 0 0.5 1" />
   </material>
  </visual>
  <collision >
   <origin  xyz="0 0 0"  rpy="0 0 0" />
   <geometry >
    <mesh  filename="package://input_connector_m.SLDASM/meshes/ic_body.STL" />
   </geometry>
  </collision>
 </link>
 <link  name="BASEM9_BASEM312_BASEM312_BASEM312_BASEM312_BASEM312_BASEM312_BASEM312_BASEM312_BASEM312_BASEM312_BASEM312_BASEM312_BASEM312_BASEM312_CONNECTORM1005_ic_in" >
  <inertial >
   <origin  xyz="-4.5413E-34 1.0801E-17 0.0047"  rpy="0 0 0" />
   <mass  value="0.50882" />
   <inertia  iyz="0"  iyy="0.00028474"  izz="0.000562"  ixy="0"  ixx="0.00028474"  ixz="2.1721E-37" />
  </inertial>
  <visual >
   <origin  xyz="0 0 0"  rpy="0 0 0" />
   <geometry >
    <mesh  filename="package://input_connector_m.SLDASM/meshes/ic_in.STL" />
   </geometry>
   <material  name="blue" >
    <color  rgba="0 0 0.5 1" />
   </material>
  </visual>
  <collision >
   <origin  xyz="0 0 0"  rpy="0 0 0" />
   <geometry >
    <mesh  filename="package://input_connector_m.SLDASM/meshes/ic_in.STL" />
   </geometry>
  </collision>
 </link>
 <link  name="BASEM9_BASEM312_BASEM312_BASEM312_BASEM312_BASEM312_BASEM312_BASEM312_BASEM312_BASEM312_BASEM312_BASEM312_BASEM312_BASEM312_JOINTM689_tj_body" >
  <inertial >
   <origin  xyz="-0.0020574 -5.8806E-08 -0.0635"  rpy="0 0 0" />
   <mass  value="0.93065" />
   <inertia  iyz="-1.9911E-10"  iyy="0.0017615"  izz="0.0011044"  ixy="8.3821E-10"  ixx="0.0017462"  ixz="1.078E-20" />
  </inertial>
  <visual >
   <origin  xyz="0 0 0"  rpy="0 0 0" />
   <geometry >
    <mesh  filename="package://jointT-m.SLDASM/meshes/tj_body.STL" />
   </geometry>
   <material  name="body" >
    <color  rgba="0.5 0.5 0.5 1" />
   </material>
  </visual>
  <collision >
   <origin  xyz="0 0 0"  rpy="0 0 0" />
   <geometry >
    <mesh  filename="package://jointT-m.SLDASM/meshes/tj_body.STL" />
   </geometry>
  </collision>
 </link>
 <link  name="BASEM9_BASEM312_BASEM312_BASEM312_BASEM312_BASEM312_BASEM312_BASEM312_BASEM312_BASEM312_BASEM312_BASEM312_BASEM312_BASEM312_JOINTM689_tj_in" >
  <inertial >
   <origin  xyz="-6.5585E-18 8.3685E-09 0.044941"  rpy="0 0 0" />
   <mass  value="0.93066" />
   <inertia  iyz="8.3821E-10"  iyy="0.0017615"  izz="0.0017462"  ixy="1.9911E-10"  ixx="0.0011044"  ixz="1.0711E-19" />
  </inertial>
  <visual >
   <origin  xyz="0 0 0"  rpy="0 0 0" />
   <geometry >
    <mesh  filename="package://jointT-m.SLDASM/meshes/tj_in.STL" />
   </geometry>
   <material  name="blue" >
    <color  rgba="0 0 0.5 1" />
   </material>
  </visual>
  <collision >
   <origin  xyz="0 0 0"  rpy="0 0 0" />
   <geometry >
    <mesh  filename="package://jointT-m.SLDASM/meshes/tj_in.STL" />
   </geometry>
  </collision>
 </link>
 <link  name="BASEM9_BASEM312_BASEM312_BASEM312_BASEM312_BASEM312_BASEM312_BASEM312_BASEM312_BASEM312_BASEM312_BASEM312_BASEM312_CONNECTORM1006_ic_body" >
  <inertial >
   <origin  xyz="0 -4.8218E-18 -0.0047"  rpy="0 0 0" />
   <mass  value="0" />
   <inertia  iyz="0"  iyy="0.00028474"  izz="0.000562"  ixy="0"  ixx="0.00028474"  ixz="2.1721E-37" />
  </inertial>
  <visual >
   <origin  xyz="0 0 0"  rpy="0 0 0" />
   <geometry >
    <mesh  filename="package://input_connector_m.SLDASM/meshes/ic_body.STL" />
   </geometry>
   <material  name="blue" >
    <color  rgba="0 0 0.5 1" />
   </material>
  </visual>
  <collision >
   <origin  xyz="0 0 0"  rpy="0 0 0" />
   <geometry >
    <mesh  filename="package://input_connector_m.SLDASM/meshes/ic_body.STL" />
   </geometry>
  </collision>
 </link>
 <link  name="BASEM9_BASEM312_BASEM312_BASEM312_BASEM312_BASEM312_BASEM312_BASEM312_BASEM312_BASEM312_BASEM312_BASEM312_BASEM312_CONNECTORM1006_ic_in" >
  <inertial >
   <origin  xyz="-4.5413E-34 1.0801E-17 0.0047"  rpy="0 0 0" />
   <mass  value="0.50882" />
   <inertia  iyz="0"  iyy="0.00028474"  izz="0.000562"  ixy="0"  ixx="0.00028474"  ixz="2.1721E-37" />
  </inertial>
  <visual >
   <origin  xyz="0 0 0"  rpy="0 0 0" />
   <geometry >
    <mesh  filename="package://input_connector_m.SLDASM/meshes/ic_in.STL" />
   </geometry>
   <material  name="blue" >
    <color  rgba="0 0 0.5 1" />
   </material>
  </visual>
  <collision >
   <origin  xyz="0 0 0"  rpy="0 0 0" />
   <geometry >
    <mesh  filename="package://input_connector_m.SLDASM/meshes/ic_in.STL" />
   </geometry>
  </collision>
 </link>
 <link  name="BASEM9_BASEM312_BASEM312_BASEM312_BASEM312_BASEM312_BASEM312_BASEM312_BASEM312_BASEM312_BASEM312_BASEM312_JOINTM690_tj_body" >
  <inertial >
   <origin  xyz="-0.0020574 -5.8806E-08 -0.0635"  rpy="0 0 0" />
   <mass  value="0.93065" />
   <inertia  iyz="-1.9911E-10"  iyy="0.0017615"  izz="0.0011044"  ixy="8.3821E-10"  ixx="0.0017462"  ixz="1.078E-20" />
  </inertial>
  <visual >
   <origin  xyz="0 0 0"  rpy="0 0 0" />
   <geometry >
    <mesh  filename="package://jointT-m.SLDASM/meshes/tj_body.STL" />
   </geometry>
   <material  name="body" >
    <color  rgba="0.5 0.5 0.5 1" />
   </material>
  </visual>
  <collision >
   <origin  xyz="0 0 0"  rpy="0 0 0" />
   <geometry >
    <mesh  filename="package://jointT-m.SLDASM/meshes/tj_body.STL" />
   </geometry>
  </collision>
 </link>
 <link  name="BASEM9_BASEM312_BASEM312_BASEM312_BASEM312_BASEM312_BASEM312_BASEM312_BASEM312_BASEM312_BASEM312_BASEM312_JOINTM690_tj_in" >
  <inertial >
   <origin  xyz="-6.5585E-18 8.3685E-09 0.044941"  rpy="0 0 0" />
   <mass  value="0.93066" />
   <inertia  iyz="8.3821E-10"  iyy="0.0017615"  izz="0.0017462"  ixy="1.9911E-10"  ixx="0.0011044"  ixz="1.0711E-19" />
  </inertial>
  <visual >
   <origin  xyz="0 0 0"  rpy="0 0 0" />
   <geometry >
    <mesh  filename="package://jointT-m.SLDASM/meshes/tj_in.STL" />
   </geometry>
   <material  name="blue" >
    <color  rgba="0 0 0.5 1" />
   </material>
  </visual>
  <collision >
   <origin  xyz="0 0 0"  rpy="0 0 0" />
   <geometry >
    <mesh  filename="package://jointT-m.SLDASM/meshes/tj_in.STL" />
   </geometry>
  </collision>
 </link>
 <link  name="BASEM9_BASEM312_BASEM312_BASEM312_BASEM312_BASEM312_BASEM312_BASEM312_BASEM312_BASEM312_BASEM312_CONNECTORM1007_ic_body" >
  <inertial >
   <origin  xyz="0 -4.8218E-18 -0.0047"  rpy="0 0 0" />
   <mass  value="0" />
   <inertia  iyz="0"  iyy="0.00028474"  izz="0.000562"  ixy="0"  ixx="0.00028474"  ixz="2.1721E-37" />
  </inertial>
  <visual >
   <origin  xyz="0 0 0"  rpy="0 0 0" />
   <geometry >
    <mesh  filename="package://input_connector_m.SLDASM/meshes/ic_body.STL" />
   </geometry>
   <material  name="blue" >
    <color  rgba="0 0 0.5 1" />
   </material>
  </visual>
  <collision >
   <origin  xyz="0 0 0"  rpy="0 0 0" />
   <geometry >
    <mesh  filename="package://input_connector_m.SLDASM/meshes/ic_body.STL" />
   </geometry>
  </collision>
 </link>
 <link  name="BASEM9_BASEM312_BASEM312_BASEM312_BASEM312_BASEM312_BASEM312_BASEM312_BASEM312_BASEM312_BASEM312_CONNECTORM1007_ic_in" >
  <inertial >
   <origin  xyz="-4.5413E-34 1.0801E-17 0.0047"  rpy="0 0 0" />
   <mass  value="0.50882" />
   <inertia  iyz="0"  iyy="0.00028474"  izz="0.000562"  ixy="0"  ixx="0.00028474"  ixz="2.1721E-37" />
  </inertial>
  <visual >
   <origin  xyz="0 0 0"  rpy="0 0 0" />
   <geometry >
    <mesh  filename="package://input_connector_m.SLDASM/meshes/ic_in.STL" />
   </geometry>
   <material  name="blue" >
    <color  rgba="0 0 0.5 1" />
   </material>
  </visual>
  <collision >
   <origin  xyz="0 0 0"  rpy="0 0 0" />
   <geometry >
    <mesh  filename="package://input_connector_m.SLDASM/meshes/ic_in.STL" />
   </geometry>
  </collision>
 </link>
 <link  name="BASEM9_BASEM312_BASEM312_BASEM312_BASEM312_BASEM312_BASEM312_BASEM312_BASEM312_BASEM312_STRAIGHTLINKMS100_sl_body" >
  <inertial >
   <origin  xyz="-2.61E-07 7.571E-07 -0.097144"  rpy="0 0 0" />
   <mass  value="0.86346" />
   <inertia  iyz="9.5259E-09"  iyy="0.0033145"  izz="0.00060028"  ixy="3.4516E-09"  ixx="0.0033145"  ixz="-3.4917E-09" />
  </inertial>
  <visual >
   <origin  xyz="0 0 0"  rpy="0 0 0" />
   <geometry >
    <mesh  filename="package://straight_link-ms.SLDASM/meshes/sl_body.STL" />
   </geometry>
   <material  name="body" >
    <color  rgba="0.5 0.5 0.5 1" />
   </material>
  </visual>
  <collision >
   <origin  xyz="0 0 0"  rpy="0 0 0" />
   <geometry >
    <mesh  filename="package://straight_link-ms.SLDASM/meshes/sl_body.STL" />
   </geometry>
  </collision>
 </link>
 <link  name="BASEM9_BASEM312_BASEM312_BASEM312_BASEM312_BASEM312_BASEM312_BASEM312_BASEM312_CONNECTORS144_reverse_ic_in" >
  <inertial >
   <origin  xyz="-3.5268E-34 -1.0426E-17 0.00365"  rpy="0 0 0" />
   <mass  value="0.23832" />
   <inertia  iyz="0"  iyy="8.0432E-05"  izz="0.00015875"  ixy="0"  ixx="8.0432E-05"  ixz="6.1355E-38" />
  </inertial>
  <visual >
   <origin  xyz="0 0 0"  rpy="0 0 0" />
   <geometry >
    <mesh  filename="package://input_connector_s.SLDASM/meshes/ic_in.STL" />
   </geometry>
   <material  name="blue" >
    <color  rgba="0 0 0.5 1" />
   </material>
  </visual>
  <collision >
   <origin  xyz="0 0 0"  rpy="0 0 0" />
   <geometry >
    <mesh  filename="package://input_connector_s.SLDASM/meshes/ic_in.STL" />
   </geometry>
  </collision>
 </link>
 <link  name="BASEM9_BASEM312_BASEM312_BASEM312_BASEM312_BASEM312_BASEM312_BASEM312_BASEM312_CONNECTORS144_reverse_ic_body" >
  <inertial >
   <origin  xyz="0 2.5266E-18 -0.00365"  rpy="0 0 0" />
   <mass  value="0" />
   <inertia  iyz="0"  iyy="8.0432E-05"  izz="0.00015875"  ixy="0"  ixx="8.0432E-05"  ixz="6.1355E-38" />
  </inertial>
  <visual >
   <origin  xyz="0 0 0"  rpy="0 0 0" />
   <geometry >
    <mesh  filename="package://input_connector_s.SLDASM/meshes/ic_body.STL" />
   </geometry>
   <material  name="blue" >
    <color  rgba="0 0 0.5 1" />
   </material>
  </visual>
  <collision >
   <origin  xyz="0 0 0"  rpy="0 0 0" />
   <geometry >
    <mesh  filename="package://input_connector_s.SLDASM/meshes/ic_body.STL" />
   </geometry>
  </collision>
 </link>
 <link  name="BASEM9_BASEM312_BASEM312_BASEM312_BASEM312_BASEM312_BASEM312_BASEM312_JOINTS140_reverse_tj_in" >
  <inertial >
   <origin  xyz="1.1276E-17 6.5484E-09 0.035118"  rpy="0 0 0" />
   <mass  value="0.50441" />
   <inertia  iyz="2.7679E-10"  iyy="0.00071638"  izz="0.00071191"  ixy="7.6335E-11"  ixx="0.00035776"  ixz="1.7534E-20" />
  </inertial>
  <visual >
   <origin  xyz="0 0 0"  rpy="0 0 0" />
   <geometry >
    <mesh  filename="package://jointT-s.SLDASM/meshes/tj_in.STL" />
   </geometry>
   <material  name="blue" >
    <color  rgba="0 0 0.5 1" />
   </material>
  </visual>
  <collision >
   <origin  xyz="0 0 0"  rpy="0 0 0" />
   <geometry >
    <mesh  filename="package://jointT-s.SLDASM/meshes/tj_in.STL" />
   </geometry>
  </collision>
 </link>
 <link  name="BASEM9_BASEM312_BASEM312_BASEM312_BASEM312_BASEM312_BASEM312_BASEM312_JOINTS140_reverse_tj_body" >
  <inertial >
   <origin  xyz="-0.0013808 -7.3281E-08 -0.0575"  rpy="0 0 0" />
   <mass  value="0.50441" />
   <inertia  iyz="-7.6335E-11"  iyy="0.00071638"  izz="0.00035776"  ixy="2.7679E-10"  ixx="0.00071191"  ixz="4.9663E-20" />
  </inertial>
  <visual >
   <origin  xyz="0 0 0"  rpy="0 0 0" />
   <geometry >
    <mesh  filename="package://jointT-s.SLDASM/meshes/tj_body.STL" />
   </geometry>
   <material  name="body" >
    <color  rgba="0.5 0.5 0.5 1" />
   </material>
  </visual>
  <collision >
   <origin  xyz="0 0 0"  rpy="0 0 0" />
   <geometry >
    <mesh  filename="package://jointT-s.SLDASM/meshes/tj_body.STL" />
   </geometry>
  </collision>
 </link>
 <link  name="BASEM9_BASEM312_BASEM312_BASEM312_BASEM312_BASEM312_BASEM312_CONNECTORS145_reverse_ic_in" >
  <inertial >
   <origin  xyz="-3.5268E-34 -1.0426E-17 0.00365"  rpy="0 0 0" />
   <mass  value="0.23832" />
   <inertia  iyz="0"  iyy="8.0432E-05"  izz="0.00015875"  ixy="0"  ixx="8.0432E-05"  ixz="6.1355E-38" />
  </inertial>
  <visual >
   <origin  xyz="0 0 0"  rpy="0 0 0" />
   <geometry >
    <mesh  filename="package://input_connector_s.SLDASM/meshes/ic_in.STL" />
   </geometry>
   <material  name="blue" >
    <color  rgba="0 0 0.5 1" />
   </material>
  </visual>
  <collision >
   <origin  xyz="0 0 0"  rpy="0 0 0" />
   <geometry >
    <mesh  filename="package://input_connector_s.SLDASM/meshes/ic_in.STL" />
   </geometry>
  </collision>
 </link>
 <link  name="BASEM9_BASEM312_BASEM312_BASEM312_BASEM312_BASEM312_BASEM312_CONNECTORS145_reverse_ic_body" >
  <inertial >
   <origin  xyz="0 2.5266E-18 -0.00365"  rpy="0 0 0" />
   <mass  value="0" />
   <inertia  iyz="0"  iyy="8.0432E-05"  izz="0.00015875"  ixy="0"  ixx="8.0432E-05"  ixz="6.1355E-38" />
  </inertial>
  <visual >
   <origin  xyz="0 0 0"  rpy="0 0 0" />
   <geometry >
    <mesh  filename="package://input_connector_s.SLDASM/meshes/ic_body.STL" />
   </geometry>
   <material  name="blue" >
    <color  rgba="0 0 0.5 1" />
   </material>
  </visual>
  <collision >
   <origin  xyz="0 0 0"  rpy="0 0 0" />
   <geometry >
    <mesh  filename="package://input_connector_s.SLDASM/meshes/ic_body.STL" />
   </geometry>
  </collision>
 </link>
 <link  name="BASEM9_BASEM312_BASEM312_BASEM312_BASEM312_BASEM312_JOINTS141_reverse_tj_in" >
  <inertial >
   <origin  xyz="1.1276E-17 6.5484E-09 0.035118"  rpy="0 0 0" />
   <mass  value="0.50441" />
   <inertia  iyz="2.7679E-10"  iyy="0.00071638"  izz="0.00071191"  ixy="7.6335E-11"  ixx="0.00035776"  ixz="1.7534E-20" />
  </inertial>
  <visual >
   <origin  xyz="0 0 0"  rpy="0 0 0" />
   <geometry >
    <mesh  filename="package://jointT-s.SLDASM/meshes/tj_in.STL" />
   </geometry>
   <material  name="blue" >
    <color  rgba="0 0 0.5 1" />
   </material>
  </visual>
  <collision >
   <origin  xyz="0 0 0"  rpy="0 0 0" />
   <geometry >
    <mesh  filename="package://jointT-s.SLDASM/meshes/tj_in.STL" />
   </geometry>
  </collision>
 </link>
 <link  name="BASEM9_BASEM312_BASEM312_BASEM312_BASEM312_BASEM312_JOINTS141_reverse_tj_body" >
  <inertial >
   <origin  xyz="-0.0013808 -7.3281E-08 -0.0575"  rpy="0 0 0" />
   <mass  value="0.50441" />
   <inertia  iyz="-7.6335E-11"  iyy="0.00071638"  izz="0.00035776"  ixy="2.7679E-10"  ixx="0.00071191"  ixz="4.9663E-20" />
  </inertial>
  <visual >
   <origin  xyz="0 0 0"  rpy="0 0 0" />
   <geometry >
    <mesh  filename="package://jointT-s.SLDASM/meshes/tj_body.STL" />
   </geometry>
   <material  name="body" >
    <color  rgba="0.5 0.5 0.5 1" />
   </material>
  </visual>
  <collision >
   <origin  xyz="0 0 0"  rpy="0 0 0" />
   <geometry >
    <mesh  filename="package://jointT-s.SLDASM/meshes/tj_body.STL" />
   </geometry>
  </collision>
 </link>
 <link  name="BASEM9_BASEM312_BASEM312_BASEM312_BASEM312_CONNECTORS146_reverse_ic_in" >
  <inertial >
   <origin  xyz="-3.5268E-34 -1.0426E-17 0.00365"  rpy="0 0 0" />
   <mass  value="0.23832" />
   <inertia  iyz="0"  iyy="8.0432E-05"  izz="0.00015875"  ixy="0"  ixx="8.0432E-05"  ixz="6.1355E-38" />
  </inertial>
  <visual >
   <origin  xyz="0 0 0"  rpy="0 0 0" />
   <geometry >
    <mesh  filename="package://input_connector_s.SLDASM/meshes/ic_in.STL" />
   </geometry>
   <material  name="blue" >
    <color  rgba="0 0 0.5 1" />
   </material>
  </visual>
  <collision >
   <origin  xyz="0 0 0"  rpy="0 0 0" />
   <geometry >
    <mesh  filename="package://input_connector_s.SLDASM/meshes/ic_in.STL" />
   </geometry>
  </collision>
 </link>
 <link  name="BASEM9_BASEM312_BASEM312_BASEM312_BASEM312_CONNECTORS146_reverse_ic_body" >
  <inertial >
   <origin  xyz="0 2.5266E-18 -0.00365"  rpy="0 0 0" />
   <mass  value="0" />
   <inertia  iyz="0"  iyy="8.0432E-05"  izz="0.00015875"  ixy="0"  ixx="8.0432E-05"  ixz="6.1355E-38" />
  </inertial>
  <visual >
   <origin  xyz="0 0 0"  rpy="0 0 0" />
   <geometry >
    <mesh  filename="package://input_connector_s.SLDASM/meshes/ic_body.STL" />
   </geometry>
   <material  name="blue" >
    <color  rgba="0 0 0.5 1" />
   </material>
  </visual>
  <collision >
   <origin  xyz="0 0 0"  rpy="0 0 0" />
   <geometry >
    <mesh  filename="package://input_connector_s.SLDASM/meshes/ic_body.STL" />
   </geometry>
  </collision>
 </link>
 <link  name="BASEM9_BASEM312_BASEM312_BASEM312_JOINTS142_reverse_tj_in" >
  <inertial >
   <origin  xyz="1.1276E-17 6.5484E-09 0.035118"  rpy="0 0 0" />
   <mass  value="0.50441" />
   <inertia  iyz="2.7679E-10"  iyy="0.00071638"  izz="0.00071191"  ixy="7.6335E-11"  ixx="0.00035776"  ixz="1.7534E-20" />
  </inertial>
  <visual >
   <origin  xyz="0 0 0"  rpy="0 0 0" />
   <geometry >
    <mesh  filename="package://jointT-s.SLDASM/meshes/tj_in.STL" />
   </geometry>
   <material  name="blue" >
    <color  rgba="0 0 0.5 1" />
   </material>
  </visual>
  <collision >
   <origin  xyz="0 0 0"  rpy="0 0 0" />
   <geometry >
    <mesh  filename="package://jointT-s.SLDASM/meshes/tj_in.STL" />
   </geometry>
  </collision>
 </link>
 <link  name="BASEM9_BASEM312_BASEM312_BASEM312_JOINTS142_reverse_tj_body" >
  <inertial >
   <origin  xyz="-0.0013808 -7.3281E-08 -0.0575"  rpy="0 0 0" />
   <mass  value="0.50441" />
   <inertia  iyz="-7.6335E-11"  iyy="0.00071638"  izz="0.00035776"  ixy="2.7679E-10"  ixx="0.00071191"  ixz="4.9663E-20" />
  </inertial>
  <visual >
   <origin  xyz="0 0 0"  rpy="0 0 0" />
   <geometry >
    <mesh  filename="package://jointT-s.SLDASM/meshes/tj_body.STL" />
   </geometry>
   <material  name="body" >
    <color  rgba="0.5 0.5 0.5 1" />
   </material>
  </visual>
  <collision >
   <origin  xyz="0 0 0"  rpy="0 0 0" />
   <geometry >
    <mesh  filename="package://jointT-s.SLDASM/meshes/tj_body.STL" />
   </geometry>
  </collision>
 </link>
 <link  name="BASEM9_BASEM312_BASEM312_CONNECTORS147_reverse_CONNECTORS147_ic_in" >
  <inertial >
   <origin  xyz="-3.5268E-34 -1.0426E-17 0.00365"  rpy="0 0 0" />
   <mass  value="0.23832" />
   <inertia  iyz="0"  iyy="8.0432E-05"  izz="0.00015875"  ixy="0"  ixx="8.0432E-05"  ixz="6.1355E-38" />
  </inertial>
  <visual >
   <origin  xyz="0 0 0"  rpy="0 0 0" />
   <geometry >
    <mesh  filename="package://input_connector_s.SLDASM/meshes/ic_in.STL" />
   </geometry>
   <material  name="blue" >
    <color  rgba="0 0 0.5 1" />
   </material>
  </visual>
  <collision >
   <origin  xyz="0 0 0"  rpy="0 0 0" />
   <geometry >
    <mesh  filename="package://input_connector_s.SLDASM/meshes/ic_in.STL" />
   </geometry>
  </collision>
 </link>
 <link  name="BASEM9_BASEM312_BASEM312_CONNECTORS147_reverse_CONNECTORS147_ic_body" >
  <inertial >
   <origin  xyz="0 2.5266E-18 -0.00365"  rpy="0 0 0" />
   <mass  value="0" />
   <inertia  iyz="0"  iyy="8.0432E-05"  izz="0.00015875"  ixy="0"  ixx="8.0432E-05"  ixz="6.1355E-38" />
  </inertial>
  <visual >
   <origin  xyz="0 0 0"  rpy="0 0 0" />
   <geometry >
    <mesh  filename="package://input_connector_s.SLDASM/meshes/ic_body.STL" />
   </geometry>
   <material  name="blue" >
    <color  rgba="0 0 0.5 1" />
   </material>
  </visual>
  <collision >
   <origin  xyz="0 0 0"  rpy="0 0 0" />
   <geometry >
    <mesh  filename="package://input_connector_s.SLDASM/meshes/ic_body.STL" />
   </geometry>
  </collision>
 </link>
 <link  name="BASEM9_BASEM312_ENDEFFECTORS4_ee_in" >
  <inertial >
   <origin  xyz="-3.3818E-35 8.2297E-19 5E-05"  rpy="0 0 0" />
   <mass  value="0.0019211" />
   <inertia  iyz="-6.9194E-23"  iyy="3.7655E-07"  izz="7.5309E-07"  ixy="2.1397E-39"  ixx="3.7655E-07"  ixz="2.5988E-42" />
  </inertial>
  <visual >
   <origin  xyz="0 0 0"  rpy="0 0 0" />
   <geometry >
    <mesh  filename="package://end_effector_v_s.SLDASM/meshes/ee_in.STL" />
   </geometry>
   <material  name="blue" >
    <color  rgba="0 0 0.5 1" />
   </material>
  </visual>
  <collision >
   <origin  xyz="0 0 0"  rpy="0 0 0" />
   <geometry >
    <mesh  filename="package://end_effector_v_s.SLDASM/meshes/ee_in.STL" />
   </geometry>
  </collision>
 </link>
 <link  name="BASEM9_BASEM312_ENDEFFECTORS4_ee_body" >
  <inertial >
   <origin  xyz="-3.3818E-35 8.2297E-19 5E-05"  rpy="0 0 0" />
   <mass  value="0.0019211" />
   <inertia  iyz="-6.9194E-23"  iyy="3.7655E-07"  izz="7.5309E-07"  ixy="2.1397E-39"  ixx="3.7655E-07"  ixz="2.5988E-42" />
  </inertial>
  <visual >
   <origin  xyz="0 0 0"  rpy="0 0 0" />
   <geometry >
    <mesh  filename="package://end_effector_v_s.SLDASM/meshes/ee_body.STL" />
   </geometry>
   <material  name="body" >
    <color  rgba="0.5 0.5 0.5 1" />
   </material>
  </visual>
  <collision >
   <origin  xyz="0 0 0"  rpy="0 0 0" />
   <geometry >
    <mesh  filename="package://end_effector_v_s.SLDASM/meshes/ee_body.STL" />
   </geometry>
  </collision>
 </link>
 <joint  type="fixed"  name="BASEM9_BASEM312_BASEM312_BASEM312_BASEM312_BASEM312_BASEM312_BASEM312_BASEM312_BASEM312_BASEM312_BASEM312_BASEM312_BASEM312_BASEM312_BASEM312_BASEM312_BASEM312_b_medium" >
  <origin  xyz="0 0 0.0423"  rpy="3.14159265358979 0 0" />
  <parent  link="BASEM9_BASEM312_BASEM312_BASEM312_BASEM312_BASEM312_BASEM312_BASEM312_BASEM312_BASEM312_BASEM312_BASEM312_BASEM312_BASEM312_BASEM312_BASEM312_BASEM312_BASEM312_b_body" />
  <child  link="BASEM9_BASEM312_BASEM312_BASEM312_BASEM312_BASEM312_BASEM312_BASEM312_BASEM312_BASEM312_BASEM312_BASEM312_BASEM312_BASEM312_BASEM312_BASEM312_BASEM312_BASEM312_b_in" />
  <axis  xyz="0 0 0" />
 </joint>
 <joint  type="fixed"  name="BASEM9_BASEM312_BASEM312_BASEM312_BASEM312_BASEM312_BASEM312_BASEM312_BASEM312_BASEM312_BASEM312_BASEM312_BASEM312_BASEM312_BASEM312_BASEM312_BASEM312_CONNECTORM1004_ic_medium_1" >
  <origin  xyz="0 0 0"  rpy="0 0 0" />
  <parent  link="BASEM9_BASEM312_BASEM312_BASEM312_BASEM312_BASEM312_BASEM312_BASEM312_BASEM312_BASEM312_BASEM312_BASEM312_BASEM312_BASEM312_BASEM312_BASEM312_BASEM312_BASEM312_b_in" />
  <child  link="BASEM9_BASEM312_BASEM312_BASEM312_BASEM312_BASEM312_BASEM312_BASEM312_BASEM312_BASEM312_BASEM312_BASEM312_BASEM312_BASEM312_BASEM312_BASEM312_BASEM312_CONNECTORM1004_ic_body" />
  <axis  xyz="0 0 0" />
 </joint>
 <joint  type="fixed"  name="BASEM9_BASEM312_BASEM312_BASEM312_BASEM312_BASEM312_BASEM312_BASEM312_BASEM312_BASEM312_BASEM312_BASEM312_BASEM312_BASEM312_BASEM312_BASEM312_BASEM312_CONNECTORM1004_ic_medium_2" >
  <origin  xyz="0 0 -0.0094"  rpy="0 0 0" />
  <parent  link="BASEM9_BASEM312_BASEM312_BASEM312_BASEM312_BASEM312_BASEM312_BASEM312_BASEM312_BASEM312_BASEM312_BASEM312_BASEM312_BASEM312_BASEM312_BASEM312_BASEM312_CONNECTORM1004_ic_body" />
  <child  link="BASEM9_BASEM312_BASEM312_BASEM312_BASEM312_BASEM312_BASEM312_BASEM312_BASEM312_BASEM312_BASEM312_BASEM312_BASEM312_BASEM312_BASEM312_BASEM312_BASEM312_CONNECTORM1004_ic_in" />
  <axis  xyz="0 0 0" />
 </joint>
 <joint  type="revolute"  name="BASEM9_BASEM312_BASEM312_BASEM312_BASEM312_BASEM312_BASEM312_BASEM312_BASEM312_BASEM312_BASEM312_BASEM312_BASEM312_BASEM312_BASEM312_BASEM312_JOINTM688_tj_medium_1" >
  <origin  xyz="0.0 0.0 0.0"  rpy="0.0 0.0 3.141592653589793" />
  <parent  link="BASEM9_BASEM312_BASEM312_BASEM312_BASEM312_BASEM312_BASEM312_BASEM312_BASEM312_BASEM312_BASEM312_BASEM312_BASEM312_BASEM312_BASEM312_BASEM312_BASEM312_CONNECTORM1004_ic_in" />
  <child  link="BASEM9_BASEM312_BASEM312_BASEM312_BASEM312_BASEM312_BASEM312_BASEM312_BASEM312_BASEM312_BASEM312_BASEM312_BASEM312_BASEM312_BASEM312_BASEM312_JOINTM688_tj_body" />
  <axis  xyz="0 0 1" />
  <limit  velocity="0.33"  lower="-3.1416"  upper="3.1416"  effort="25.5" />
 </joint>
 <joint  type="fixed"  name="BASEM9_BASEM312_BASEM312_BASEM312_BASEM312_BASEM312_BASEM312_BASEM312_BASEM312_BASEM312_BASEM312_BASEM312_BASEM312_BASEM312_BASEM312_BASEM312_JOINTM688_tj_medium_2" >
  <origin  xyz="-0.047 0 -0.0635"  rpy="0 1.5707963267949 0" />
  <parent  link="BASEM9_BASEM312_BASEM312_BASEM312_BASEM312_BASEM312_BASEM312_BASEM312_BASEM312_BASEM312_BASEM312_BASEM312_BASEM312_BASEM312_BASEM312_BASEM312_JOINTM688_tj_body" />
  <child  link="BASEM9_BASEM312_BASEM312_BASEM312_BASEM312_BASEM312_BASEM312_BASEM312_BASEM312_BASEM312_BASEM312_BASEM312_BASEM312_BASEM312_BASEM312_BASEM312_JOINTM688_tj_in" />
  <axis  xyz="0 -1 0" />
 </joint>
 <joint  type="fixed"  name="BASEM9_BASEM312_BASEM312_BASEM312_BASEM312_BASEM312_BASEM312_BASEM312_BASEM312_BASEM312_BASEM312_BASEM312_BASEM312_BASEM312_BASEM312_CONNECTORM1005_ic_medium_1" >
  <origin  xyz="0 0 0"  rpy="0 0 0" />
  <parent  link="BASEM9_BASEM312_BASEM312_BASEM312_BASEM312_BASEM312_BASEM312_BASEM312_BASEM312_BASEM312_BASEM312_BASEM312_BASEM312_BASEM312_BASEM312_BASEM312_JOINTM688_tj_in" />
  <child  link="BASEM9_BASEM312_BASEM312_BASEM312_BASEM312_BASEM312_BASEM312_BASEM312_BASEM312_BASEM312_BASEM312_BASEM312_BASEM312_BASEM312_BASEM312_CONNECTORM1005_ic_body" />
  <axis  xyz="0 0 0" />
 </joint>
 <joint  type="fixed"  name="BASEM9_BASEM312_BASEM312_BASEM312_BASEM312_BASEM312_BASEM312_BASEM312_BASEM312_BASEM312_BASEM312_BASEM312_BASEM312_BASEM312_BASEM312_CONNECTORM1005_ic_medium_2" >
  <origin  xyz="0 0 -0.0094"  rpy="0 0 0" />
  <parent  link="BASEM9_BASEM312_BASEM312_BASEM312_BASEM312_BASEM312_BASEM312_BASEM312_BASEM312_BASEM312_BASEM312_BASEM312_BASEM312_BASEM312_BASEM312_CONNECTORM1005_ic_body" />
  <child  link="BASEM9_BASEM312_BASEM312_BASEM312_BASEM312_BASEM312_BASEM312_BASEM312_BASEM312_BASEM312_BASEM312_BASEM312_BASEM312_BASEM312_BASEM312_CONNECTORM1005_ic_in" />
  <axis  xyz="0 0 0" />
 </joint>
 <joint  type="revolute"  name="BASEM9_BASEM312_BASEM312_BASEM312_BASEM312_BASEM312_BASEM312_BASEM312_BASEM312_BASEM312_BASEM312_BASEM312_BASEM312_BASEM312_JOINTM689_tj_medium_1" >
  <origin  xyz="0.0 0.0 0.0"  rpy="0.0 0.0 3.141592653589793" />
  <parent  link="BASEM9_BASEM312_BASEM312_BASEM312_BASEM312_BASEM312_BASEM312_BASEM312_BASEM312_BASEM312_BASEM312_BASEM312_BASEM312_BASEM312_BASEM312_CONNECTORM1005_ic_in" />
  <child  link="BASEM9_BASEM312_BASEM312_BASEM312_BASEM312_BASEM312_BASEM312_BASEM312_BASEM312_BASEM312_BASEM312_BASEM312_BASEM312_BASEM312_JOINTM689_tj_body" />
  <axis  xyz="0 0 1" />
  <limit  velocity="0.33"  lower="-3.1416"  upper="3.1416"  effort="25.5" />
 </joint>
 <joint  type="fixed"  name="BASEM9_BASEM312_BASEM312_BASEM312_BASEM312_BASEM312_BASEM312_BASEM312_BASEM312_BASEM312_BASEM312_BASEM312_BASEM312_BASEM312_JOINTM689_tj_medium_2" >
  <origin  xyz="-0.047 0 -0.0635"  rpy="0 1.5707963267949 0" />
  <parent  link="BASEM9_BASEM312_BASEM312_BASEM312_BASEM312_BASEM312_BASEM312_BASEM312_BASEM312_BASEM312_BASEM312_BASEM312_BASEM312_BASEM312_JOINTM689_tj_body" />
  <child  link="BASEM9_BASEM312_BASEM312_BASEM312_BASEM312_BASEM312_BASEM312_BASEM312_BASEM312_BASEM312_BASEM312_BASEM312_BASEM312_BASEM312_JOINTM689_tj_in" />
  <axis  xyz="0 -1 0" />
 </joint>
 <joint  type="fixed"  name="BASEM9_BASEM312_BASEM312_BASEM312_BASEM312_BASEM312_BASEM312_BASEM312_BASEM312_BASEM312_BASEM312_BASEM312_BASEM312_CONNECTORM1006_ic_medium_1" >
  <origin  xyz="0 0 0"  rpy="0 0 0" />
  <parent  link="BASEM9_BASEM312_BASEM312_BASEM312_BASEM312_BASEM312_BASEM312_BASEM312_BASEM312_BASEM312_BASEM312_BASEM312_BASEM312_BASEM312_JOINTM689_tj_in" />
  <child  link="BASEM9_BASEM312_BASEM312_BASEM312_BASEM312_BASEM312_BASEM312_BASEM312_BASEM312_BASEM312_BASEM312_BASEM312_BASEM312_CONNECTORM1006_ic_body" />
  <axis  xyz="0 0 0" />
 </joint>
 <joint  type="fixed"  name="BASEM9_BASEM312_BASEM312_BASEM312_BASEM312_BASEM312_BASEM312_BASEM312_BASEM312_BASEM312_BASEM312_BASEM312_BASEM312_CONNECTORM1006_ic_medium_2" >
  <origin  xyz="0 0 -0.0094"  rpy="0 0 0" />
  <parent  link="BASEM9_BASEM312_BASEM312_BASEM312_BASEM312_BASEM312_BASEM312_BASEM312_BASEM312_BASEM312_BASEM312_BASEM312_BASEM312_CONNECTORM1006_ic_body" />
  <child  link="BASEM9_BASEM312_BASEM312_BASEM312_BASEM312_BASEM312_BASEM312_BASEM312_BASEM312_BASEM312_BASEM312_BASEM312_BASEM312_CONNECTORM1006_ic_in" />
  <axis  xyz="0 0 0" />
 </joint>
 <joint  type="revolute"  name="BASEM9_BASEM312_BASEM312_BASEM312_BASEM312_BASEM312_BASEM312_BASEM312_BASEM312_BASEM312_BASEM312_BASEM312_JOINTM690_tj_medium_1" >
  <origin  xyz="0.0 0.0 0.0"  rpy="0.0 0.0 3.141592653589793" />
  <parent  link="BASEM9_BASEM312_BASEM312_BASEM312_BASEM312_BASEM312_BASEM312_BASEM312_BASEM312_BASEM312_BASEM312_BASEM312_BASEM312_CONNECTORM1006_ic_in" />
  <child  link="BASEM9_BASEM312_BASEM312_BASEM312_BASEM312_BASEM312_BASEM312_BASEM312_BASEM312_BASEM312_BASEM312_BASEM312_JOINTM690_tj_body" />
  <axis  xyz="0 0 1" />
  <limit  velocity="0.33"  lower="-3.1416"  upper="3.1416"  effort="25.5" />
 </joint>
 <joint  type="fixed"  name="BASEM9_BASEM312_BASEM312_BASEM312_BASEM312_BASEM312_BASEM312_BASEM312_BASEM312_BASEM312_BASEM312_BASEM312_JOINTM690_tj_medium_2" >
  <origin  xyz="-0.047 0 -0.0635"  rpy="0 1.5707963267949 0" />
  <parent  link="BASEM9_BASEM312_BASEM312_BASEM312_BASEM312_BASEM312_BASEM312_BASEM312_BASEM312_BASEM312_BASEM312_BASEM312_JOINTM690_tj_body" />
  <child  link="BASEM9_BASEM312_BASEM312_BASEM312_BASEM312_BASEM312_BASEM312_BASEM312_BASEM312_BASEM312_BASEM312_BASEM312_JOINTM690_tj_in" />
  <axis  xyz="0 -1 0" />
 </joint>
 <joint  type="fixed"  name="BASEM9_BASEM312_BASEM312_BASEM312_BASEM312_BASEM312_BASEM312_BASEM312_BASEM312_BASEM312_BASEM312_CONNECTORM1007_ic_medium_1" >
  <origin  xyz="0 0 0"  rpy="0 0 0" />
  <parent  link="BASEM9_BASEM312_BASEM312_BASEM312_BASEM312_BASEM312_BASEM312_BASEM312_BASEM312_BASEM312_BASEM312_BASEM312_JOINTM690_tj_in" />
  <child  link="BASEM9_BASEM312_BASEM312_BASEM312_BASEM312_BASEM312_BASEM312_BASEM312_BASEM312_BASEM312_BASEM312_CONNECTORM1007_ic_body" />
  <axis  xyz="0 0 0" />
 </joint>
 <joint  type="fixed"  name="BASEM9_BASEM312_BASEM312_BASEM312_BASEM312_BASEM312_BASEM312_BASEM312_BASEM312_BASEM312_BASEM312_CONNECTORM1007_ic_medium_2" >
  <origin  xyz="0 0 -0.0094"  rpy="0 0 0" />
  <parent  link="BASEM9_BASEM312_BASEM312_BASEM312_BASEM312_BASEM312_BASEM312_BASEM312_BASEM312_BASEM312_BASEM312_CONNECTORM1007_ic_body" />
  <child  link="BASEM9_BASEM312_BASEM312_BASEM312_BASEM312_BASEM312_BASEM312_BASEM312_BASEM312_BASEM312_BASEM312_CONNECTORM1007_ic_in" />
  <axis  xyz="0 0 0" />
 </joint>
 <joint  type="fixed"  name="BASEM9_BASEM312_BASEM312_BASEM312_BASEM312_BASEM312_BASEM312_BASEM312_BASEM312_BASEM312_STRAIGHTLINKMS100_sl_medium" >
  <origin  xyz="0 0 0"  rpy="0 0 0" />
  <parent  link="BASEM9_BASEM312_BASEM312_BASEM312_BASEM312_BASEM312_BASEM312_BASEM312_BASEM312_BASEM312_BASEM312_CONNECTORM1007_ic_in" />
  <child  link="BASEM9_BASEM312_BASEM312_BASEM312_BASEM312_BASEM312_BASEM312_BASEM312_BASEM312_BASEM312_STRAIGHTLINKMS100_sl_body" />
  <axis  xyz="0 0 0" />
 </joint>
 <joint  type="fixed"  name="BASEM9_BASEM312_BASEM312_BASEM312_BASEM312_BASEM312_BASEM312_BASEM312_BASEM312_BASEM312_STRAIGHTLINKMS100_sl_small" >
  <origin  xyz="0 0 -0.2"  rpy="3.1416 0 0" />
  <parent  link="BASEM9_BASEM312_BASEM312_BASEM312_BASEM312_BASEM312_BASEM312_BASEM312_BASEM312_BASEM312_STRAIGHTLINKMS100_sl_body" />
  <child  link="BASEM9_BASEM312_BASEM312_BASEM312_BASEM312_BASEM312_BASEM312_BASEM312_BASEM312_CONNECTORS144_reverse_ic_in" />
  <axis  xyz="0 0 0" />
 </joint>
 <joint  type="fixed"  name="BASEM9_BASEM312_BASEM312_BASEM312_BASEM312_BASEM312_BASEM312_BASEM312_BASEM312_CONNECTORS144_reverse_ic_small_2" >
  <origin  xyz="0.0 0.0 0.0073"  rpy="0.0 0.0 3.141592653589793" />
  <parent  link="BASEM9_BASEM312_BASEM312_BASEM312_BASEM312_BASEM312_BASEM312_BASEM312_BASEM312_CONNECTORS144_reverse_ic_in" />
  <child  link="BASEM9_BASEM312_BASEM312_BASEM312_BASEM312_BASEM312_BASEM312_BASEM312_BASEM312_CONNECTORS144_reverse_ic_body" />
  <axis  xyz="0 0 0" />
 </joint>
 <joint  type="fixed"  name="BASEM9_BASEM312_BASEM312_BASEM312_BASEM312_BASEM312_BASEM312_BASEM312_BASEM312_CONNECTORS144_reverse_ic_small_1" >
  <origin  xyz="-0.0 -0.0 -0.0"  rpy="0.0 0.0 0.0" />
  <parent  link="BASEM9_BASEM312_BASEM312_BASEM312_BASEM312_BASEM312_BASEM312_BASEM312_BASEM312_CONNECTORS144_reverse_ic_body" />
  <child  link="BASEM9_BASEM312_BASEM312_BASEM312_BASEM312_BASEM312_BASEM312_BASEM312_JOINTS140_reverse_tj_in" />
  <axis  xyz="0 0 0" />
 </joint>
 <joint  type="fixed"  name="BASEM9_BASEM312_BASEM312_BASEM312_BASEM312_BASEM312_BASEM312_BASEM312_JOINTS140_reverse_tj_small_2" >
  <origin  xyz="-0.057500000000000134 -0.0 0.036499999999999796"  rpy="0.0 -1.5707963267949 0.0" />
  <parent  link="BASEM9_BASEM312_BASEM312_BASEM312_BASEM312_BASEM312_BASEM312_BASEM312_JOINTS140_reverse_tj_in" />
  <child  link="BASEM9_BASEM312_BASEM312_BASEM312_BASEM312_BASEM312_BASEM312_BASEM312_JOINTS140_reverse_tj_body" />
  <axis  xyz="0 0 0" />
 </joint>
 <joint  type="revolute"  name="BASEM9_BASEM312_BASEM312_BASEM312_BASEM312_BASEM312_BASEM312_BASEM312_JOINTS140_reverse_tj_small_1" >
  <origin  xyz="-0.0 -0.0 -0.0"  rpy="0.0 0.0 0.0" />
  <parent  link="BASEM9_BASEM312_BASEM312_BASEM312_BASEM312_BASEM312_BASEM312_BASEM312_JOINTS140_reverse_tj_body" />
  <child  link="BASEM9_BASEM312_BASEM312_BASEM312_BASEM312_BASEM312_BASEM312_CONNECTORS145_reverse_ic_in" />
  <axis  xyz="0 0 1" />
  <limit  velocity="0.4"  lower="-3.1416"  upper="3.1416"  effort="4.5" />
 </joint>
 <joint  type="fixed"  name="BASEM9_BASEM312_BASEM312_BASEM312_BASEM312_BASEM312_BASEM312_CONNECTORS145_reverse_ic_small_2" >
  <origin  xyz="0.0 0.0 0.0073"  rpy="0.0 0.0 3.141592653589793" />
  <parent  link="BASEM9_BASEM312_BASEM312_BASEM312_BASEM312_BASEM312_BASEM312_CONNECTORS145_reverse_ic_in" />
  <child  link="BASEM9_BASEM312_BASEM312_BASEM312_BASEM312_BASEM312_BASEM312_CONNECTORS145_reverse_ic_body" />
  <axis  xyz="0 0 0" />
 </joint>
 <joint  type="fixed"  name="BASEM9_BASEM312_BASEM312_BASEM312_BASEM312_BASEM312_BASEM312_CONNECTORS145_reverse_ic_small_1" >
  <origin  xyz="-0.0 -0.0 -0.0"  rpy="0.0 0.0 0.0" />
  <parent  link="BASEM9_BASEM312_BASEM312_BASEM312_BASEM312_BASEM312_BASEM312_CONNECTORS145_reverse_ic_body" />
  <child  link="BASEM9_BASEM312_BASEM312_BASEM312_BASEM312_BASEM312_JOINTS141_reverse_tj_in" />
  <axis  xyz="0 0 0" />
 </joint>
 <joint  type="fixed"  name="BASEM9_BASEM312_BASEM312_BASEM312_BASEM312_BASEM312_JOINTS141_reverse_tj_small_2" >
  <origin  xyz="-0.057500000000000134 -0.0 0.036499999999999796"  rpy="0.0 -1.5707963267949 0.0" />
  <parent  link="BASEM9_BASEM312_BASEM312_BASEM312_BASEM312_BASEM312_JOINTS141_reverse_tj_in" />
  <child  link="BASEM9_BASEM312_BASEM312_BASEM312_BASEM312_BASEM312_JOINTS141_reverse_tj_body" />
  <axis  xyz="0 0 0" />
 </joint>
 <joint  type="revolute"  name="BASEM9_BASEM312_BASEM312_BASEM312_BASEM312_BASEM312_JOINTS141_reverse_tj_small_1" >
  <origin  xyz="-0.0 -0.0 -0.0"  rpy="0.0 0.0 0.0" />
  <parent  link="BASEM9_BASEM312_BASEM312_BASEM312_BASEM312_BASEM312_JOINTS141_reverse_tj_body" />
  <child  link="BASEM9_BASEM312_BASEM312_BASEM312_BASEM312_CONNECTORS146_reverse_ic_in" />
  <axis  xyz="0 0 1" />
  <limit  velocity="0.4"  lower="-3.1416"  upper="3.1416"  effort="4.5" />
 </joint>
 <joint  type="fixed"  name="BASEM9_BASEM312_BASEM312_BASEM312_BASEM312_CONNECTORS146_reverse_ic_small_2" >
  <origin  xyz="0.0 0.0 0.0073"  rpy="0.0 0.0 3.141592653589793" />
  <parent  link="BASEM9_BASEM312_BASEM312_BASEM312_BASEM312_CONNECTORS146_reverse_ic_in" />
  <child  link="BASEM9_BASEM312_BASEM312_BASEM312_BASEM312_CONNECTORS146_reverse_ic_body" />
  <axis  xyz="0 0 0" />
 </joint>
 <joint  type="fixed"  name="BASEM9_BASEM312_BASEM312_BASEM312_BASEM312_CONNECTORS146_reverse_ic_small_1" >
  <origin  xyz="-0.0 -0.0 -0.0"  rpy="0.0 0.0 0.0" />
  <parent  link="BASEM9_BASEM312_BASEM312_BASEM312_BASEM312_CONNECTORS146_reverse_ic_body" />
  <child  link="BASEM9_BASEM312_BASEM312_BASEM312_JOINTS142_reverse_tj_in" />
  <axis  xyz="0 0 0" />
 </joint>
 <joint  type="fixed"  name="BASEM9_BASEM312_BASEM312_BASEM312_JOINTS142_reverse_tj_small_2" >
  <origin  xyz="-0.057500000000000134 -0.0 0.036499999999999796"  rpy="0.0 -1.5707963267949 0.0" />
  <parent  link="BASEM9_BASEM312_BASEM312_BASEM312_JOINTS142_reverse_tj_in" />
  <child  link="BASEM9_BASEM312_BASEM312_BASEM312_JOINTS142_reverse_tj_body" />
  <axis  xyz="0 0 0" />
 </joint>
 <joint  type="revolute"  name="BASEM9_BASEM312_BASEM312_BASEM312_JOINTS142_reverse_tj_small_1" >
  <origin  xyz="-0.0 -0.0 -0.0"  rpy="0.0 0.0 0.0" />
  <parent  link="BASEM9_BASEM312_BASEM312_BASEM312_JOINTS142_reverse_tj_body" />
  <child  link="BASEM9_BASEM312_BASEM312_CONNECTORS147_reverse_CONNECTORS147_ic_in" />
  <axis  xyz="0 0 1" />
  <limit  velocity="0.4"  lower="-3.1416"  upper="3.1416"  effort="4.5" />
 </joint>
 <joint  type="fixed"  name="BASEM9_BASEM312_BASEM312_CONNECTORS147_reverse_CONNECTORS147_ic_small_2" >
  <origin  xyz="-0.0 -0.0 0.0073"  rpy="0.0 0.0 0.0" />
  <parent  link="BASEM9_BASEM312_BASEM312_CONNECTORS147_reverse_CONNECTORS147_ic_in" />
  <child  link="BASEM9_BASEM312_BASEM312_CONNECTORS147_reverse_CONNECTORS147_ic_body" />
  <axis  xyz="0 0 0" />
 </joint>
 <joint  type="fixed"  name="BASEM9_BASEM312_BASEM312_CONNECTORS147_reverse_CONNECTORS147_ic_small_1" >
  <origin  xyz="-0.0 -0.0 -0.0"  rpy="0.0 0.0 0.0" />
  <parent  link="BASEM9_BASEM312_BASEM312_CONNECTORS147_reverse_CONNECTORS147_ic_body" />
  <child  link="BASEM9_BASEM312_ENDEFFECTORS4_ee_in" />
  <axis  xyz="0 0 0" />
 </joint>
 <joint  type="fixed"  name="BASEM9_BASEM312_ENDEFFECTORS4_ee_small" >
  <origin  xyz="0 0 0"  rpy="0 0 0" />
  <parent  link="BASEM9_BASEM312_ENDEFFECTORS4_ee_in" />
  <child  link="BASEM9_BASEM312_ENDEFFECTORS4_ee_body" />
  <axis  xyz="0 0 0" />
 </joint>
</robot>
