<?xml version="1.0"?>
<robot  name="UNNAMED_557" >
 <link  name="JMM223_JTMU7079_JTMU7079_JTMU7079_JTMU7079_JTMU7079_JTMU7079_JTMU7079_JTMU7079_JTMU7079_JTMU7079_JTMU7079_JTMU7079_JTMU7079_JTMU7079_JTMU7079_JTMU7079_JTMU7079_JTMU7079_JTMU7079_JTMU7079_JTMU7079_JTMU7079_JTMU7079_JTMU7079_JTMU7079_JTMU7079_JTMU7079_JTMU7079_JTMU7079_JTMU7079_JTMU7079_JTMU7079_JTMU7079_JTMU7079_U_tj_out" >
  <inertial >
   <origin  rpy="0 0 0"  xyz="-0.0020588 8.3685E-09 -0.0635" />
   <mass  value="0.93066" />
   <inertia  iyz="-1.9911E-10"  ixy="8.3821E-10"  ixz="1.078E-20"  ixx="0.0017462"  izz="0.0011044"  iyy="0.0017615" />
  </inertial>
  <visual >
   <origin  rpy="0 0 0"  xyz="0 0 0" />
   <geometry >
    <mesh  filename="package://jointT-m.SLDASM/meshes/tj_out.STL" />
   </geometry>
   <material  name="red" >
    <color  rgba="0.5 0 0 1" />
   </material>
  </visual>
  <collision >
   <origin  rpy="0 0 0"  xyz="0 0 0" />
   <geometry >
    <mesh  filename="package://jointT-m.SLDASM/meshes/tj_out.STL" />
   </geometry>
  </collision>
 </link>
 <link  name="JMM223_JTMU7079_JTMU7079_JTMU7079_JTMU7079_JTMU7079_JTMU7079_JTMU7079_JTMU7079_JTMU7079_JTMU7079_JTMU7079_JTMU7079_JTMU7079_JTMU7079_JTMU7079_JTMU7079_JTMU7079_JTMU7079_JTMU7079_JTMU7079_JTMU7079_JTMU7079_JTMU7079_JTMU7079_JTMU7079_JTMU7079_JTMU7079_JTMU7079_JTMU7079_JTMU7079_JTMU7079_JTMU7079_JTMU7079_JTMU7079_U_tj_body" >
  <inertial >
   <origin  rpy="0 0 0"  xyz="-0.0020574 -5.8806E-08 -0.0635" />
   <mass  value="0.93065" />
   <inertia  iyz="-1.9911E-10"  ixy="8.3821E-10"  ixz="1.078E-20"  ixx="0.0017462"  izz="0.0011044"  iyy="0.0017615" />
  </inertial>
  <visual >
   <origin  rpy="0 0 0"  xyz="0 0 0" />
   <geometry >
    <mesh  filename="package://jointT-m.SLDASM/meshes/tj_body.STL" />
   </geometry>
   <material  name="body" >
    <color  rgba="0.5 0.5 0.5 1" />
   </material>
  </visual>
  <collision >
   <origin  rpy="0 0 0"  xyz="0 0 0" />
   <geometry >
    <mesh  filename="package://jointT-m.SLDASM/meshes/tj_body.STL" />
   </geometry>
  </collision>
 </link>
 <link  name="JMM223_JTMU7079_JTMU7079_JTMU7079_JTMU7079_JTMU7079_JTMU7079_JTMU7079_JTMU7079_JTMU7079_JTMU7079_JTMU7079_JTMU7079_JTMU7079_JTMU7079_JTMU7079_JTMU7079_JTMU7079_JTMU7079_JTMU7079_JTMU7079_JTMU7079_JTMU7079_JTMU7079_JTMU7079_JTMU7079_JTMU7079_JTMU7079_JTMU7079_JTMU7079_JTMU7079_JTMU7079_JTMU7079_JTMU7079_JTMU7079_U_tj_in" >
  <inertial >
   <origin  rpy="0 0 0"  xyz="-6.5585E-18 8.3685E-09 0.044941" />
   <mass  value="0.93066" />
   <inertia  iyz="8.3821E-10"  ixy="1.9911E-10"  ixz="1.0711E-19"  ixx="0.0011044"  izz="0.0017462"  iyy="0.0017615" />
  </inertial>
  <visual >
   <origin  rpy="0 0 0"  xyz="0 0 0" />
   <geometry >
    <mesh  filename="package://jointT-m.SLDASM/meshes/tj_in.STL" />
   </geometry>
   <material  name="blue" >
    <color  rgba="0 0 0.5 1" />
   </material>
  </visual>
  <collision >
   <origin  rpy="0 0 0"  xyz="0 0 0" />
   <geometry >
    <mesh  filename="package://jointT-m.SLDASM/meshes/tj_in.STL" />
   </geometry>
  </collision>
 </link>
 <link  name="JMM223_JTMU7079_JTMU7079_JTMU7079_JTMU7079_JTMU7079_JTMU7079_JTMU7079_JTMU7079_JTMU7079_JTMU7079_JTMU7079_JTMU7079_JTMU7079_JTMU7079_JTMU7079_JTMU7079_JTMU7079_JTMU7079_JTMU7079_JTMU7079_JTMU7079_JTMU7079_JTMU7079_JTMU7079_JTMU7079_JTMU7079_JTMU7079_JTMU7079_JTMU7079_JTMU7079_JTMU7079_JTMU7079_JTMU7079_IMU7203_U_ic_body" >
  <inertial >
   <origin  rpy="0 0 0"  xyz="0 -4.8218E-18 -0.0047" />
   <mass  value="0" />
   <inertia  iyz="0"  ixy="0"  ixz="2.1721E-37"  ixx="0.00028474"  izz="0.000562"  iyy="0.00028474" />
  </inertial>
  <visual >
   <origin  rpy="0 0 0"  xyz="0 0 0" />
   <geometry >
    <mesh  filename="package://input_connector_m.SLDASM/meshes/ic_body.STL" />
   </geometry>
   <material  name="blue" >
    <color  rgba="0 0 0.5 1" />
   </material>
  </visual>
  <collision >
   <origin  rpy="0 0 0"  xyz="0 0 0" />
   <geometry >
    <mesh  filename="package://input_connector_m.SLDASM/meshes/ic_body.STL" />
   </geometry>
  </collision>
 </link>
 <link  name="JMM223_JTMU7079_JTMU7079_JTMU7079_JTMU7079_JTMU7079_JTMU7079_JTMU7079_JTMU7079_JTMU7079_JTMU7079_JTMU7079_JTMU7079_JTMU7079_JTMU7079_JTMU7079_JTMU7079_JTMU7079_JTMU7079_JTMU7079_JTMU7079_JTMU7079_JTMU7079_JTMU7079_JTMU7079_JTMU7079_JTMU7079_JTMU7079_JTMU7079_JTMU7079_JTMU7079_JTMU7079_JTMU7079_JTMU7079_IMU7203_U_ic_in" >
  <inertial >
   <origin  rpy="0 0 0"  xyz="-4.5413E-34 1.0801E-17 0.0047" />
   <mass  value="0.50882" />
   <inertia  iyz="0"  ixy="0"  ixz="2.1721E-37"  ixx="0.00028474"  izz="0.000562"  iyy="0.00028474" />
  </inertial>
  <visual >
   <origin  rpy="0 0 0"  xyz="0 0 0" />
   <geometry >
    <mesh  filename="package://input_connector_m.SLDASM/meshes/ic_in.STL" />
   </geometry>
   <material  name="blue" >
    <color  rgba="0 0 0.5 1" />
   </material>
  </visual>
  <collision >
   <origin  rpy="0 0 0"  xyz="0 0 0" />
   <geometry >
    <mesh  filename="package://input_connector_m.SLDASM/meshes/ic_in.STL" />
   </geometry>
  </collision>
 </link>
 <link  name="JMM223_JTMU7079_JTMU7079_JTMU7079_JTMU7079_JTMU7079_JTMU7079_JTMU7079_JTMU7079_JTMU7079_JTMU7079_JTMU7079_JTMU7079_JTMU7079_JTMU7079_JTMU7079_JTMU7079_JTMU7079_JTMU7079_JTMU7079_JTMU7079_JTMU7079_JTMU7079_JTMU7079_JTMU7079_JTMU7079_JTMU7079_JTMU7079_JTMU7079_JTMU7079_JTMU7079_JTMU7079_JTMU7079_JTMU7080_U_tj_body" >
  <inertial >
   <origin  rpy="0 0 0"  xyz="-0.0020574 -5.8806E-08 -0.0635" />
   <mass  value="0.93065" />
   <inertia  iyz="-1.9911E-10"  ixz="1.078E-20"  ixy="8.3821E-10"  ixx="0.0017462"  izz="0.0011044"  iyy="0.0017615" />
  </inertial>
  <visual >
   <origin  rpy="0 0 0"  xyz="0 0 0" />
   <geometry >
    <mesh  filename="package://jointT-m.SLDASM/meshes/tj_body.STL" />
   </geometry>
   <material  name="body" >
    <color  rgba="0.5 0.5 0.5 1" />
   </material>
  </visual>
  <collision >
   <origin  rpy="0 0 0"  xyz="0 0 0" />
   <geometry >
    <mesh  filename="package://jointT-m.SLDASM/meshes/tj_body.STL" />
   </geometry>
  </collision>
 </link>
 <link  name="JMM223_JTMU7079_JTMU7079_JTMU7079_JTMU7079_JTMU7079_JTMU7079_JTMU7079_JTMU7079_JTMU7079_JTMU7079_JTMU7079_JTMU7079_JTMU7079_JTMU7079_JTMU7079_JTMU7079_JTMU7079_JTMU7079_JTMU7079_JTMU7079_JTMU7079_JTMU7079_JTMU7079_JTMU7079_JTMU7079_JTMU7079_JTMU7079_JTMU7079_JTMU7079_JTMU7079_JTMU7079_JTMU7079_JTMU7080_U_tj_in" >
  <inertial >
   <origin  rpy="0 0 0"  xyz="-6.5585E-18 8.3685E-09 0.044941" />
   <mass  value="0.93066" />
   <inertia  iyz="8.3821E-10"  ixz="1.0711E-19"  ixy="1.9911E-10"  ixx="0.0011044"  izz="0.0017462"  iyy="0.0017615" />
  </inertial>
  <visual >
   <origin  rpy="0 0 0"  xyz="0 0 0" />
   <geometry >
    <mesh  filename="package://jointT-m.SLDASM/meshes/tj_in.STL" />
   </geometry>
   <material  name="blue" >
    <color  rgba="0 0 0.5 1" />
   </material>
  </visual>
  <collision >
   <origin  rpy="0 0 0"  xyz="0 0 0" />
   <geometry >
    <mesh  filename="package://jointT-m.SLDASM/meshes/tj_in.STL" />
   </geometry>
  </collision>
 </link>
 <link  name="JMM223_JTMU7079_JTMU7079_JTMU7079_JTMU7079_JTMU7079_JTMU7079_JTMU7079_JTMU7079_JTMU7079_JTMU7079_JTMU7079_JTMU7079_JTMU7079_JTMU7079_JTMU7079_JTMU7079_JTMU7079_JTMU7079_JTMU7079_JTMU7079_JTMU7079_JTMU7079_JTMU7079_JTMU7079_JTMU7079_JTMU7079_JTMU7079_JTMU7079_JTMU7079_JTMU7079_JTMU7079_IMU7204_U_ic_body" >
  <inertial >
   <origin  rpy="0 0 0"  xyz="0 -4.8218E-18 -0.0047" />
   <mass  value="0" />
   <inertia  iyz="0"  ixy="0"  ixz="2.1721E-37"  ixx="0.00028474"  izz="0.000562"  iyy="0.00028474" />
  </inertial>
  <visual >
   <origin  rpy="0 0 0"  xyz="0 0 0" />
   <geometry >
    <mesh  filename="package://input_connector_m.SLDASM/meshes/ic_body.STL" />
   </geometry>
   <material  name="blue" >
    <color  rgba="0 0 0.5 1" />
   </material>
  </visual>
  <collision >
   <origin  rpy="0 0 0"  xyz="0 0 0" />
   <geometry >
    <mesh  filename="package://input_connector_m.SLDASM/meshes/ic_body.STL" />
   </geometry>
  </collision>
 </link>
 <link  name="JMM223_JTMU7079_JTMU7079_JTMU7079_JTMU7079_JTMU7079_JTMU7079_JTMU7079_JTMU7079_JTMU7079_JTMU7079_JTMU7079_JTMU7079_JTMU7079_JTMU7079_JTMU7079_JTMU7079_JTMU7079_JTMU7079_JTMU7079_JTMU7079_JTMU7079_JTMU7079_JTMU7079_JTMU7079_JTMU7079_JTMU7079_JTMU7079_JTMU7079_JTMU7079_JTMU7079_JTMU7079_IMU7204_U_ic_in" >
  <inertial >
   <origin  rpy="0 0 0"  xyz="-4.5413E-34 1.0801E-17 0.0047" />
   <mass  value="0.50882" />
   <inertia  iyz="0"  ixy="0"  ixz="2.1721E-37"  ixx="0.00028474"  izz="0.000562"  iyy="0.00028474" />
  </inertial>
  <visual >
   <origin  rpy="0 0 0"  xyz="0 0 0" />
   <geometry >
    <mesh  filename="package://input_connector_m.SLDASM/meshes/ic_in.STL" />
   </geometry>
   <material  name="blue" >
    <color  rgba="0 0 0.5 1" />
   </material>
  </visual>
  <collision >
   <origin  rpy="0 0 0"  xyz="0 0 0" />
   <geometry >
    <mesh  filename="package://input_connector_m.SLDASM/meshes/ic_in.STL" />
   </geometry>
  </collision>
 </link>
 <link  name="JMM223_JTMU7079_JTMU7079_JTMU7079_JTMU7079_JTMU7079_JTMU7079_JTMU7079_JTMU7079_JTMU7079_JTMU7079_JTMU7079_JTMU7079_JTMU7079_JTMU7079_JTMU7079_JTMU7079_JTMU7079_JTMU7079_JTMU7079_JTMU7079_JTMU7079_JTMU7079_JTMU7079_JTMU7079_JTMU7079_JTMU7079_JTMU7079_JTMU7079_JTMU7079_JTMU7079_JTMU7081_U_tj_body" >
  <inertial >
   <origin  rpy="0 0 0"  xyz="-0.0020574 -5.8806E-08 -0.0635" />
   <mass  value="0.93065" />
   <inertia  iyz="-1.9911E-10"  ixz="1.078E-20"  ixy="8.3821E-10"  ixx="0.0017462"  izz="0.0011044"  iyy="0.0017615" />
  </inertial>
  <visual >
   <origin  rpy="0 0 0"  xyz="0 0 0" />
   <geometry >
    <mesh  filename="package://jointT-m.SLDASM/meshes/tj_body.STL" />
   </geometry>
   <material  name="body" >
    <color  rgba="0.5 0.5 0.5 1" />
   </material>
  </visual>
  <collision >
   <origin  rpy="0 0 0"  xyz="0 0 0" />
   <geometry >
    <mesh  filename="package://jointT-m.SLDASM/meshes/tj_body.STL" />
   </geometry>
  </collision>
 </link>
 <link  name="JMM223_JTMU7079_JTMU7079_JTMU7079_JTMU7079_JTMU7079_JTMU7079_JTMU7079_JTMU7079_JTMU7079_JTMU7079_JTMU7079_JTMU7079_JTMU7079_JTMU7079_JTMU7079_JTMU7079_JTMU7079_JTMU7079_JTMU7079_JTMU7079_JTMU7079_JTMU7079_JTMU7079_JTMU7079_JTMU7079_JTMU7079_JTMU7079_JTMU7079_JTMU7079_JTMU7079_JTMU7081_U_tj_in" >
  <inertial >
   <origin  rpy="0 0 0"  xyz="-6.5585E-18 8.3685E-09 0.044941" />
   <mass  value="0.93066" />
   <inertia  iyz="8.3821E-10"  ixz="1.0711E-19"  ixy="1.9911E-10"  ixx="0.0011044"  izz="0.0017462"  iyy="0.0017615" />
  </inertial>
  <visual >
   <origin  rpy="0 0 0"  xyz="0 0 0" />
   <geometry >
    <mesh  filename="package://jointT-m.SLDASM/meshes/tj_in.STL" />
   </geometry>
   <material  name="blue" >
    <color  rgba="0 0 0.5 1" />
   </material>
  </visual>
  <collision >
   <origin  rpy="0 0 0"  xyz="0 0 0" />
   <geometry >
    <mesh  filename="package://jointT-m.SLDASM/meshes/tj_in.STL" />
   </geometry>
  </collision>
 </link>
 <link  name="JMM223_JTMU7079_JTMU7079_JTMU7079_JTMU7079_JTMU7079_JTMU7079_JTMU7079_JTMU7079_JTMU7079_JTMU7079_JTMU7079_JTMU7079_JTMU7079_JTMU7079_JTMU7079_JTMU7079_JTMU7079_JTMU7079_JTMU7079_JTMU7079_JTMU7079_JTMU7079_JTMU7079_JTMU7079_JTMU7079_JTMU7079_JTMU7079_JTMU7079_JTMU7079_IMU7205_U_ic_body" >
  <inertial >
   <origin  rpy="0 0 0"  xyz="0 -4.8218E-18 -0.0047" />
   <mass  value="0" />
   <inertia  iyz="0"  ixy="0"  ixz="2.1721E-37"  ixx="0.00028474"  izz="0.000562"  iyy="0.00028474" />
  </inertial>
  <visual >
   <origin  rpy="0 0 0"  xyz="0 0 0" />
   <geometry >
    <mesh  filename="package://input_connector_m.SLDASM/meshes/ic_body.STL" />
   </geometry>
   <material  name="blue" >
    <color  rgba="0 0 0.5 1" />
   </material>
  </visual>
  <collision >
   <origin  rpy="0 0 0"  xyz="0 0 0" />
   <geometry >
    <mesh  filename="package://input_connector_m.SLDASM/meshes/ic_body.STL" />
   </geometry>
  </collision>
 </link>
 <link  name="JMM223_JTMU7079_JTMU7079_JTMU7079_JTMU7079_JTMU7079_JTMU7079_JTMU7079_JTMU7079_JTMU7079_JTMU7079_JTMU7079_JTMU7079_JTMU7079_JTMU7079_JTMU7079_JTMU7079_JTMU7079_JTMU7079_JTMU7079_JTMU7079_JTMU7079_JTMU7079_JTMU7079_JTMU7079_JTMU7079_JTMU7079_JTMU7079_JTMU7079_JTMU7079_IMU7205_U_ic_in" >
  <inertial >
   <origin  rpy="0 0 0"  xyz="-4.5413E-34 1.0801E-17 0.0047" />
   <mass  value="0.50882" />
   <inertia  iyz="0"  ixy="0"  ixz="2.1721E-37"  ixx="0.00028474"  izz="0.000562"  iyy="0.00028474" />
  </inertial>
  <visual >
   <origin  rpy="0 0 0"  xyz="0 0 0" />
   <geometry >
    <mesh  filename="package://input_connector_m.SLDASM/meshes/ic_in.STL" />
   </geometry>
   <material  name="blue" >
    <color  rgba="0 0 0.5 1" />
   </material>
  </visual>
  <collision >
   <origin  rpy="0 0 0"  xyz="0 0 0" />
   <geometry >
    <mesh  filename="package://input_connector_m.SLDASM/meshes/ic_in.STL" />
   </geometry>
  </collision>
 </link>
 <link  name="JMM223_JTMU7079_JTMU7079_JTMU7079_JTMU7079_JTMU7079_JTMU7079_JTMU7079_JTMU7079_JTMU7079_JTMU7079_JTMU7079_JTMU7079_JTMU7079_JTMU7079_JTMU7079_JTMU7079_JTMU7079_JTMU7079_JTMU7079_JTMU7079_JTMU7079_JTMU7079_JTMU7079_JTMU7079_JTMU7079_JTMU7079_JTMU7079_JTMU7079_JTMU7082_U_tj_body" >
  <inertial >
   <origin  rpy="0 0 0"  xyz="-0.0020574 -5.8806E-08 -0.0635" />
   <mass  value="0.93065" />
   <inertia  iyz="-1.9911E-10"  ixz="1.078E-20"  ixy="8.3821E-10"  ixx="0.0017462"  izz="0.0011044"  iyy="0.0017615" />
  </inertial>
  <visual >
   <origin  rpy="0 0 0"  xyz="0 0 0" />
   <geometry >
    <mesh  filename="package://jointT-m.SLDASM/meshes/tj_body.STL" />
   </geometry>
   <material  name="body" >
    <color  rgba="0.5 0.5 0.5 1" />
   </material>
  </visual>
  <collision >
   <origin  rpy="0 0 0"  xyz="0 0 0" />
   <geometry >
    <mesh  filename="package://jointT-m.SLDASM/meshes/tj_body.STL" />
   </geometry>
  </collision>
 </link>
 <link  name="JMM223_JTMU7079_JTMU7079_JTMU7079_JTMU7079_JTMU7079_JTMU7079_JTMU7079_JTMU7079_JTMU7079_JTMU7079_JTMU7079_JTMU7079_JTMU7079_JTMU7079_JTMU7079_JTMU7079_JTMU7079_JTMU7079_JTMU7079_JTMU7079_JTMU7079_JTMU7079_JTMU7079_JTMU7079_JTMU7079_JTMU7079_JTMU7079_JTMU7079_JTMU7082_U_tj_in" >
  <inertial >
   <origin  rpy="0 0 0"  xyz="-6.5585E-18 8.3685E-09 0.044941" />
   <mass  value="0.93066" />
   <inertia  iyz="8.3821E-10"  ixz="1.0711E-19"  ixy="1.9911E-10"  ixx="0.0011044"  izz="0.0017462"  iyy="0.0017615" />
  </inertial>
  <visual >
   <origin  rpy="0 0 0"  xyz="0 0 0" />
   <geometry >
    <mesh  filename="package://jointT-m.SLDASM/meshes/tj_in.STL" />
   </geometry>
   <material  name="blue" >
    <color  rgba="0 0 0.5 1" />
   </material>
  </visual>
  <collision >
   <origin  rpy="0 0 0"  xyz="0 0 0" />
   <geometry >
    <mesh  filename="package://jointT-m.SLDASM/meshes/tj_in.STL" />
   </geometry>
  </collision>
 </link>
 <link  name="JMM223_JTMU7079_JTMU7079_JTMU7079_JTMU7079_JTMU7079_JTMU7079_JTMU7079_JTMU7079_JTMU7079_JTMU7079_JTMU7079_JTMU7079_JTMU7079_JTMU7079_JTMU7079_JTMU7079_JTMU7079_JTMU7079_JTMU7079_JTMU7079_JTMU7079_JTMU7079_JTMU7079_JTMU7079_JTMU7079_JTMU7079_JTMU7079_IMU7206_U_ic_body" >
  <inertial >
   <origin  rpy="0 0 0"  xyz="0 -4.8218E-18 -0.0047" />
   <mass  value="0" />
   <inertia  iyz="0"  ixy="0"  ixz="2.1721E-37"  ixx="0.00028474"  izz="0.000562"  iyy="0.00028474" />
  </inertial>
  <visual >
   <origin  rpy="0 0 0"  xyz="0 0 0" />
   <geometry >
    <mesh  filename="package://input_connector_m.SLDASM/meshes/ic_body.STL" />
   </geometry>
   <material  name="blue" >
    <color  rgba="0 0 0.5 1" />
   </material>
  </visual>
  <collision >
   <origin  rpy="0 0 0"  xyz="0 0 0" />
   <geometry >
    <mesh  filename="package://input_connector_m.SLDASM/meshes/ic_body.STL" />
   </geometry>
  </collision>
 </link>
 <link  name="JMM223_JTMU7079_JTMU7079_JTMU7079_JTMU7079_JTMU7079_JTMU7079_JTMU7079_JTMU7079_JTMU7079_JTMU7079_JTMU7079_JTMU7079_JTMU7079_JTMU7079_JTMU7079_JTMU7079_JTMU7079_JTMU7079_JTMU7079_JTMU7079_JTMU7079_JTMU7079_JTMU7079_JTMU7079_JTMU7079_JTMU7079_JTMU7079_IMU7206_U_ic_in" >
  <inertial >
   <origin  rpy="0 0 0"  xyz="-4.5413E-34 1.0801E-17 0.0047" />
   <mass  value="0.50882" />
   <inertia  iyz="0"  ixy="0"  ixz="2.1721E-37"  ixx="0.00028474"  izz="0.000562"  iyy="0.00028474" />
  </inertial>
  <visual >
   <origin  rpy="0 0 0"  xyz="0 0 0" />
   <geometry >
    <mesh  filename="package://input_connector_m.SLDASM/meshes/ic_in.STL" />
   </geometry>
   <material  name="blue" >
    <color  rgba="0 0 0.5 1" />
   </material>
  </visual>
  <collision >
   <origin  rpy="0 0 0"  xyz="0 0 0" />
   <geometry >
    <mesh  filename="package://input_connector_m.SLDASM/meshes/ic_in.STL" />
   </geometry>
  </collision>
 </link>
 <link  name="JMM223_JTMU7079_JTMU7079_JTMU7079_JTMU7079_JTMU7079_JTMU7079_JTMU7079_JTMU7079_JTMU7079_JTMU7079_JTMU7079_JTMU7079_JTMU7079_JTMU7079_JTMU7079_JTMU7079_JTMU7079_JTMU7079_JTMU7079_JTMU7079_JTMU7079_JTMU7079_JTMU7079_JTMU7079_JTMU7079_JTMU7079_JTMU7083_U_tj_body" >
  <inertial >
   <origin  rpy="0 0 0"  xyz="-0.0020574 -5.8806E-08 -0.0635" />
   <mass  value="0.93065" />
   <inertia  iyz="-1.9911E-10"  ixz="1.078E-20"  ixy="8.3821E-10"  ixx="0.0017462"  izz="0.0011044"  iyy="0.0017615" />
  </inertial>
  <visual >
   <origin  rpy="0 0 0"  xyz="0 0 0" />
   <geometry >
    <mesh  filename="package://jointT-m.SLDASM/meshes/tj_body.STL" />
   </geometry>
   <material  name="body" >
    <color  rgba="0.5 0.5 0.5 1" />
   </material>
  </visual>
  <collision >
   <origin  rpy="0 0 0"  xyz="0 0 0" />
   <geometry >
    <mesh  filename="package://jointT-m.SLDASM/meshes/tj_body.STL" />
   </geometry>
  </collision>
 </link>
 <link  name="JMM223_JTMU7079_JTMU7079_JTMU7079_JTMU7079_JTMU7079_JTMU7079_JTMU7079_JTMU7079_JTMU7079_JTMU7079_JTMU7079_JTMU7079_JTMU7079_JTMU7079_JTMU7079_JTMU7079_JTMU7079_JTMU7079_JTMU7079_JTMU7079_JTMU7079_JTMU7079_JTMU7079_JTMU7079_JTMU7079_JTMU7079_JTMU7083_U_tj_in" >
  <inertial >
   <origin  rpy="0 0 0"  xyz="-6.5585E-18 8.3685E-09 0.044941" />
   <mass  value="0.93066" />
   <inertia  iyz="8.3821E-10"  ixz="1.0711E-19"  ixy="1.9911E-10"  ixx="0.0011044"  izz="0.0017462"  iyy="0.0017615" />
  </inertial>
  <visual >
   <origin  rpy="0 0 0"  xyz="0 0 0" />
   <geometry >
    <mesh  filename="package://jointT-m.SLDASM/meshes/tj_in.STL" />
   </geometry>
   <material  name="blue" >
    <color  rgba="0 0 0.5 1" />
   </material>
  </visual>
  <collision >
   <origin  rpy="0 0 0"  xyz="0 0 0" />
   <geometry >
    <mesh  filename="package://jointT-m.SLDASM/meshes/tj_in.STL" />
   </geometry>
  </collision>
 </link>
 <link  name="JMM223_JTMU7079_JTMU7079_JTMU7079_JTMU7079_JTMU7079_JTMU7079_JTMU7079_JTMU7079_JTMU7079_JTMU7079_JTMU7079_JTMU7079_JTMU7079_JTMU7079_JTMU7079_JTMU7079_JTMU7079_JTMU7079_JTMU7079_JTMU7079_JTMU7079_JTMU7079_JTMU7079_JTMU7079_JTMU7079_IMU7207_U_ic_body" >
  <inertial >
   <origin  rpy="0 0 0"  xyz="0 -4.8218E-18 -0.0047" />
   <mass  value="0" />
   <inertia  iyz="0"  ixy="0"  ixz="2.1721E-37"  ixx="0.00028474"  izz="0.000562"  iyy="0.00028474" />
  </inertial>
  <visual >
   <origin  rpy="0 0 0"  xyz="0 0 0" />
   <geometry >
    <mesh  filename="package://input_connector_m.SLDASM/meshes/ic_body.STL" />
   </geometry>
   <material  name="blue" >
    <color  rgba="0 0 0.5 1" />
   </material>
  </visual>
  <collision >
   <origin  rpy="0 0 0"  xyz="0 0 0" />
   <geometry >
    <mesh  filename="package://input_connector_m.SLDASM/meshes/ic_body.STL" />
   </geometry>
  </collision>
 </link>
 <link  name="JMM223_JTMU7079_JTMU7079_JTMU7079_JTMU7079_JTMU7079_JTMU7079_JTMU7079_JTMU7079_JTMU7079_JTMU7079_JTMU7079_JTMU7079_JTMU7079_JTMU7079_JTMU7079_JTMU7079_JTMU7079_JTMU7079_JTMU7079_JTMU7079_JTMU7079_JTMU7079_JTMU7079_JTMU7079_JTMU7079_IMU7207_U_ic_in" >
  <inertial >
   <origin  rpy="0 0 0"  xyz="-4.5413E-34 1.0801E-17 0.0047" />
   <mass  value="0.50882" />
   <inertia  iyz="0"  ixy="0"  ixz="2.1721E-37"  ixx="0.00028474"  izz="0.000562"  iyy="0.00028474" />
  </inertial>
  <visual >
   <origin  rpy="0 0 0"  xyz="0 0 0" />
   <geometry >
    <mesh  filename="package://input_connector_m.SLDASM/meshes/ic_in.STL" />
   </geometry>
   <material  name="blue" >
    <color  rgba="0 0 0.5 1" />
   </material>
  </visual>
  <collision >
   <origin  rpy="0 0 0"  xyz="0 0 0" />
   <geometry >
    <mesh  filename="package://input_connector_m.SLDASM/meshes/ic_in.STL" />
   </geometry>
  </collision>
 </link>
 <link  name="JMM223_JTMU7079_JTMU7079_JTMU7079_JTMU7079_JTMU7079_JTMU7079_JTMU7079_JTMU7079_JTMU7079_JTMU7079_JTMU7079_JTMU7079_JTMU7079_JTMU7079_JTMU7079_JTMU7079_JTMU7079_JTMU7079_JTMU7079_JTMU7079_JTMU7079_JTMU7079_JTMU7079_JTMU7079_JTMU7084_U_tj_body" >
  <inertial >
   <origin  rpy="0 0 0"  xyz="-0.0020574 -5.8806E-08 -0.0635" />
   <mass  value="0.93065" />
   <inertia  iyz="-1.9911E-10"  ixz="1.078E-20"  ixy="8.3821E-10"  ixx="0.0017462"  izz="0.0011044"  iyy="0.0017615" />
  </inertial>
  <visual >
   <origin  rpy="0 0 0"  xyz="0 0 0" />
   <geometry >
    <mesh  filename="package://jointT-m.SLDASM/meshes/tj_body.STL" />
   </geometry>
   <material  name="body" >
    <color  rgba="0.5 0.5 0.5 1" />
   </material>
  </visual>
  <collision >
   <origin  rpy="0 0 0"  xyz="0 0 0" />
   <geometry >
    <mesh  filename="package://jointT-m.SLDASM/meshes/tj_body.STL" />
   </geometry>
  </collision>
 </link>
 <link  name="JMM223_JTMU7079_JTMU7079_JTMU7079_JTMU7079_JTMU7079_JTMU7079_JTMU7079_JTMU7079_JTMU7079_JTMU7079_JTMU7079_JTMU7079_JTMU7079_JTMU7079_JTMU7079_JTMU7079_JTMU7079_JTMU7079_JTMU7079_JTMU7079_JTMU7079_JTMU7079_JTMU7079_JTMU7079_JTMU7084_U_tj_in" >
  <inertial >
   <origin  rpy="0 0 0"  xyz="-6.5585E-18 8.3685E-09 0.044941" />
   <mass  value="0.93066" />
   <inertia  iyz="8.3821E-10"  ixz="1.0711E-19"  ixy="1.9911E-10"  ixx="0.0011044"  izz="0.0017462"  iyy="0.0017615" />
  </inertial>
  <visual >
   <origin  rpy="0 0 0"  xyz="0 0 0" />
   <geometry >
    <mesh  filename="package://jointT-m.SLDASM/meshes/tj_in.STL" />
   </geometry>
   <material  name="blue" >
    <color  rgba="0 0 0.5 1" />
   </material>
  </visual>
  <collision >
   <origin  rpy="0 0 0"  xyz="0 0 0" />
   <geometry >
    <mesh  filename="package://jointT-m.SLDASM/meshes/tj_in.STL" />
   </geometry>
  </collision>
 </link>
 <link  name="JMM223_JTMU7079_JTMU7079_JTMU7079_JTMU7079_JTMU7079_JTMU7079_JTMU7079_JTMU7079_JTMU7079_JTMU7079_JTMU7079_JTMU7079_JTMU7079_JTMU7079_JTMU7079_JTMU7079_JTMU7079_JTMU7079_JTMU7079_JTMU7079_JTMU7079_JTMU7079_JTMU7079_IMU7208_U_ic_body" >
  <inertial >
   <origin  rpy="0 0 0"  xyz="0 -4.8218E-18 -0.0047" />
   <mass  value="0" />
   <inertia  iyz="0"  ixy="0"  ixz="2.1721E-37"  ixx="0.00028474"  izz="0.000562"  iyy="0.00028474" />
  </inertial>
  <visual >
   <origin  rpy="0 0 0"  xyz="0 0 0" />
   <geometry >
    <mesh  filename="package://input_connector_m.SLDASM/meshes/ic_body.STL" />
   </geometry>
   <material  name="blue" >
    <color  rgba="0 0 0.5 1" />
   </material>
  </visual>
  <collision >
   <origin  rpy="0 0 0"  xyz="0 0 0" />
   <geometry >
    <mesh  filename="package://input_connector_m.SLDASM/meshes/ic_body.STL" />
   </geometry>
  </collision>
 </link>
 <link  name="JMM223_JTMU7079_JTMU7079_JTMU7079_JTMU7079_JTMU7079_JTMU7079_JTMU7079_JTMU7079_JTMU7079_JTMU7079_JTMU7079_JTMU7079_JTMU7079_JTMU7079_JTMU7079_JTMU7079_JTMU7079_JTMU7079_JTMU7079_JTMU7079_JTMU7079_JTMU7079_JTMU7079_IMU7208_U_ic_in" >
  <inertial >
   <origin  rpy="0 0 0"  xyz="-4.5413E-34 1.0801E-17 0.0047" />
   <mass  value="0.50882" />
   <inertia  iyz="0"  ixy="0"  ixz="2.1721E-37"  ixx="0.00028474"  izz="0.000562"  iyy="0.00028474" />
  </inertial>
  <visual >
   <origin  rpy="0 0 0"  xyz="0 0 0" />
   <geometry >
    <mesh  filename="package://input_connector_m.SLDASM/meshes/ic_in.STL" />
   </geometry>
   <material  name="blue" >
    <color  rgba="0 0 0.5 1" />
   </material>
  </visual>
  <collision >
   <origin  rpy="0 0 0"  xyz="0 0 0" />
   <geometry >
    <mesh  filename="package://input_connector_m.SLDASM/meshes/ic_in.STL" />
   </geometry>
  </collision>
 </link>
 <link  name="JMM223_JTMU7079_JTMU7079_JTMU7079_JTMU7079_JTMU7079_JTMU7079_JTMU7079_JTMU7079_JTMU7079_JTMU7079_JTMU7079_JTMU7079_JTMU7079_JTMU7079_JTMU7079_JTMU7079_JTMU7079_JTMU7079_JTMU7079_JTMU7079_JTMU7079_JTMU7079_JTMU7085_U_tj_body" >
  <inertial >
   <origin  rpy="0 0 0"  xyz="-0.0020574 -5.8806E-08 -0.0635" />
   <mass  value="0.93065" />
   <inertia  iyz="-1.9911E-10"  ixz="1.078E-20"  ixy="8.3821E-10"  ixx="0.0017462"  izz="0.0011044"  iyy="0.0017615" />
  </inertial>
  <visual >
   <origin  rpy="0 0 0"  xyz="0 0 0" />
   <geometry >
    <mesh  filename="package://jointT-m.SLDASM/meshes/tj_body.STL" />
   </geometry>
   <material  name="body" >
    <color  rgba="0.5 0.5 0.5 1" />
   </material>
  </visual>
  <collision >
   <origin  rpy="0 0 0"  xyz="0 0 0" />
   <geometry >
    <mesh  filename="package://jointT-m.SLDASM/meshes/tj_body.STL" />
   </geometry>
  </collision>
 </link>
 <link  name="JMM223_JTMU7079_JTMU7079_JTMU7079_JTMU7079_JTMU7079_JTMU7079_JTMU7079_JTMU7079_JTMU7079_JTMU7079_JTMU7079_JTMU7079_JTMU7079_JTMU7079_JTMU7079_JTMU7079_JTMU7079_JTMU7079_JTMU7079_JTMU7079_JTMU7079_JTMU7079_JTMU7085_U_tj_in" >
  <inertial >
   <origin  rpy="0 0 0"  xyz="-6.5585E-18 8.3685E-09 0.044941" />
   <mass  value="0.93066" />
   <inertia  iyz="8.3821E-10"  ixz="1.0711E-19"  ixy="1.9911E-10"  ixx="0.0011044"  izz="0.0017462"  iyy="0.0017615" />
  </inertial>
  <visual >
   <origin  rpy="0 0 0"  xyz="0 0 0" />
   <geometry >
    <mesh  filename="package://jointT-m.SLDASM/meshes/tj_in.STL" />
   </geometry>
   <material  name="blue" >
    <color  rgba="0 0 0.5 1" />
   </material>
  </visual>
  <collision >
   <origin  rpy="0 0 0"  xyz="0 0 0" />
   <geometry >
    <mesh  filename="package://jointT-m.SLDASM/meshes/tj_in.STL" />
   </geometry>
  </collision>
 </link>
 <link  name="JMM223_JTMU7079_JTMU7079_JTMU7079_JTMU7079_JTMU7079_JTMU7079_JTMU7079_JTMU7079_JTMU7079_JTMU7079_JTMU7079_JTMU7079_JTMU7079_JTMU7079_JTMU7079_JTMU7079_JTMU7079_JTMU7079_JTMU7079_JTMU7079_JTMU7079_IMU7209_U_ic_body" >
  <inertial >
   <origin  rpy="0 0 0"  xyz="0 -4.8218E-18 -0.0047" />
   <mass  value="0" />
   <inertia  iyz="0"  ixy="0"  ixz="2.1721E-37"  ixx="0.00028474"  izz="0.000562"  iyy="0.00028474" />
  </inertial>
  <visual >
   <origin  rpy="0 0 0"  xyz="0 0 0" />
   <geometry >
    <mesh  filename="package://input_connector_m.SLDASM/meshes/ic_body.STL" />
   </geometry>
   <material  name="blue" >
    <color  rgba="0 0 0.5 1" />
   </material>
  </visual>
  <collision >
   <origin  rpy="0 0 0"  xyz="0 0 0" />
   <geometry >
    <mesh  filename="package://input_connector_m.SLDASM/meshes/ic_body.STL" />
   </geometry>
  </collision>
 </link>
 <link  name="JMM223_JTMU7079_JTMU7079_JTMU7079_JTMU7079_JTMU7079_JTMU7079_JTMU7079_JTMU7079_JTMU7079_JTMU7079_JTMU7079_JTMU7079_JTMU7079_JTMU7079_JTMU7079_JTMU7079_JTMU7079_JTMU7079_JTMU7079_JTMU7079_JTMU7079_IMU7209_U_ic_in" >
  <inertial >
   <origin  rpy="0 0 0"  xyz="-4.5413E-34 1.0801E-17 0.0047" />
   <mass  value="0.50882" />
   <inertia  iyz="0"  ixy="0"  ixz="2.1721E-37"  ixx="0.00028474"  izz="0.000562"  iyy="0.00028474" />
  </inertial>
  <visual >
   <origin  rpy="0 0 0"  xyz="0 0 0" />
   <geometry >
    <mesh  filename="package://input_connector_m.SLDASM/meshes/ic_in.STL" />
   </geometry>
   <material  name="blue" >
    <color  rgba="0 0 0.5 1" />
   </material>
  </visual>
  <collision >
   <origin  rpy="0 0 0"  xyz="0 0 0" />
   <geometry >
    <mesh  filename="package://input_connector_m.SLDASM/meshes/ic_in.STL" />
   </geometry>
  </collision>
 </link>
 <link  name="JMM223_JTMU7079_JTMU7079_JTMU7079_JTMU7079_JTMU7079_JTMU7079_JTMU7079_JTMU7079_JTMU7079_JTMU7079_JTMU7079_JTMU7079_JTMU7079_JTMU7079_JTMU7079_JTMU7079_JTMU7079_JTMU7079_JTMU7079_JTMU7079_JTMU7086_U_tj_body" >
  <inertial >
   <origin  rpy="0 0 0"  xyz="-0.0020574 -5.8806E-08 -0.0635" />
   <mass  value="0.93065" />
   <inertia  iyz="-1.9911E-10"  ixz="1.078E-20"  ixy="8.3821E-10"  ixx="0.0017462"  izz="0.0011044"  iyy="0.0017615" />
  </inertial>
  <visual >
   <origin  rpy="0 0 0"  xyz="0 0 0" />
   <geometry >
    <mesh  filename="package://jointT-m.SLDASM/meshes/tj_body.STL" />
   </geometry>
   <material  name="body" >
    <color  rgba="0.5 0.5 0.5 1" />
   </material>
  </visual>
  <collision >
   <origin  rpy="0 0 0"  xyz="0 0 0" />
   <geometry >
    <mesh  filename="package://jointT-m.SLDASM/meshes/tj_body.STL" />
   </geometry>
  </collision>
 </link>
 <link  name="JMM223_JTMU7079_JTMU7079_JTMU7079_JTMU7079_JTMU7079_JTMU7079_JTMU7079_JTMU7079_JTMU7079_JTMU7079_JTMU7079_JTMU7079_JTMU7079_JTMU7079_JTMU7079_JTMU7079_JTMU7079_JTMU7079_JTMU7079_JTMU7079_JTMU7086_U_tj_in" >
  <inertial >
   <origin  rpy="0 0 0"  xyz="-6.5585E-18 8.3685E-09 0.044941" />
   <mass  value="0.93066" />
   <inertia  iyz="8.3821E-10"  ixz="1.0711E-19"  ixy="1.9911E-10"  ixx="0.0011044"  izz="0.0017462"  iyy="0.0017615" />
  </inertial>
  <visual >
   <origin  rpy="0 0 0"  xyz="0 0 0" />
   <geometry >
    <mesh  filename="package://jointT-m.SLDASM/meshes/tj_in.STL" />
   </geometry>
   <material  name="blue" >
    <color  rgba="0 0 0.5 1" />
   </material>
  </visual>
  <collision >
   <origin  rpy="0 0 0"  xyz="0 0 0" />
   <geometry >
    <mesh  filename="package://jointT-m.SLDASM/meshes/tj_in.STL" />
   </geometry>
  </collision>
 </link>
 <link  name="JMM223_JTMU7079_JTMU7079_JTMU7079_JTMU7079_JTMU7079_JTMU7079_JTMU7079_JTMU7079_JTMU7079_JTMU7079_JTMU7079_JTMU7079_JTMU7079_JTMU7079_JTMU7079_JTMU7079_JTMU7079_JTMU7079_JTMU7079_IMU7210_U_ic_body" >
  <inertial >
   <origin  rpy="0 0 0"  xyz="0 -4.8218E-18 -0.0047" />
   <mass  value="0" />
   <inertia  iyz="0"  ixy="0"  ixz="2.1721E-37"  ixx="0.00028474"  izz="0.000562"  iyy="0.00028474" />
  </inertial>
  <visual >
   <origin  rpy="0 0 0"  xyz="0 0 0" />
   <geometry >
    <mesh  filename="package://input_connector_m.SLDASM/meshes/ic_body.STL" />
   </geometry>
   <material  name="blue" >
    <color  rgba="0 0 0.5 1" />
   </material>
  </visual>
  <collision >
   <origin  rpy="0 0 0"  xyz="0 0 0" />
   <geometry >
    <mesh  filename="package://input_connector_m.SLDASM/meshes/ic_body.STL" />
   </geometry>
  </collision>
 </link>
 <link  name="JMM223_JTMU7079_JTMU7079_JTMU7079_JTMU7079_JTMU7079_JTMU7079_JTMU7079_JTMU7079_JTMU7079_JTMU7079_JTMU7079_JTMU7079_JTMU7079_JTMU7079_JTMU7079_JTMU7079_JTMU7079_JTMU7079_JTMU7079_IMU7210_U_ic_in" >
  <inertial >
   <origin  rpy="0 0 0"  xyz="-4.5413E-34 1.0801E-17 0.0047" />
   <mass  value="0.50882" />
   <inertia  iyz="0"  ixy="0"  ixz="2.1721E-37"  ixx="0.00028474"  izz="0.000562"  iyy="0.00028474" />
  </inertial>
  <visual >
   <origin  rpy="0 0 0"  xyz="0 0 0" />
   <geometry >
    <mesh  filename="package://input_connector_m.SLDASM/meshes/ic_in.STL" />
   </geometry>
   <material  name="blue" >
    <color  rgba="0 0 0.5 1" />
   </material>
  </visual>
  <collision >
   <origin  rpy="0 0 0"  xyz="0 0 0" />
   <geometry >
    <mesh  filename="package://input_connector_m.SLDASM/meshes/ic_in.STL" />
   </geometry>
  </collision>
 </link>
 <link  name="JMM223_JTMU7079_JTMU7079_JTMU7079_JTMU7079_JTMU7079_JTMU7079_JTMU7079_JTMU7079_JTMU7079_JTMU7079_JTMU7079_JTMU7079_JTMU7079_JTMU7079_JTMU7079_JTMU7079_JTMU7079_JTMU7079_JTMU7087_U_tj_body" >
  <inertial >
   <origin  rpy="0 0 0"  xyz="-0.0020574 -5.8806E-08 -0.0635" />
   <mass  value="0.93065" />
   <inertia  iyz="-1.9911E-10"  ixz="1.078E-20"  ixy="8.3821E-10"  ixx="0.0017462"  izz="0.0011044"  iyy="0.0017615" />
  </inertial>
  <visual >
   <origin  rpy="0 0 0"  xyz="0 0 0" />
   <geometry >
    <mesh  filename="package://jointT-m.SLDASM/meshes/tj_body.STL" />
   </geometry>
   <material  name="body" >
    <color  rgba="0.5 0.5 0.5 1" />
   </material>
  </visual>
  <collision >
   <origin  rpy="0 0 0"  xyz="0 0 0" />
   <geometry >
    <mesh  filename="package://jointT-m.SLDASM/meshes/tj_body.STL" />
   </geometry>
  </collision>
 </link>
 <link  name="JMM223_JTMU7079_JTMU7079_JTMU7079_JTMU7079_JTMU7079_JTMU7079_JTMU7079_JTMU7079_JTMU7079_JTMU7079_JTMU7079_JTMU7079_JTMU7079_JTMU7079_JTMU7079_JTMU7079_JTMU7079_JTMU7079_JTMU7087_U_tj_in" >
  <inertial >
   <origin  rpy="0 0 0"  xyz="-6.5585E-18 8.3685E-09 0.044941" />
   <mass  value="0.93066" />
   <inertia  iyz="8.3821E-10"  ixz="1.0711E-19"  ixy="1.9911E-10"  ixx="0.0011044"  izz="0.0017462"  iyy="0.0017615" />
  </inertial>
  <visual >
   <origin  rpy="0 0 0"  xyz="0 0 0" />
   <geometry >
    <mesh  filename="package://jointT-m.SLDASM/meshes/tj_in.STL" />
   </geometry>
   <material  name="blue" >
    <color  rgba="0 0 0.5 1" />
   </material>
  </visual>
  <collision >
   <origin  rpy="0 0 0"  xyz="0 0 0" />
   <geometry >
    <mesh  filename="package://jointT-m.SLDASM/meshes/tj_in.STL" />
   </geometry>
  </collision>
 </link>
 <link  name="JMM223_JTMU7079_JTMU7079_JTMU7079_JTMU7079_JTMU7079_JTMU7079_JTMU7079_JTMU7079_JTMU7079_JTMU7079_JTMU7079_JTMU7079_JTMU7079_JTMU7079_JTMU7079_JTMU7079_JTMU7079_IMU7211_U_ic_body" >
  <inertial >
   <origin  rpy="0 0 0"  xyz="0 -4.8218E-18 -0.0047" />
   <mass  value="0" />
   <inertia  iyz="0"  ixy="0"  ixz="2.1721E-37"  ixx="0.00028474"  izz="0.000562"  iyy="0.00028474" />
  </inertial>
  <visual >
   <origin  rpy="0 0 0"  xyz="0 0 0" />
   <geometry >
    <mesh  filename="package://input_connector_m.SLDASM/meshes/ic_body.STL" />
   </geometry>
   <material  name="blue" >
    <color  rgba="0 0 0.5 1" />
   </material>
  </visual>
  <collision >
   <origin  rpy="0 0 0"  xyz="0 0 0" />
   <geometry >
    <mesh  filename="package://input_connector_m.SLDASM/meshes/ic_body.STL" />
   </geometry>
  </collision>
 </link>
 <link  name="JMM223_JTMU7079_JTMU7079_JTMU7079_JTMU7079_JTMU7079_JTMU7079_JTMU7079_JTMU7079_JTMU7079_JTMU7079_JTMU7079_JTMU7079_JTMU7079_JTMU7079_JTMU7079_JTMU7079_JTMU7079_IMU7211_U_ic_in" >
  <inertial >
   <origin  rpy="0 0 0"  xyz="-4.5413E-34 1.0801E-17 0.0047" />
   <mass  value="0.50882" />
   <inertia  iyz="0"  ixy="0"  ixz="2.1721E-37"  ixx="0.00028474"  izz="0.000562"  iyy="0.00028474" />
  </inertial>
  <visual >
   <origin  rpy="0 0 0"  xyz="0 0 0" />
   <geometry >
    <mesh  filename="package://input_connector_m.SLDASM/meshes/ic_in.STL" />
   </geometry>
   <material  name="blue" >
    <color  rgba="0 0 0.5 1" />
   </material>
  </visual>
  <collision >
   <origin  rpy="0 0 0"  xyz="0 0 0" />
   <geometry >
    <mesh  filename="package://input_connector_m.SLDASM/meshes/ic_in.STL" />
   </geometry>
  </collision>
 </link>
 <link  name="JMM223_JTMU7079_JTMU7079_JTMU7079_JTMU7079_JTMU7079_JTMU7079_JTMU7079_JTMU7079_JTMU7079_JTMU7079_JTMU7079_JTMU7079_JTMU7079_JTMU7079_JTMU7079_JTMU7079_JTMU7088_U_tj_body" >
  <inertial >
   <origin  rpy="0 0 0"  xyz="-0.0020574 -5.8806E-08 -0.0635" />
   <mass  value="0.93065" />
   <inertia  iyz="-1.9911E-10"  ixz="1.078E-20"  ixy="8.3821E-10"  ixx="0.0017462"  izz="0.0011044"  iyy="0.0017615" />
  </inertial>
  <visual >
   <origin  rpy="0 0 0"  xyz="0 0 0" />
   <geometry >
    <mesh  filename="package://jointT-m.SLDASM/meshes/tj_body.STL" />
   </geometry>
   <material  name="body" >
    <color  rgba="0.5 0.5 0.5 1" />
   </material>
  </visual>
  <collision >
   <origin  rpy="0 0 0"  xyz="0 0 0" />
   <geometry >
    <mesh  filename="package://jointT-m.SLDASM/meshes/tj_body.STL" />
   </geometry>
  </collision>
 </link>
 <link  name="JMM223_JTMU7079_JTMU7079_JTMU7079_JTMU7079_JTMU7079_JTMU7079_JTMU7079_JTMU7079_JTMU7079_JTMU7079_JTMU7079_JTMU7079_JTMU7079_JTMU7079_JTMU7079_JTMU7079_JTMU7088_U_tj_in" >
  <inertial >
   <origin  rpy="0 0 0"  xyz="-6.5585E-18 8.3685E-09 0.044941" />
   <mass  value="0.93066" />
   <inertia  iyz="8.3821E-10"  ixz="1.0711E-19"  ixy="1.9911E-10"  ixx="0.0011044"  izz="0.0017462"  iyy="0.0017615" />
  </inertial>
  <visual >
   <origin  rpy="0 0 0"  xyz="0 0 0" />
   <geometry >
    <mesh  filename="package://jointT-m.SLDASM/meshes/tj_in.STL" />
   </geometry>
   <material  name="blue" >
    <color  rgba="0 0 0.5 1" />
   </material>
  </visual>
  <collision >
   <origin  rpy="0 0 0"  xyz="0 0 0" />
   <geometry >
    <mesh  filename="package://jointT-m.SLDASM/meshes/tj_in.STL" />
   </geometry>
  </collision>
 </link>
 <link  name="JMM223_JTMU7079_JTMU7079_JTMU7079_JTMU7079_JTMU7079_JTMU7079_JTMU7079_JTMU7079_JTMU7079_JTMU7079_JTMU7079_JTMU7079_JTMU7079_JTMU7079_JTMU7079_IMU7212_U_ic_body" >
  <inertial >
   <origin  rpy="0 0 0"  xyz="0 -4.8218E-18 -0.0047" />
   <mass  value="0" />
   <inertia  iyz="0"  ixy="0"  ixz="2.1721E-37"  ixx="0.00028474"  izz="0.000562"  iyy="0.00028474" />
  </inertial>
  <visual >
   <origin  rpy="0 0 0"  xyz="0 0 0" />
   <geometry >
    <mesh  filename="package://input_connector_m.SLDASM/meshes/ic_body.STL" />
   </geometry>
   <material  name="blue" >
    <color  rgba="0 0 0.5 1" />
   </material>
  </visual>
  <collision >
   <origin  rpy="0 0 0"  xyz="0 0 0" />
   <geometry >
    <mesh  filename="package://input_connector_m.SLDASM/meshes/ic_body.STL" />
   </geometry>
  </collision>
 </link>
 <link  name="JMM223_JTMU7079_JTMU7079_JTMU7079_JTMU7079_JTMU7079_JTMU7079_JTMU7079_JTMU7079_JTMU7079_JTMU7079_JTMU7079_JTMU7079_JTMU7079_JTMU7079_JTMU7079_IMU7212_U_ic_in" >
  <inertial >
   <origin  rpy="0 0 0"  xyz="-4.5413E-34 1.0801E-17 0.0047" />
   <mass  value="0.50882" />
   <inertia  iyz="0"  ixy="0"  ixz="2.1721E-37"  ixx="0.00028474"  izz="0.000562"  iyy="0.00028474" />
  </inertial>
  <visual >
   <origin  rpy="0 0 0"  xyz="0 0 0" />
   <geometry >
    <mesh  filename="package://input_connector_m.SLDASM/meshes/ic_in.STL" />
   </geometry>
   <material  name="blue" >
    <color  rgba="0 0 0.5 1" />
   </material>
  </visual>
  <collision >
   <origin  rpy="0 0 0"  xyz="0 0 0" />
   <geometry >
    <mesh  filename="package://input_connector_m.SLDASM/meshes/ic_in.STL" />
   </geometry>
  </collision>
 </link>
 <link  name="JMM223_JTMU7079_JTMU7079_JTMU7079_JTMU7079_JTMU7079_JTMU7079_JTMU7079_JTMU7079_JTMU7079_JTMU7079_JTMU7079_JTMU7079_JTMU7079_JTMU7079_JTMU7089_U_tj_body" >
  <inertial >
   <origin  rpy="0 0 0"  xyz="-0.0020574 -5.8806E-08 -0.0635" />
   <mass  value="0.93065" />
   <inertia  iyz="-1.9911E-10"  ixz="1.078E-20"  ixy="8.3821E-10"  ixx="0.0017462"  izz="0.0011044"  iyy="0.0017615" />
  </inertial>
  <visual >
   <origin  rpy="0 0 0"  xyz="0 0 0" />
   <geometry >
    <mesh  filename="package://jointT-m.SLDASM/meshes/tj_body.STL" />
   </geometry>
   <material  name="body" >
    <color  rgba="0.5 0.5 0.5 1" />
   </material>
  </visual>
  <collision >
   <origin  rpy="0 0 0"  xyz="0 0 0" />
   <geometry >
    <mesh  filename="package://jointT-m.SLDASM/meshes/tj_body.STL" />
   </geometry>
  </collision>
 </link>
 <link  name="JMM223_JTMU7079_JTMU7079_JTMU7079_JTMU7079_JTMU7079_JTMU7079_JTMU7079_JTMU7079_JTMU7079_JTMU7079_JTMU7079_JTMU7079_JTMU7079_JTMU7079_JTMU7089_U_tj_in" >
  <inertial >
   <origin  rpy="0 0 0"  xyz="-6.5585E-18 8.3685E-09 0.044941" />
   <mass  value="0.93066" />
   <inertia  iyz="8.3821E-10"  ixz="1.0711E-19"  ixy="1.9911E-10"  ixx="0.0011044"  izz="0.0017462"  iyy="0.0017615" />
  </inertial>
  <visual >
   <origin  rpy="0 0 0"  xyz="0 0 0" />
   <geometry >
    <mesh  filename="package://jointT-m.SLDASM/meshes/tj_in.STL" />
   </geometry>
   <material  name="blue" >
    <color  rgba="0 0 0.5 1" />
   </material>
  </visual>
  <collision >
   <origin  rpy="0 0 0"  xyz="0 0 0" />
   <geometry >
    <mesh  filename="package://jointT-m.SLDASM/meshes/tj_in.STL" />
   </geometry>
  </collision>
 </link>
 <link  name="JMM223_JTMU7079_JTMU7079_JTMU7079_JTMU7079_JTMU7079_JTMU7079_JTMU7079_JTMU7079_JTMU7079_JTMU7079_JTMU7079_JTMU7079_JTMU7079_IMU7213_U_ic_body" >
  <inertial >
   <origin  rpy="0 0 0"  xyz="0 -4.8218E-18 -0.0047" />
   <mass  value="0" />
   <inertia  iyz="0"  ixy="0"  ixz="2.1721E-37"  ixx="0.00028474"  izz="0.000562"  iyy="0.00028474" />
  </inertial>
  <visual >
   <origin  rpy="0 0 0"  xyz="0 0 0" />
   <geometry >
    <mesh  filename="package://input_connector_m.SLDASM/meshes/ic_body.STL" />
   </geometry>
   <material  name="blue" >
    <color  rgba="0 0 0.5 1" />
   </material>
  </visual>
  <collision >
   <origin  rpy="0 0 0"  xyz="0 0 0" />
   <geometry >
    <mesh  filename="package://input_connector_m.SLDASM/meshes/ic_body.STL" />
   </geometry>
  </collision>
 </link>
 <link  name="JMM223_JTMU7079_JTMU7079_JTMU7079_JTMU7079_JTMU7079_JTMU7079_JTMU7079_JTMU7079_JTMU7079_JTMU7079_JTMU7079_JTMU7079_JTMU7079_IMU7213_U_ic_in" >
  <inertial >
   <origin  rpy="0 0 0"  xyz="-4.5413E-34 1.0801E-17 0.0047" />
   <mass  value="0.50882" />
   <inertia  iyz="0"  ixy="0"  ixz="2.1721E-37"  ixx="0.00028474"  izz="0.000562"  iyy="0.00028474" />
  </inertial>
  <visual >
   <origin  rpy="0 0 0"  xyz="0 0 0" />
   <geometry >
    <mesh  filename="package://input_connector_m.SLDASM/meshes/ic_in.STL" />
   </geometry>
   <material  name="blue" >
    <color  rgba="0 0 0.5 1" />
   </material>
  </visual>
  <collision >
   <origin  rpy="0 0 0"  xyz="0 0 0" />
   <geometry >
    <mesh  filename="package://input_connector_m.SLDASM/meshes/ic_in.STL" />
   </geometry>
  </collision>
 </link>
 <link  name="JMM223_JTMU7079_JTMU7079_JTMU7079_JTMU7079_JTMU7079_JTMU7079_JTMU7079_JTMU7079_JTMU7079_JTMU7079_JTMU7079_JTMU7079_JTMU7090_U_tj_body" >
  <inertial >
   <origin  rpy="0 0 0"  xyz="-0.0020574 -5.8806E-08 -0.0635" />
   <mass  value="0.93065" />
   <inertia  iyz="-1.9911E-10"  ixz="1.078E-20"  ixy="8.3821E-10"  ixx="0.0017462"  izz="0.0011044"  iyy="0.0017615" />
  </inertial>
  <visual >
   <origin  rpy="0 0 0"  xyz="0 0 0" />
   <geometry >
    <mesh  filename="package://jointT-m.SLDASM/meshes/tj_body.STL" />
   </geometry>
   <material  name="body" >
    <color  rgba="0.5 0.5 0.5 1" />
   </material>
  </visual>
  <collision >
   <origin  rpy="0 0 0"  xyz="0 0 0" />
   <geometry >
    <mesh  filename="package://jointT-m.SLDASM/meshes/tj_body.STL" />
   </geometry>
  </collision>
 </link>
 <link  name="JMM223_JTMU7079_JTMU7079_JTMU7079_JTMU7079_JTMU7079_JTMU7079_JTMU7079_JTMU7079_JTMU7079_JTMU7079_JTMU7079_JTMU7079_JTMU7090_U_tj_in" >
  <inertial >
   <origin  rpy="0 0 0"  xyz="-6.5585E-18 8.3685E-09 0.044941" />
   <mass  value="0.93066" />
   <inertia  iyz="8.3821E-10"  ixz="1.0711E-19"  ixy="1.9911E-10"  ixx="0.0011044"  izz="0.0017462"  iyy="0.0017615" />
  </inertial>
  <visual >
   <origin  rpy="0 0 0"  xyz="0 0 0" />
   <geometry >
    <mesh  filename="package://jointT-m.SLDASM/meshes/tj_in.STL" />
   </geometry>
   <material  name="blue" >
    <color  rgba="0 0 0.5 1" />
   </material>
  </visual>
  <collision >
   <origin  rpy="0 0 0"  xyz="0 0 0" />
   <geometry >
    <mesh  filename="package://jointT-m.SLDASM/meshes/tj_in.STL" />
   </geometry>
  </collision>
 </link>
 <link  name="JMM223_JTMU7079_JTMU7079_JTMU7079_JTMU7079_JTMU7079_JTMU7079_JTMU7079_JTMU7079_JTMU7079_JTMU7079_JTMU7079_IMU7214_U_ic_body" >
  <inertial >
   <origin  rpy="0 0 0"  xyz="0 -4.8218E-18 -0.0047" />
   <mass  value="0" />
   <inertia  iyz="0"  ixy="0"  ixz="2.1721E-37"  ixx="0.00028474"  izz="0.000562"  iyy="0.00028474" />
  </inertial>
  <visual >
   <origin  rpy="0 0 0"  xyz="0 0 0" />
   <geometry >
    <mesh  filename="package://input_connector_m.SLDASM/meshes/ic_body.STL" />
   </geometry>
   <material  name="blue" >
    <color  rgba="0 0 0.5 1" />
   </material>
  </visual>
  <collision >
   <origin  rpy="0 0 0"  xyz="0 0 0" />
   <geometry >
    <mesh  filename="package://input_connector_m.SLDASM/meshes/ic_body.STL" />
   </geometry>
  </collision>
 </link>
 <link  name="JMM223_JTMU7079_JTMU7079_JTMU7079_JTMU7079_JTMU7079_JTMU7079_JTMU7079_JTMU7079_JTMU7079_JTMU7079_JTMU7079_IMU7214_U_ic_in" >
  <inertial >
   <origin  rpy="0 0 0"  xyz="-4.5413E-34 1.0801E-17 0.0047" />
   <mass  value="0.50882" />
   <inertia  iyz="0"  ixy="0"  ixz="2.1721E-37"  ixx="0.00028474"  izz="0.000562"  iyy="0.00028474" />
  </inertial>
  <visual >
   <origin  rpy="0 0 0"  xyz="0 0 0" />
   <geometry >
    <mesh  filename="package://input_connector_m.SLDASM/meshes/ic_in.STL" />
   </geometry>
   <material  name="blue" >
    <color  rgba="0 0 0.5 1" />
   </material>
  </visual>
  <collision >
   <origin  rpy="0 0 0"  xyz="0 0 0" />
   <geometry >
    <mesh  filename="package://input_connector_m.SLDASM/meshes/ic_in.STL" />
   </geometry>
  </collision>
 </link>
 <link  name="JMM223_JTMU7079_JTMU7079_JTMU7079_JTMU7079_JTMU7079_JTMU7079_JTMU7079_JTMU7079_JTMU7079_JTMU7079_JTMU7091_U_tj_body" >
  <inertial >
   <origin  rpy="0 0 0"  xyz="-0.0020574 -5.8806E-08 -0.0635" />
   <mass  value="0.93065" />
   <inertia  iyz="-1.9911E-10"  ixz="1.078E-20"  ixy="8.3821E-10"  ixx="0.0017462"  izz="0.0011044"  iyy="0.0017615" />
  </inertial>
  <visual >
   <origin  rpy="0 0 0"  xyz="0 0 0" />
   <geometry >
    <mesh  filename="package://jointT-m.SLDASM/meshes/tj_body.STL" />
   </geometry>
   <material  name="body" >
    <color  rgba="0.5 0.5 0.5 1" />
   </material>
  </visual>
  <collision >
   <origin  rpy="0 0 0"  xyz="0 0 0" />
   <geometry >
    <mesh  filename="package://jointT-m.SLDASM/meshes/tj_body.STL" />
   </geometry>
  </collision>
 </link>
 <link  name="JMM223_JTMU7079_JTMU7079_JTMU7079_JTMU7079_JTMU7079_JTMU7079_JTMU7079_JTMU7079_JTMU7079_JTMU7079_JTMU7091_U_tj_in" >
  <inertial >
   <origin  rpy="0 0 0"  xyz="-6.5585E-18 8.3685E-09 0.044941" />
   <mass  value="0.93066" />
   <inertia  iyz="8.3821E-10"  ixz="1.0711E-19"  ixy="1.9911E-10"  ixx="0.0011044"  izz="0.0017462"  iyy="0.0017615" />
  </inertial>
  <visual >
   <origin  rpy="0 0 0"  xyz="0 0 0" />
   <geometry >
    <mesh  filename="package://jointT-m.SLDASM/meshes/tj_in.STL" />
   </geometry>
   <material  name="blue" >
    <color  rgba="0 0 0.5 1" />
   </material>
  </visual>
  <collision >
   <origin  rpy="0 0 0"  xyz="0 0 0" />
   <geometry >
    <mesh  filename="package://jointT-m.SLDASM/meshes/tj_in.STL" />
   </geometry>
  </collision>
 </link>
 <link  name="JMM223_JTMU7079_JTMU7079_JTMU7079_JTMU7079_JTMU7079_JTMU7079_JTMU7079_JTMU7079_JTMU7079_IMU7215_U_ic_body" >
  <inertial >
   <origin  rpy="0 0 0"  xyz="0 -4.8218E-18 -0.0047" />
   <mass  value="0" />
   <inertia  iyz="0"  ixy="0"  ixz="2.1721E-37"  ixx="0.00028474"  izz="0.000562"  iyy="0.00028474" />
  </inertial>
  <visual >
   <origin  rpy="0 0 0"  xyz="0 0 0" />
   <geometry >
    <mesh  filename="package://input_connector_m.SLDASM/meshes/ic_body.STL" />
   </geometry>
   <material  name="blue" >
    <color  rgba="0 0 0.5 1" />
   </material>
  </visual>
  <collision >
   <origin  rpy="0 0 0"  xyz="0 0 0" />
   <geometry >
    <mesh  filename="package://input_connector_m.SLDASM/meshes/ic_body.STL" />
   </geometry>
  </collision>
 </link>
 <link  name="JMM223_JTMU7079_JTMU7079_JTMU7079_JTMU7079_JTMU7079_JTMU7079_JTMU7079_JTMU7079_JTMU7079_IMU7215_U_ic_in" >
  <inertial >
   <origin  rpy="0 0 0"  xyz="-4.5413E-34 1.0801E-17 0.0047" />
   <mass  value="0.50882" />
   <inertia  iyz="0"  ixy="0"  ixz="2.1721E-37"  ixx="0.00028474"  izz="0.000562"  iyy="0.00028474" />
  </inertial>
  <visual >
   <origin  rpy="0 0 0"  xyz="0 0 0" />
   <geometry >
    <mesh  filename="package://input_connector_m.SLDASM/meshes/ic_in.STL" />
   </geometry>
   <material  name="blue" >
    <color  rgba="0 0 0.5 1" />
   </material>
  </visual>
  <collision >
   <origin  rpy="0 0 0"  xyz="0 0 0" />
   <geometry >
    <mesh  filename="package://input_connector_m.SLDASM/meshes/ic_in.STL" />
   </geometry>
  </collision>
 </link>
 <link  name="JMM223_JTMU7079_JTMU7079_JTMU7079_JTMU7079_JTMU7079_JTMU7079_JTMU7079_JTMU7079_JTMU7092_U_tj_body" >
  <inertial >
   <origin  rpy="0 0 0"  xyz="-0.0020574 -5.8806E-08 -0.0635" />
   <mass  value="0.93065" />
   <inertia  iyz="-1.9911E-10"  ixz="1.078E-20"  ixy="8.3821E-10"  ixx="0.0017462"  izz="0.0011044"  iyy="0.0017615" />
  </inertial>
  <visual >
   <origin  rpy="0 0 0"  xyz="0 0 0" />
   <geometry >
    <mesh  filename="package://jointT-m.SLDASM/meshes/tj_body.STL" />
   </geometry>
   <material  name="body" >
    <color  rgba="0.5 0.5 0.5 1" />
   </material>
  </visual>
  <collision >
   <origin  rpy="0 0 0"  xyz="0 0 0" />
   <geometry >
    <mesh  filename="package://jointT-m.SLDASM/meshes/tj_body.STL" />
   </geometry>
  </collision>
 </link>
 <link  name="JMM223_JTMU7079_JTMU7079_JTMU7079_JTMU7079_JTMU7079_JTMU7079_JTMU7079_JTMU7079_JTMU7092_U_tj_in" >
  <inertial >
   <origin  rpy="0 0 0"  xyz="-6.5585E-18 8.3685E-09 0.044941" />
   <mass  value="0.93066" />
   <inertia  iyz="8.3821E-10"  ixz="1.0711E-19"  ixy="1.9911E-10"  ixx="0.0011044"  izz="0.0017462"  iyy="0.0017615" />
  </inertial>
  <visual >
   <origin  rpy="0 0 0"  xyz="0 0 0" />
   <geometry >
    <mesh  filename="package://jointT-m.SLDASM/meshes/tj_in.STL" />
   </geometry>
   <material  name="blue" >
    <color  rgba="0 0 0.5 1" />
   </material>
  </visual>
  <collision >
   <origin  rpy="0 0 0"  xyz="0 0 0" />
   <geometry >
    <mesh  filename="package://jointT-m.SLDASM/meshes/tj_in.STL" />
   </geometry>
  </collision>
 </link>
 <link  name="JMM223_JTMU7079_JTMU7079_JTMU7079_JTMU7079_JTMU7079_JTMU7079_JTMU7079_IMU7216_U_ic_body" >
  <inertial >
   <origin  rpy="0 0 0"  xyz="0 -4.8218E-18 -0.0047" />
   <mass  value="0" />
   <inertia  iyz="0"  ixy="0"  ixz="2.1721E-37"  ixx="0.00028474"  izz="0.000562"  iyy="0.00028474" />
  </inertial>
  <visual >
   <origin  rpy="0 0 0"  xyz="0 0 0" />
   <geometry >
    <mesh  filename="package://input_connector_m.SLDASM/meshes/ic_body.STL" />
   </geometry>
   <material  name="blue" >
    <color  rgba="0 0 0.5 1" />
   </material>
  </visual>
  <collision >
   <origin  rpy="0 0 0"  xyz="0 0 0" />
   <geometry >
    <mesh  filename="package://input_connector_m.SLDASM/meshes/ic_body.STL" />
   </geometry>
  </collision>
 </link>
 <link  name="JMM223_JTMU7079_JTMU7079_JTMU7079_JTMU7079_JTMU7079_JTMU7079_JTMU7079_IMU7216_U_ic_in" >
  <inertial >
   <origin  rpy="0 0 0"  xyz="-4.5413E-34 1.0801E-17 0.0047" />
   <mass  value="0.50882" />
   <inertia  iyz="0"  ixy="0"  ixz="2.1721E-37"  ixx="0.00028474"  izz="0.000562"  iyy="0.00028474" />
  </inertial>
  <visual >
   <origin  rpy="0 0 0"  xyz="0 0 0" />
   <geometry >
    <mesh  filename="package://input_connector_m.SLDASM/meshes/ic_in.STL" />
   </geometry>
   <material  name="blue" >
    <color  rgba="0 0 0.5 1" />
   </material>
  </visual>
  <collision >
   <origin  rpy="0 0 0"  xyz="0 0 0" />
   <geometry >
    <mesh  filename="package://input_connector_m.SLDASM/meshes/ic_in.STL" />
   </geometry>
  </collision>
 </link>
 <link  name="JMM223_JTMU7079_JTMU7079_JTMU7079_JTMU7079_JTMU7079_JTMU7079_JTMU7093_U_tj_body" >
  <inertial >
   <origin  rpy="0 0 0"  xyz="-0.0020574 -5.8806E-08 -0.0635" />
   <mass  value="0.93065" />
   <inertia  iyz="-1.9911E-10"  ixz="1.078E-20"  ixy="8.3821E-10"  ixx="0.0017462"  izz="0.0011044"  iyy="0.0017615" />
  </inertial>
  <visual >
   <origin  rpy="0 0 0"  xyz="0 0 0" />
   <geometry >
    <mesh  filename="package://jointT-m.SLDASM/meshes/tj_body.STL" />
   </geometry>
   <material  name="body" >
    <color  rgba="0.5 0.5 0.5 1" />
   </material>
  </visual>
  <collision >
   <origin  rpy="0 0 0"  xyz="0 0 0" />
   <geometry >
    <mesh  filename="package://jointT-m.SLDASM/meshes/tj_body.STL" />
   </geometry>
  </collision>
 </link>
 <link  name="JMM223_JTMU7079_JTMU7079_JTMU7079_JTMU7079_JTMU7079_JTMU7079_JTMU7093_U_tj_in" >
  <inertial >
   <origin  rpy="0 0 0"  xyz="-6.5585E-18 8.3685E-09 0.044941" />
   <mass  value="0.93066" />
   <inertia  iyz="8.3821E-10"  ixz="1.0711E-19"  ixy="1.9911E-10"  ixx="0.0011044"  izz="0.0017462"  iyy="0.0017615" />
  </inertial>
  <visual >
   <origin  rpy="0 0 0"  xyz="0 0 0" />
   <geometry >
    <mesh  filename="package://jointT-m.SLDASM/meshes/tj_in.STL" />
   </geometry>
   <material  name="blue" >
    <color  rgba="0 0 0.5 1" />
   </material>
  </visual>
  <collision >
   <origin  rpy="0 0 0"  xyz="0 0 0" />
   <geometry >
    <mesh  filename="package://jointT-m.SLDASM/meshes/tj_in.STL" />
   </geometry>
  </collision>
 </link>
 <link  name="JMM223_JTMU7079_JTMU7079_JTMU7079_JTMU7079_JTMU7079_IMU7217_U_ic_body" >
  <inertial >
   <origin  rpy="0 0 0"  xyz="0 -4.8218E-18 -0.0047" />
   <mass  value="0" />
   <inertia  iyz="0"  ixy="0"  ixz="2.1721E-37"  ixx="0.00028474"  izz="0.000562"  iyy="0.00028474" />
  </inertial>
  <visual >
   <origin  rpy="0 0 0"  xyz="0 0 0" />
   <geometry >
    <mesh  filename="package://input_connector_m.SLDASM/meshes/ic_body.STL" />
   </geometry>
   <material  name="blue" >
    <color  rgba="0 0 0.5 1" />
   </material>
  </visual>
  <collision >
   <origin  rpy="0 0 0"  xyz="0 0 0" />
   <geometry >
    <mesh  filename="package://input_connector_m.SLDASM/meshes/ic_body.STL" />
   </geometry>
  </collision>
 </link>
 <link  name="JMM223_JTMU7079_JTMU7079_JTMU7079_JTMU7079_JTMU7079_IMU7217_U_ic_in" >
  <inertial >
   <origin  rpy="0 0 0"  xyz="-4.5413E-34 1.0801E-17 0.0047" />
   <mass  value="0.50882" />
   <inertia  iyz="0"  ixy="0"  ixz="2.1721E-37"  ixx="0.00028474"  izz="0.000562"  iyy="0.00028474" />
  </inertial>
  <visual >
   <origin  rpy="0 0 0"  xyz="0 0 0" />
   <geometry >
    <mesh  filename="package://input_connector_m.SLDASM/meshes/ic_in.STL" />
   </geometry>
   <material  name="blue" >
    <color  rgba="0 0 0.5 1" />
   </material>
  </visual>
  <collision >
   <origin  rpy="0 0 0"  xyz="0 0 0" />
   <geometry >
    <mesh  filename="package://input_connector_m.SLDASM/meshes/ic_in.STL" />
   </geometry>
  </collision>
 </link>
 <link  name="JMM223_JTMU7079_JTMU7079_JTMU7079_JTMU7079_JTMU7094_U_tj_body" >
  <inertial >
   <origin  rpy="0 0 0"  xyz="-0.0020574 -5.8806E-08 -0.0635" />
   <mass  value="0.93065" />
   <inertia  iyz="-1.9911E-10"  ixz="1.078E-20"  ixy="8.3821E-10"  ixx="0.0017462"  izz="0.0011044"  iyy="0.0017615" />
  </inertial>
  <visual >
   <origin  rpy="0 0 0"  xyz="0 0 0" />
   <geometry >
    <mesh  filename="package://jointT-m.SLDASM/meshes/tj_body.STL" />
   </geometry>
   <material  name="body" >
    <color  rgba="0.5 0.5 0.5 1" />
   </material>
  </visual>
  <collision >
   <origin  rpy="0 0 0"  xyz="0 0 0" />
   <geometry >
    <mesh  filename="package://jointT-m.SLDASM/meshes/tj_body.STL" />
   </geometry>
  </collision>
 </link>
 <link  name="JMM223_JTMU7079_JTMU7079_JTMU7079_JTMU7079_JTMU7094_U_tj_in" >
  <inertial >
   <origin  rpy="0 0 0"  xyz="-6.5585E-18 8.3685E-09 0.044941" />
   <mass  value="0.93066" />
   <inertia  iyz="8.3821E-10"  ixz="1.0711E-19"  ixy="1.9911E-10"  ixx="0.0011044"  izz="0.0017462"  iyy="0.0017615" />
  </inertial>
  <visual >
   <origin  rpy="0 0 0"  xyz="0 0 0" />
   <geometry >
    <mesh  filename="package://jointT-m.SLDASM/meshes/tj_in.STL" />
   </geometry>
   <material  name="blue" >
    <color  rgba="0 0 0.5 1" />
   </material>
  </visual>
  <collision >
   <origin  rpy="0 0 0"  xyz="0 0 0" />
   <geometry >
    <mesh  filename="package://jointT-m.SLDASM/meshes/tj_in.STL" />
   </geometry>
  </collision>
 </link>
 <link  name="JMM223_JTMU7079_JTMU7079_JTMU7079_IMU7218_U_ic_body" >
  <inertial >
   <origin  rpy="0 0 0"  xyz="0 -4.8218E-18 -0.0047" />
   <mass  value="0" />
   <inertia  iyz="0"  ixy="0"  ixz="2.1721E-37"  ixx="0.00028474"  izz="0.000562"  iyy="0.00028474" />
  </inertial>
  <visual >
   <origin  rpy="0 0 0"  xyz="0 0 0" />
   <geometry >
    <mesh  filename="package://input_connector_m.SLDASM/meshes/ic_body.STL" />
   </geometry>
   <material  name="blue" >
    <color  rgba="0 0 0.5 1" />
   </material>
  </visual>
  <collision >
   <origin  rpy="0 0 0"  xyz="0 0 0" />
   <geometry >
    <mesh  filename="package://input_connector_m.SLDASM/meshes/ic_body.STL" />
   </geometry>
  </collision>
 </link>
 <link  name="JMM223_JTMU7079_JTMU7079_JTMU7079_IMU7218_U_ic_in" >
  <inertial >
   <origin  rpy="0 0 0"  xyz="-4.5413E-34 1.0801E-17 0.0047" />
   <mass  value="0.50882" />
   <inertia  iyz="0"  ixy="0"  ixz="2.1721E-37"  ixx="0.00028474"  izz="0.000562"  iyy="0.00028474" />
  </inertial>
  <visual >
   <origin  rpy="0 0 0"  xyz="0 0 0" />
   <geometry >
    <mesh  filename="package://input_connector_m.SLDASM/meshes/ic_in.STL" />
   </geometry>
   <material  name="blue" >
    <color  rgba="0 0 0.5 1" />
   </material>
  </visual>
  <collision >
   <origin  rpy="0 0 0"  xyz="0 0 0" />
   <geometry >
    <mesh  filename="package://input_connector_m.SLDASM/meshes/ic_in.STL" />
   </geometry>
  </collision>
 </link>
 <link  name="JMM223_JTMU7079_JTMU7079_JTMU7095_U_tj_body" >
  <inertial >
   <origin  rpy="0 0 0"  xyz="-0.0020574 -5.8806E-08 -0.0635" />
   <mass  value="0.93065" />
   <inertia  iyz="-1.9911E-10"  ixz="1.078E-20"  ixy="8.3821E-10"  ixx="0.0017462"  izz="0.0011044"  iyy="0.0017615" />
  </inertial>
  <visual >
   <origin  rpy="0 0 0"  xyz="0 0 0" />
   <geometry >
    <mesh  filename="package://jointT-m.SLDASM/meshes/tj_body.STL" />
   </geometry>
   <material  name="body" >
    <color  rgba="0.5 0.5 0.5 1" />
   </material>
  </visual>
  <collision >
   <origin  rpy="0 0 0"  xyz="0 0 0" />
   <geometry >
    <mesh  filename="package://jointT-m.SLDASM/meshes/tj_body.STL" />
   </geometry>
  </collision>
 </link>
 <link  name="JMM223_JTMU7079_JTMU7079_JTMU7095_U_tj_in" >
  <inertial >
   <origin  rpy="0 0 0"  xyz="-6.5585E-18 8.3685E-09 0.044941" />
   <mass  value="0.93066" />
   <inertia  iyz="8.3821E-10"  ixz="1.0711E-19"  ixy="1.9911E-10"  ixx="0.0011044"  izz="0.0017462"  iyy="0.0017615" />
  </inertial>
  <visual >
   <origin  rpy="0 0 0"  xyz="0 0 0" />
   <geometry >
    <mesh  filename="package://jointT-m.SLDASM/meshes/tj_in.STL" />
   </geometry>
   <material  name="blue" >
    <color  rgba="0 0 0.5 1" />
   </material>
  </visual>
  <collision >
   <origin  rpy="0 0 0"  xyz="0 0 0" />
   <geometry >
    <mesh  filename="package://jointT-m.SLDASM/meshes/tj_in.STL" />
   </geometry>
  </collision>
 </link>
 <link  name="JMM223_JTMU7079_IMU7219_U_ic_body" >
  <inertial >
   <origin  rpy="0 0 0"  xyz="0 -4.8218E-18 -0.0047" />
   <mass  value="0" />
   <inertia  iyz="0"  ixy="0"  ixz="2.1721E-37"  ixx="0.00028474"  izz="0.000562"  iyy="0.00028474" />
  </inertial>
  <visual >
   <origin  rpy="0 0 0"  xyz="0 0 0" />
   <geometry >
    <mesh  filename="package://input_connector_m.SLDASM/meshes/ic_body.STL" />
   </geometry>
   <material  name="blue" >
    <color  rgba="0 0 0.5 1" />
   </material>
  </visual>
  <collision >
   <origin  rpy="0 0 0"  xyz="0 0 0" />
   <geometry >
    <mesh  filename="package://input_connector_m.SLDASM/meshes/ic_body.STL" />
   </geometry>
  </collision>
 </link>
 <link  name="JMM223_JTMU7079_IMU7219_U_ic_in" >
  <inertial >
   <origin  rpy="0 0 0"  xyz="-4.5413E-34 1.0801E-17 0.0047" />
   <mass  value="0.50882" />
   <inertia  iyz="0"  ixy="0"  ixz="2.1721E-37"  ixx="0.00028474"  izz="0.000562"  iyy="0.00028474" />
  </inertial>
  <visual >
   <origin  rpy="0 0 0"  xyz="0 0 0" />
   <geometry >
    <mesh  filename="package://input_connector_m.SLDASM/meshes/ic_in.STL" />
   </geometry>
   <material  name="blue" >
    <color  rgba="0 0 0.5 1" />
   </material>
  </visual>
  <collision >
   <origin  rpy="0 0 0"  xyz="0 0 0" />
   <geometry >
    <mesh  filename="package://input_connector_m.SLDASM/meshes/ic_in.STL" />
   </geometry>
  </collision>
 </link>
 <joint  name="JMM223_JTMU7079_JTMU7079_JTMU7079_JTMU7079_JTMU7079_JTMU7079_JTMU7079_JTMU7079_JTMU7079_JTMU7079_JTMU7079_JTMU7079_JTMU7079_JTMU7079_JTMU7079_JTMU7079_JTMU7079_JTMU7079_JTMU7079_JTMU7079_JTMU7079_JTMU7079_JTMU7079_JTMU7079_JTMU7079_JTMU7079_JTMU7079_JTMU7079_JTMU7079_JTMU7079_JTMU7079_JTMU7079_JTMU7079_JTMU7079_U_tj_medium_1"  type="revolute" >
  <origin  rpy="0.0 0.0 3.141592653589793"  xyz="0.0 0.0 0.0" />
  <parent  link="JMM223_JTMU7079_JTMU7079_JTMU7079_JTMU7079_JTMU7079_JTMU7079_JTMU7079_JTMU7079_JTMU7079_JTMU7079_JTMU7079_JTMU7079_JTMU7079_JTMU7079_JTMU7079_JTMU7079_JTMU7079_JTMU7079_JTMU7079_JTMU7079_JTMU7079_JTMU7079_JTMU7079_JTMU7079_JTMU7079_JTMU7079_JTMU7079_JTMU7079_JTMU7079_JTMU7079_JTMU7079_JTMU7079_JTMU7079_JTMU7079_U_tj_out" />
  <child  link="JMM223_JTMU7079_JTMU7079_JTMU7079_JTMU7079_JTMU7079_JTMU7079_JTMU7079_JTMU7079_JTMU7079_JTMU7079_JTMU7079_JTMU7079_JTMU7079_JTMU7079_JTMU7079_JTMU7079_JTMU7079_JTMU7079_JTMU7079_JTMU7079_JTMU7079_JTMU7079_JTMU7079_JTMU7079_JTMU7079_JTMU7079_JTMU7079_JTMU7079_JTMU7079_JTMU7079_JTMU7079_JTMU7079_JTMU7079_JTMU7079_U_tj_body" />
  <axis  xyz="0 0 1" />
  <limit  velocity="0.33"  upper="3.1416"  lower="-3.1416"  effort="25.5" />
 </joint>
 <joint  name="JMM223_JTMU7079_JTMU7079_JTMU7079_JTMU7079_JTMU7079_JTMU7079_JTMU7079_JTMU7079_JTMU7079_JTMU7079_JTMU7079_JTMU7079_JTMU7079_JTMU7079_JTMU7079_JTMU7079_JTMU7079_JTMU7079_JTMU7079_JTMU7079_JTMU7079_JTMU7079_JTMU7079_JTMU7079_JTMU7079_JTMU7079_JTMU7079_JTMU7079_JTMU7079_JTMU7079_JTMU7079_JTMU7079_JTMU7079_JTMU7079_U_tj_medium_2"  type="fixed" >
  <origin  rpy="0 1.5707963267949 0"  xyz="-0.047 0 -0.0635" />
  <parent  link="JMM223_JTMU7079_JTMU7079_JTMU7079_JTMU7079_JTMU7079_JTMU7079_JTMU7079_JTMU7079_JTMU7079_JTMU7079_JTMU7079_JTMU7079_JTMU7079_JTMU7079_JTMU7079_JTMU7079_JTMU7079_JTMU7079_JTMU7079_JTMU7079_JTMU7079_JTMU7079_JTMU7079_JTMU7079_JTMU7079_JTMU7079_JTMU7079_JTMU7079_JTMU7079_JTMU7079_JTMU7079_JTMU7079_JTMU7079_JTMU7079_U_tj_body" />
  <child  link="JMM223_JTMU7079_JTMU7079_JTMU7079_JTMU7079_JTMU7079_JTMU7079_JTMU7079_JTMU7079_JTMU7079_JTMU7079_JTMU7079_JTMU7079_JTMU7079_JTMU7079_JTMU7079_JTMU7079_JTMU7079_JTMU7079_JTMU7079_JTMU7079_JTMU7079_JTMU7079_JTMU7079_JTMU7079_JTMU7079_JTMU7079_JTMU7079_JTMU7079_JTMU7079_JTMU7079_JTMU7079_JTMU7079_JTMU7079_JTMU7079_U_tj_in" />
  <axis  xyz="0 -1 0" />
 </joint>
 <joint  name="JMM223_JTMU7079_JTMU7079_JTMU7079_JTMU7079_JTMU7079_JTMU7079_JTMU7079_JTMU7079_JTMU7079_JTMU7079_JTMU7079_JTMU7079_JTMU7079_JTMU7079_JTMU7079_JTMU7079_JTMU7079_JTMU7079_JTMU7079_JTMU7079_JTMU7079_JTMU7079_JTMU7079_JTMU7079_JTMU7079_JTMU7079_JTMU7079_JTMU7079_JTMU7079_JTMU7079_JTMU7079_JTMU7079_JTMU7079_IMU7203_U_ic_medium_1"  type="fixed" >
  <origin  rpy="0 0 0"  xyz="0 0 0" />
  <parent  link="JMM223_JTMU7079_JTMU7079_JTMU7079_JTMU7079_JTMU7079_JTMU7079_JTMU7079_JTMU7079_JTMU7079_JTMU7079_JTMU7079_JTMU7079_JTMU7079_JTMU7079_JTMU7079_JTMU7079_JTMU7079_JTMU7079_JTMU7079_JTMU7079_JTMU7079_JTMU7079_JTMU7079_JTMU7079_JTMU7079_JTMU7079_JTMU7079_JTMU7079_JTMU7079_JTMU7079_JTMU7079_JTMU7079_JTMU7079_JTMU7079_U_tj_in" />
  <child  link="JMM223_JTMU7079_JTMU7079_JTMU7079_JTMU7079_JTMU7079_JTMU7079_JTMU7079_JTMU7079_JTMU7079_JTMU7079_JTMU7079_JTMU7079_JTMU7079_JTMU7079_JTMU7079_JTMU7079_JTMU7079_JTMU7079_JTMU7079_JTMU7079_JTMU7079_JTMU7079_JTMU7079_JTMU7079_JTMU7079_JTMU7079_JTMU7079_JTMU7079_JTMU7079_JTMU7079_JTMU7079_JTMU7079_JTMU7079_IMU7203_U_ic_body" />
  <axis  xyz="0 0 0" />
 </joint>
 <joint  name="JMM223_JTMU7079_JTMU7079_JTMU7079_JTMU7079_JTMU7079_JTMU7079_JTMU7079_JTMU7079_JTMU7079_JTMU7079_JTMU7079_JTMU7079_JTMU7079_JTMU7079_JTMU7079_JTMU7079_JTMU7079_JTMU7079_JTMU7079_JTMU7079_JTMU7079_JTMU7079_JTMU7079_JTMU7079_JTMU7079_JTMU7079_JTMU7079_JTMU7079_JTMU7079_JTMU7079_JTMU7079_JTMU7079_JTMU7079_IMU7203_U_ic_medium_2"  type="fixed" >
  <origin  rpy="0 0 0"  xyz="0 0 -0.0094" />
  <parent  link="JMM223_JTMU7079_JTMU7079_JTMU7079_JTMU7079_JTMU7079_JTMU7079_JTMU7079_JTMU7079_JTMU7079_JTMU7079_JTMU7079_JTMU7079_JTMU7079_JTMU7079_JTMU7079_JTMU7079_JTMU7079_JTMU7079_JTMU7079_JTMU7079_JTMU7079_JTMU7079_JTMU7079_JTMU7079_JTMU7079_JTMU7079_JTMU7079_JTMU7079_JTMU7079_JTMU7079_JTMU7079_JTMU7079_JTMU7079_IMU7203_U_ic_body" />
  <child  link="JMM223_JTMU7079_JTMU7079_JTMU7079_JTMU7079_JTMU7079_JTMU7079_JTMU7079_JTMU7079_JTMU7079_JTMU7079_JTMU7079_JTMU7079_JTMU7079_JTMU7079_JTMU7079_JTMU7079_JTMU7079_JTMU7079_JTMU7079_JTMU7079_JTMU7079_JTMU7079_JTMU7079_JTMU7079_JTMU7079_JTMU7079_JTMU7079_JTMU7079_JTMU7079_JTMU7079_JTMU7079_JTMU7079_JTMU7079_IMU7203_U_ic_in" />
  <axis  xyz="0 0 0" />
 </joint>
 <joint  name="JMM223_JTMU7079_JTMU7079_JTMU7079_JTMU7079_JTMU7079_JTMU7079_JTMU7079_JTMU7079_JTMU7079_JTMU7079_JTMU7079_JTMU7079_JTMU7079_JTMU7079_JTMU7079_JTMU7079_JTMU7079_JTMU7079_JTMU7079_JTMU7079_JTMU7079_JTMU7079_JTMU7079_JTMU7079_JTMU7079_JTMU7079_JTMU7079_JTMU7079_JTMU7079_JTMU7079_JTMU7079_JTMU7079_JTMU7080_U_tj_medium_1"  type="revolute" >
  <origin  rpy="0.0 0.0 3.141592653589793"  xyz="0.0 0.0 0.0" />
  <parent  link="JMM223_JTMU7079_JTMU7079_JTMU7079_JTMU7079_JTMU7079_JTMU7079_JTMU7079_JTMU7079_JTMU7079_JTMU7079_JTMU7079_JTMU7079_JTMU7079_JTMU7079_JTMU7079_JTMU7079_JTMU7079_JTMU7079_JTMU7079_JTMU7079_JTMU7079_JTMU7079_JTMU7079_JTMU7079_JTMU7079_JTMU7079_JTMU7079_JTMU7079_JTMU7079_JTMU7079_JTMU7079_JTMU7079_JTMU7079_IMU7203_U_ic_in" />
  <child  link="JMM223_JTMU7079_JTMU7079_JTMU7079_JTMU7079_JTMU7079_JTMU7079_JTMU7079_JTMU7079_JTMU7079_JTMU7079_JTMU7079_JTMU7079_JTMU7079_JTMU7079_JTMU7079_JTMU7079_JTMU7079_JTMU7079_JTMU7079_JTMU7079_JTMU7079_JTMU7079_JTMU7079_JTMU7079_JTMU7079_JTMU7079_JTMU7079_JTMU7079_JTMU7079_JTMU7079_JTMU7079_JTMU7079_JTMU7080_U_tj_body" />
  <axis  xyz="0 0 1" />
  <limit  velocity="0.33"  upper="3.1416"  lower="-3.1416"  effort="25.5" />
 </joint>
 <joint  name="JMM223_JTMU7079_JTMU7079_JTMU7079_JTMU7079_JTMU7079_JTMU7079_JTMU7079_JTMU7079_JTMU7079_JTMU7079_JTMU7079_JTMU7079_JTMU7079_JTMU7079_JTMU7079_JTMU7079_JTMU7079_JTMU7079_JTMU7079_JTMU7079_JTMU7079_JTMU7079_JTMU7079_JTMU7079_JTMU7079_JTMU7079_JTMU7079_JTMU7079_JTMU7079_JTMU7079_JTMU7079_JTMU7079_JTMU7080_U_tj_medium_2"  type="fixed" >
  <origin  rpy="0 1.5707963267949 0"  xyz="-0.047 0 -0.0635" />
  <parent  link="JMM223_JTMU7079_JTMU7079_JTMU7079_JTMU7079_JTMU7079_JTMU7079_JTMU7079_JTMU7079_JTMU7079_JTMU7079_JTMU7079_JTMU7079_JTMU7079_JTMU7079_JTMU7079_JTMU7079_JTMU7079_JTMU7079_JTMU7079_JTMU7079_JTMU7079_JTMU7079_JTMU7079_JTMU7079_JTMU7079_JTMU7079_JTMU7079_JTMU7079_JTMU7079_JTMU7079_JTMU7079_JTMU7079_JTMU7080_U_tj_body" />
  <child  link="JMM223_JTMU7079_JTMU7079_JTMU7079_JTMU7079_JTMU7079_JTMU7079_JTMU7079_JTMU7079_JTMU7079_JTMU7079_JTMU7079_JTMU7079_JTMU7079_JTMU7079_JTMU7079_JTMU7079_JTMU7079_JTMU7079_JTMU7079_JTMU7079_JTMU7079_JTMU7079_JTMU7079_JTMU7079_JTMU7079_JTMU7079_JTMU7079_JTMU7079_JTMU7079_JTMU7079_JTMU7079_JTMU7079_JTMU7080_U_tj_in" />
  <axis  xyz="0 -1 0" />
 </joint>
 <joint  name="JMM223_JTMU7079_JTMU7079_JTMU7079_JTMU7079_JTMU7079_JTMU7079_JTMU7079_JTMU7079_JTMU7079_JTMU7079_JTMU7079_JTMU7079_JTMU7079_JTMU7079_JTMU7079_JTMU7079_JTMU7079_JTMU7079_JTMU7079_JTMU7079_JTMU7079_JTMU7079_JTMU7079_JTMU7079_JTMU7079_JTMU7079_JTMU7079_JTMU7079_JTMU7079_JTMU7079_JTMU7079_IMU7204_U_ic_medium_1"  type="fixed" >
  <origin  rpy="0 0 0"  xyz="0 0 0" />
  <parent  link="JMM223_JTMU7079_JTMU7079_JTMU7079_JTMU7079_JTMU7079_JTMU7079_JTMU7079_JTMU7079_JTMU7079_JTMU7079_JTMU7079_JTMU7079_JTMU7079_JTMU7079_JTMU7079_JTMU7079_JTMU7079_JTMU7079_JTMU7079_JTMU7079_JTMU7079_JTMU7079_JTMU7079_JTMU7079_JTMU7079_JTMU7079_JTMU7079_JTMU7079_JTMU7079_JTMU7079_JTMU7079_JTMU7079_JTMU7080_U_tj_in" />
  <child  link="JMM223_JTMU7079_JTMU7079_JTMU7079_JTMU7079_JTMU7079_JTMU7079_JTMU7079_JTMU7079_JTMU7079_JTMU7079_JTMU7079_JTMU7079_JTMU7079_JTMU7079_JTMU7079_JTMU7079_JTMU7079_JTMU7079_JTMU7079_JTMU7079_JTMU7079_JTMU7079_JTMU7079_JTMU7079_JTMU7079_JTMU7079_JTMU7079_JTMU7079_JTMU7079_JTMU7079_JTMU7079_IMU7204_U_ic_body" />
  <axis  xyz="0 0 0" />
 </joint>
 <joint  name="JMM223_JTMU7079_JTMU7079_JTMU7079_JTMU7079_JTMU7079_JTMU7079_JTMU7079_JTMU7079_JTMU7079_JTMU7079_JTMU7079_JTMU7079_JTMU7079_JTMU7079_JTMU7079_JTMU7079_JTMU7079_JTMU7079_JTMU7079_JTMU7079_JTMU7079_JTMU7079_JTMU7079_JTMU7079_JTMU7079_JTMU7079_JTMU7079_JTMU7079_JTMU7079_JTMU7079_JTMU7079_IMU7204_U_ic_medium_2"  type="fixed" >
  <origin  rpy="0 0 0"  xyz="0 0 -0.0094" />
  <parent  link="JMM223_JTMU7079_JTMU7079_JTMU7079_JTMU7079_JTMU7079_JTMU7079_JTMU7079_JTMU7079_JTMU7079_JTMU7079_JTMU7079_JTMU7079_JTMU7079_JTMU7079_JTMU7079_JTMU7079_JTMU7079_JTMU7079_JTMU7079_JTMU7079_JTMU7079_JTMU7079_JTMU7079_JTMU7079_JTMU7079_JTMU7079_JTMU7079_JTMU7079_JTMU7079_JTMU7079_JTMU7079_IMU7204_U_ic_body" />
  <child  link="JMM223_JTMU7079_JTMU7079_JTMU7079_JTMU7079_JTMU7079_JTMU7079_JTMU7079_JTMU7079_JTMU7079_JTMU7079_JTMU7079_JTMU7079_JTMU7079_JTMU7079_JTMU7079_JTMU7079_JTMU7079_JTMU7079_JTMU7079_JTMU7079_JTMU7079_JTMU7079_JTMU7079_JTMU7079_JTMU7079_JTMU7079_JTMU7079_JTMU7079_JTMU7079_JTMU7079_JTMU7079_IMU7204_U_ic_in" />
  <axis  xyz="0 0 0" />
 </joint>
 <joint  name="JMM223_JTMU7079_JTMU7079_JTMU7079_JTMU7079_JTMU7079_JTMU7079_JTMU7079_JTMU7079_JTMU7079_JTMU7079_JTMU7079_JTMU7079_JTMU7079_JTMU7079_JTMU7079_JTMU7079_JTMU7079_JTMU7079_JTMU7079_JTMU7079_JTMU7079_JTMU7079_JTMU7079_JTMU7079_JTMU7079_JTMU7079_JTMU7079_JTMU7079_JTMU7079_JTMU7079_JTMU7081_U_tj_medium_1"  type="revolute" >
  <origin  rpy="0.0 0.0 3.141592653589793"  xyz="0.0 0.0 0.0" />
  <parent  link="JMM223_JTMU7079_JTMU7079_JTMU7079_JTMU7079_JTMU7079_JTMU7079_JTMU7079_JTMU7079_JTMU7079_JTMU7079_JTMU7079_JTMU7079_JTMU7079_JTMU7079_JTMU7079_JTMU7079_JTMU7079_JTMU7079_JTMU7079_JTMU7079_JTMU7079_JTMU7079_JTMU7079_JTMU7079_JTMU7079_JTMU7079_JTMU7079_JTMU7079_JTMU7079_JTMU7079_JTMU7079_IMU7204_U_ic_in" />
  <child  link="JMM223_JTMU7079_JTMU7079_JTMU7079_JTMU7079_JTMU7079_JTMU7079_JTMU7079_JTMU7079_JTMU7079_JTMU7079_JTMU7079_JTMU7079_JTMU7079_JTMU7079_JTMU7079_JTMU7079_JTMU7079_JTMU7079_JTMU7079_JTMU7079_JTMU7079_JTMU7079_JTMU7079_JTMU7079_JTMU7079_JTMU7079_JTMU7079_JTMU7079_JTMU7079_JTMU7079_JTMU7081_U_tj_body" />
  <axis  xyz="0 0 1" />
  <limit  velocity="0.33"  upper="3.1416"  lower="-3.1416"  effort="25.5" />
 </joint>
 <joint  name="JMM223_JTMU7079_JTMU7079_JTMU7079_JTMU7079_JTMU7079_JTMU7079_JTMU7079_JTMU7079_JTMU7079_JTMU7079_JTMU7079_JTMU7079_JTMU7079_JTMU7079_JTMU7079_JTMU7079_JTMU7079_JTMU7079_JTMU7079_JTMU7079_JTMU7079_JTMU7079_JTMU7079_JTMU7079_JTMU7079_JTMU7079_JTMU7079_JTMU7079_JTMU7079_JTMU7079_JTMU7081_U_tj_medium_2"  type="fixed" >
  <origin  rpy="0 1.5707963267949 0"  xyz="-0.047 0 -0.0635" />
  <parent  link="JMM223_JTMU7079_JTMU7079_JTMU7079_JTMU7079_JTMU7079_JTMU7079_JTMU7079_JTMU7079_JTMU7079_JTMU7079_JTMU7079_JTMU7079_JTMU7079_JTMU7079_JTMU7079_JTMU7079_JTMU7079_JTMU7079_JTMU7079_JTMU7079_JTMU7079_JTMU7079_JTMU7079_JTMU7079_JTMU7079_JTMU7079_JTMU7079_JTMU7079_JTMU7079_JTMU7079_JTMU7081_U_tj_body" />
  <child  link="JMM223_JTMU7079_JTMU7079_JTMU7079_JTMU7079_JTMU7079_JTMU7079_JTMU7079_JTMU7079_JTMU7079_JTMU7079_JTMU7079_JTMU7079_JTMU7079_JTMU7079_JTMU7079_JTMU7079_JTMU7079_JTMU7079_JTMU7079_JTMU7079_JTMU7079_JTMU7079_JTMU7079_JTMU7079_JTMU7079_JTMU7079_JTMU7079_JTMU7079_JTMU7079_JTMU7079_JTMU7081_U_tj_in" />
  <axis  xyz="0 -1 0" />
 </joint>
 <joint  name="JMM223_JTMU7079_JTMU7079_JTMU7079_JTMU7079_JTMU7079_JTMU7079_JTMU7079_JTMU7079_JTMU7079_JTMU7079_JTMU7079_JTMU7079_JTMU7079_JTMU7079_JTMU7079_JTMU7079_JTMU7079_JTMU7079_JTMU7079_JTMU7079_JTMU7079_JTMU7079_JTMU7079_JTMU7079_JTMU7079_JTMU7079_JTMU7079_JTMU7079_JTMU7079_IMU7205_U_ic_medium_1"  type="fixed" >
  <origin  rpy="0 0 0"  xyz="0 0 0" />
  <parent  link="JMM223_JTMU7079_JTMU7079_JTMU7079_JTMU7079_JTMU7079_JTMU7079_JTMU7079_JTMU7079_JTMU7079_JTMU7079_JTMU7079_JTMU7079_JTMU7079_JTMU7079_JTMU7079_JTMU7079_JTMU7079_JTMU7079_JTMU7079_JTMU7079_JTMU7079_JTMU7079_JTMU7079_JTMU7079_JTMU7079_JTMU7079_JTMU7079_JTMU7079_JTMU7079_JTMU7079_JTMU7081_U_tj_in" />
  <child  link="JMM223_JTMU7079_JTMU7079_JTMU7079_JTMU7079_JTMU7079_JTMU7079_JTMU7079_JTMU7079_JTMU7079_JTMU7079_JTMU7079_JTMU7079_JTMU7079_JTMU7079_JTMU7079_JTMU7079_JTMU7079_JTMU7079_JTMU7079_JTMU7079_JTMU7079_JTMU7079_JTMU7079_JTMU7079_JTMU7079_JTMU7079_JTMU7079_JTMU7079_JTMU7079_IMU7205_U_ic_body" />
  <axis  xyz="0 0 0" />
 </joint>
 <joint  name="JMM223_JTMU7079_JTMU7079_JTMU7079_JTMU7079_JTMU7079_JTMU7079_JTMU7079_JTMU7079_JTMU7079_JTMU7079_JTMU7079_JTMU7079_JTMU7079_JTMU7079_JTMU7079_JTMU7079_JTMU7079_JTMU7079_JTMU7079_JTMU7079_JTMU7079_JTMU7079_JTMU7079_JTMU7079_JTMU7079_JTMU7079_JTMU7079_JTMU7079_JTMU7079_IMU7205_U_ic_medium_2"  type="fixed" >
  <origin  rpy="0 0 0"  xyz="0 0 -0.0094" />
  <parent  link="JMM223_JTMU7079_JTMU7079_JTMU7079_JTMU7079_JTMU7079_JTMU7079_JTMU7079_JTMU7079_JTMU7079_JTMU7079_JTMU7079_JTMU7079_JTMU7079_JTMU7079_JTMU7079_JTMU7079_JTMU7079_JTMU7079_JTMU7079_JTMU7079_JTMU7079_JTMU7079_JTMU7079_JTMU7079_JTMU7079_JTMU7079_JTMU7079_JTMU7079_JTMU7079_IMU7205_U_ic_body" />
  <child  link="JMM223_JTMU7079_JTMU7079_JTMU7079_JTMU7079_JTMU7079_JTMU7079_JTMU7079_JTMU7079_JTMU7079_JTMU7079_JTMU7079_JTMU7079_JTMU7079_JTMU7079_JTMU7079_JTMU7079_JTMU7079_JTMU7079_JTMU7079_JTMU7079_JTMU7079_JTMU7079_JTMU7079_JTMU7079_JTMU7079_JTMU7079_JTMU7079_JTMU7079_JTMU7079_IMU7205_U_ic_in" />
  <axis  xyz="0 0 0" />
 </joint>
 <joint  name="JMM223_JTMU7079_JTMU7079_JTMU7079_JTMU7079_JTMU7079_JTMU7079_JTMU7079_JTMU7079_JTMU7079_JTMU7079_JTMU7079_JTMU7079_JTMU7079_JTMU7079_JTMU7079_JTMU7079_JTMU7079_JTMU7079_JTMU7079_JTMU7079_JTMU7079_JTMU7079_JTMU7079_JTMU7079_JTMU7079_JTMU7079_JTMU7079_JTMU7079_JTMU7082_U_tj_medium_1"  type="revolute" >
  <origin  rpy="0.0 0.0 3.141592653589793"  xyz="0.0 0.0 0.0" />
  <parent  link="JMM223_JTMU7079_JTMU7079_JTMU7079_JTMU7079_JTMU7079_JTMU7079_JTMU7079_JTMU7079_JTMU7079_JTMU7079_JTMU7079_JTMU7079_JTMU7079_JTMU7079_JTMU7079_JTMU7079_JTMU7079_JTMU7079_JTMU7079_JTMU7079_JTMU7079_JTMU7079_JTMU7079_JTMU7079_JTMU7079_JTMU7079_JTMU7079_JTMU7079_JTMU7079_IMU7205_U_ic_in" />
  <child  link="JMM223_JTMU7079_JTMU7079_JTMU7079_JTMU7079_JTMU7079_JTMU7079_JTMU7079_JTMU7079_JTMU7079_JTMU7079_JTMU7079_JTMU7079_JTMU7079_JTMU7079_JTMU7079_JTMU7079_JTMU7079_JTMU7079_JTMU7079_JTMU7079_JTMU7079_JTMU7079_JTMU7079_JTMU7079_JTMU7079_JTMU7079_JTMU7079_JTMU7079_JTMU7082_U_tj_body" />
  <axis  xyz="0 0 1" />
  <limit  velocity="0.33"  upper="3.1416"  lower="-3.1416"  effort="25.5" />
 </joint>
 <joint  name="JMM223_JTMU7079_JTMU7079_JTMU7079_JTMU7079_JTMU7079_JTMU7079_JTMU7079_JTMU7079_JTMU7079_JTMU7079_JTMU7079_JTMU7079_JTMU7079_JTMU7079_JTMU7079_JTMU7079_JTMU7079_JTMU7079_JTMU7079_JTMU7079_JTMU7079_JTMU7079_JTMU7079_JTMU7079_JTMU7079_JTMU7079_JTMU7079_JTMU7079_JTMU7082_U_tj_medium_2"  type="fixed" >
  <origin  rpy="0 1.5707963267949 0"  xyz="-0.047 0 -0.0635" />
  <parent  link="JMM223_JTMU7079_JTMU7079_JTMU7079_JTMU7079_JTMU7079_JTMU7079_JTMU7079_JTMU7079_JTMU7079_JTMU7079_JTMU7079_JTMU7079_JTMU7079_JTMU7079_JTMU7079_JTMU7079_JTMU7079_JTMU7079_JTMU7079_JTMU7079_JTMU7079_JTMU7079_JTMU7079_JTMU7079_JTMU7079_JTMU7079_JTMU7079_JTMU7079_JTMU7082_U_tj_body" />
  <child  link="JMM223_JTMU7079_JTMU7079_JTMU7079_JTMU7079_JTMU7079_JTMU7079_JTMU7079_JTMU7079_JTMU7079_JTMU7079_JTMU7079_JTMU7079_JTMU7079_JTMU7079_JTMU7079_JTMU7079_JTMU7079_JTMU7079_JTMU7079_JTMU7079_JTMU7079_JTMU7079_JTMU7079_JTMU7079_JTMU7079_JTMU7079_JTMU7079_JTMU7079_JTMU7082_U_tj_in" />
  <axis  xyz="0 -1 0" />
 </joint>
 <joint  name="JMM223_JTMU7079_JTMU7079_JTMU7079_JTMU7079_JTMU7079_JTMU7079_JTMU7079_JTMU7079_JTMU7079_JTMU7079_JTMU7079_JTMU7079_JTMU7079_JTMU7079_JTMU7079_JTMU7079_JTMU7079_JTMU7079_JTMU7079_JTMU7079_JTMU7079_JTMU7079_JTMU7079_JTMU7079_JTMU7079_JTMU7079_JTMU7079_IMU7206_U_ic_medium_1"  type="fixed" >
  <origin  rpy="0 0 0"  xyz="0 0 0" />
  <parent  link="JMM223_JTMU7079_JTMU7079_JTMU7079_JTMU7079_JTMU7079_JTMU7079_JTMU7079_JTMU7079_JTMU7079_JTMU7079_JTMU7079_JTMU7079_JTMU7079_JTMU7079_JTMU7079_JTMU7079_JTMU7079_JTMU7079_JTMU7079_JTMU7079_JTMU7079_JTMU7079_JTMU7079_JTMU7079_JTMU7079_JTMU7079_JTMU7079_JTMU7079_JTMU7082_U_tj_in" />
  <child  link="JMM223_JTMU7079_JTMU7079_JTMU7079_JTMU7079_JTMU7079_JTMU7079_JTMU7079_JTMU7079_JTMU7079_JTMU7079_JTMU7079_JTMU7079_JTMU7079_JTMU7079_JTMU7079_JTMU7079_JTMU7079_JTMU7079_JTMU7079_JTMU7079_JTMU7079_JTMU7079_JTMU7079_JTMU7079_JTMU7079_JTMU7079_JTMU7079_IMU7206_U_ic_body" />
  <axis  xyz="0 0 0" />
 </joint>
 <joint  name="JMM223_JTMU7079_JTMU7079_JTMU7079_JTMU7079_JTMU7079_JTMU7079_JTMU7079_JTMU7079_JTMU7079_JTMU7079_JTMU7079_JTMU7079_JTMU7079_JTMU7079_JTMU7079_JTMU7079_JTMU7079_JTMU7079_JTMU7079_JTMU7079_JTMU7079_JTMU7079_JTMU7079_JTMU7079_JTMU7079_JTMU7079_JTMU7079_IMU7206_U_ic_medium_2"  type="fixed" >
  <origin  rpy="0 0 0"  xyz="0 0 -0.0094" />
  <parent  link="JMM223_JTMU7079_JTMU7079_JTMU7079_JTMU7079_JTMU7079_JTMU7079_JTMU7079_JTMU7079_JTMU7079_JTMU7079_JTMU7079_JTMU7079_JTMU7079_JTMU7079_JTMU7079_JTMU7079_JTMU7079_JTMU7079_JTMU7079_JTMU7079_JTMU7079_JTMU7079_JTMU7079_JTMU7079_JTMU7079_JTMU7079_JTMU7079_IMU7206_U_ic_body" />
  <child  link="JMM223_JTMU7079_JTMU7079_JTMU7079_JTMU7079_JTMU7079_JTMU7079_JTMU7079_JTMU7079_JTMU7079_JTMU7079_JTMU7079_JTMU7079_JTMU7079_JTMU7079_JTMU7079_JTMU7079_JTMU7079_JTMU7079_JTMU7079_JTMU7079_JTMU7079_JTMU7079_JTMU7079_JTMU7079_JTMU7079_JTMU7079_JTMU7079_IMU7206_U_ic_in" />
  <axis  xyz="0 0 0" />
 </joint>
 <joint  name="JMM223_JTMU7079_JTMU7079_JTMU7079_JTMU7079_JTMU7079_JTMU7079_JTMU7079_JTMU7079_JTMU7079_JTMU7079_JTMU7079_JTMU7079_JTMU7079_JTMU7079_JTMU7079_JTMU7079_JTMU7079_JTMU7079_JTMU7079_JTMU7079_JTMU7079_JTMU7079_JTMU7079_JTMU7079_JTMU7079_JTMU7079_JTMU7083_U_tj_medium_1"  type="revolute" >
  <origin  rpy="0.0 0.0 3.141592653589793"  xyz="0.0 0.0 0.0" />
  <parent  link="JMM223_JTMU7079_JTMU7079_JTMU7079_JTMU7079_JTMU7079_JTMU7079_JTMU7079_JTMU7079_JTMU7079_JTMU7079_JTMU7079_JTMU7079_JTMU7079_JTMU7079_JTMU7079_JTMU7079_JTMU7079_JTMU7079_JTMU7079_JTMU7079_JTMU7079_JTMU7079_JTMU7079_JTMU7079_JTMU7079_JTMU7079_JTMU7079_IMU7206_U_ic_in" />
  <child  link="JMM223_JTMU7079_JTMU7079_JTMU7079_JTMU7079_JTMU7079_JTMU7079_JTMU7079_JTMU7079_JTMU7079_JTMU7079_JTMU7079_JTMU7079_JTMU7079_JTMU7079_JTMU7079_JTMU7079_JTMU7079_JTMU7079_JTMU7079_JTMU7079_JTMU7079_JTMU7079_JTMU7079_JTMU7079_JTMU7079_JTMU7079_JTMU7083_U_tj_body" />
  <axis  xyz="0 0 1" />
  <limit  velocity="0.33"  upper="3.1416"  lower="-3.1416"  effort="25.5" />
 </joint>
 <joint  name="JMM223_JTMU7079_JTMU7079_JTMU7079_JTMU7079_JTMU7079_JTMU7079_JTMU7079_JTMU7079_JTMU7079_JTMU7079_JTMU7079_JTMU7079_JTMU7079_JTMU7079_JTMU7079_JTMU7079_JTMU7079_JTMU7079_JTMU7079_JTMU7079_JTMU7079_JTMU7079_JTMU7079_JTMU7079_JTMU7079_JTMU7079_JTMU7083_U_tj_medium_2"  type="fixed" >
  <origin  rpy="0 1.5707963267949 0"  xyz="-0.047 0 -0.0635" />
  <parent  link="JMM223_JTMU7079_JTMU7079_JTMU7079_JTMU7079_JTMU7079_JTMU7079_JTMU7079_JTMU7079_JTMU7079_JTMU7079_JTMU7079_JTMU7079_JTMU7079_JTMU7079_JTMU7079_JTMU7079_JTMU7079_JTMU7079_JTMU7079_JTMU7079_JTMU7079_JTMU7079_JTMU7079_JTMU7079_JTMU7079_JTMU7079_JTMU7083_U_tj_body" />
  <child  link="JMM223_JTMU7079_JTMU7079_JTMU7079_JTMU7079_JTMU7079_JTMU7079_JTMU7079_JTMU7079_JTMU7079_JTMU7079_JTMU7079_JTMU7079_JTMU7079_JTMU7079_JTMU7079_JTMU7079_JTMU7079_JTMU7079_JTMU7079_JTMU7079_JTMU7079_JTMU7079_JTMU7079_JTMU7079_JTMU7079_JTMU7079_JTMU7083_U_tj_in" />
  <axis  xyz="0 -1 0" />
 </joint>
 <joint  name="JMM223_JTMU7079_JTMU7079_JTMU7079_JTMU7079_JTMU7079_JTMU7079_JTMU7079_JTMU7079_JTMU7079_JTMU7079_JTMU7079_JTMU7079_JTMU7079_JTMU7079_JTMU7079_JTMU7079_JTMU7079_JTMU7079_JTMU7079_JTMU7079_JTMU7079_JTMU7079_JTMU7079_JTMU7079_JTMU7079_IMU7207_U_ic_medium_1"  type="fixed" >
  <origin  rpy="0 0 0"  xyz="0 0 0" />
  <parent  link="JMM223_JTMU7079_JTMU7079_JTMU7079_JTMU7079_JTMU7079_JTMU7079_JTMU7079_JTMU7079_JTMU7079_JTMU7079_JTMU7079_JTMU7079_JTMU7079_JTMU7079_JTMU7079_JTMU7079_JTMU7079_JTMU7079_JTMU7079_JTMU7079_JTMU7079_JTMU7079_JTMU7079_JTMU7079_JTMU7079_JTMU7079_JTMU7083_U_tj_in" />
  <child  link="JMM223_JTMU7079_JTMU7079_JTMU7079_JTMU7079_JTMU7079_JTMU7079_JTMU7079_JTMU7079_JTMU7079_JTMU7079_JTMU7079_JTMU7079_JTMU7079_JTMU7079_JTMU7079_JTMU7079_JTMU7079_JTMU7079_JTMU7079_JTMU7079_JTMU7079_JTMU7079_JTMU7079_JTMU7079_JTMU7079_IMU7207_U_ic_body" />
  <axis  xyz="0 0 0" />
 </joint>
 <joint  name="JMM223_JTMU7079_JTMU7079_JTMU7079_JTMU7079_JTMU7079_JTMU7079_JTMU7079_JTMU7079_JTMU7079_JTMU7079_JTMU7079_JTMU7079_JTMU7079_JTMU7079_JTMU7079_JTMU7079_JTMU7079_JTMU7079_JTMU7079_JTMU7079_JTMU7079_JTMU7079_JTMU7079_JTMU7079_JTMU7079_IMU7207_U_ic_medium_2"  type="fixed" >
  <origin  rpy="0 0 0"  xyz="0 0 -0.0094" />
  <parent  link="JMM223_JTMU7079_JTMU7079_JTMU7079_JTMU7079_JTMU7079_JTMU7079_JTMU7079_JTMU7079_JTMU7079_JTMU7079_JTMU7079_JTMU7079_JTMU7079_JTMU7079_JTMU7079_JTMU7079_JTMU7079_JTMU7079_JTMU7079_JTMU7079_JTMU7079_JTMU7079_JTMU7079_JTMU7079_JTMU7079_IMU7207_U_ic_body" />
  <child  link="JMM223_JTMU7079_JTMU7079_JTMU7079_JTMU7079_JTMU7079_JTMU7079_JTMU7079_JTMU7079_JTMU7079_JTMU7079_JTMU7079_JTMU7079_JTMU7079_JTMU7079_JTMU7079_JTMU7079_JTMU7079_JTMU7079_JTMU7079_JTMU7079_JTMU7079_JTMU7079_JTMU7079_JTMU7079_JTMU7079_IMU7207_U_ic_in" />
  <axis  xyz="0 0 0" />
 </joint>
 <joint  name="JMM223_JTMU7079_JTMU7079_JTMU7079_JTMU7079_JTMU7079_JTMU7079_JTMU7079_JTMU7079_JTMU7079_JTMU7079_JTMU7079_JTMU7079_JTMU7079_JTMU7079_JTMU7079_JTMU7079_JTMU7079_JTMU7079_JTMU7079_JTMU7079_JTMU7079_JTMU7079_JTMU7079_JTMU7079_JTMU7084_U_tj_medium_1"  type="revolute" >
  <origin  rpy="0.0 0.0 3.141592653589793"  xyz="0.0 0.0 0.0" />
  <parent  link="JMM223_JTMU7079_JTMU7079_JTMU7079_JTMU7079_JTMU7079_JTMU7079_JTMU7079_JTMU7079_JTMU7079_JTMU7079_JTMU7079_JTMU7079_JTMU7079_JTMU7079_JTMU7079_JTMU7079_JTMU7079_JTMU7079_JTMU7079_JTMU7079_JTMU7079_JTMU7079_JTMU7079_JTMU7079_JTMU7079_IMU7207_U_ic_in" />
  <child  link="JMM223_JTMU7079_JTMU7079_JTMU7079_JTMU7079_JTMU7079_JTMU7079_JTMU7079_JTMU7079_JTMU7079_JTMU7079_JTMU7079_JTMU7079_JTMU7079_JTMU7079_JTMU7079_JTMU7079_JTMU7079_JTMU7079_JTMU7079_JTMU7079_JTMU7079_JTMU7079_JTMU7079_JTMU7079_JTMU7084_U_tj_body" />
  <axis  xyz="0 0 1" />
  <limit  velocity="0.33"  upper="3.1416"  lower="-3.1416"  effort="25.5" />
 </joint>
 <joint  name="JMM223_JTMU7079_JTMU7079_JTMU7079_JTMU7079_JTMU7079_JTMU7079_JTMU7079_JTMU7079_JTMU7079_JTMU7079_JTMU7079_JTMU7079_JTMU7079_JTMU7079_JTMU7079_JTMU7079_JTMU7079_JTMU7079_JTMU7079_JTMU7079_JTMU7079_JTMU7079_JTMU7079_JTMU7079_JTMU7084_U_tj_medium_2"  type="fixed" >
  <origin  rpy="0 1.5707963267949 0"  xyz="-0.047 0 -0.0635" />
  <parent  link="JMM223_JTMU7079_JTMU7079_JTMU7079_JTMU7079_JTMU7079_JTMU7079_JTMU7079_JTMU7079_JTMU7079_JTMU7079_JTMU7079_JTMU7079_JTMU7079_JTMU7079_JTMU7079_JTMU7079_JTMU7079_JTMU7079_JTMU7079_JTMU7079_JTMU7079_JTMU7079_JTMU7079_JTMU7079_JTMU7084_U_tj_body" />
  <child  link="JMM223_JTMU7079_JTMU7079_JTMU7079_JTMU7079_JTMU7079_JTMU7079_JTMU7079_JTMU7079_JTMU7079_JTMU7079_JTMU7079_JTMU7079_JTMU7079_JTMU7079_JTMU7079_JTMU7079_JTMU7079_JTMU7079_JTMU7079_JTMU7079_JTMU7079_JTMU7079_JTMU7079_JTMU7079_JTMU7084_U_tj_in" />
  <axis  xyz="0 -1 0" />
 </joint>
 <joint  name="JMM223_JTMU7079_JTMU7079_JTMU7079_JTMU7079_JTMU7079_JTMU7079_JTMU7079_JTMU7079_JTMU7079_JTMU7079_JTMU7079_JTMU7079_JTMU7079_JTMU7079_JTMU7079_JTMU7079_JTMU7079_JTMU7079_JTMU7079_JTMU7079_JTMU7079_JTMU7079_JTMU7079_IMU7208_U_ic_medium_1"  type="fixed" >
  <origin  rpy="0 0 0"  xyz="0 0 0" />
  <parent  link="JMM223_JTMU7079_JTMU7079_JTMU7079_JTMU7079_JTMU7079_JTMU7079_JTMU7079_JTMU7079_JTMU7079_JTMU7079_JTMU7079_JTMU7079_JTMU7079_JTMU7079_JTMU7079_JTMU7079_JTMU7079_JTMU7079_JTMU7079_JTMU7079_JTMU7079_JTMU7079_JTMU7079_JTMU7079_JTMU7084_U_tj_in" />
  <child  link="JMM223_JTMU7079_JTMU7079_JTMU7079_JTMU7079_JTMU7079_JTMU7079_JTMU7079_JTMU7079_JTMU7079_JTMU7079_JTMU7079_JTMU7079_JTMU7079_JTMU7079_JTMU7079_JTMU7079_JTMU7079_JTMU7079_JTMU7079_JTMU7079_JTMU7079_JTMU7079_JTMU7079_IMU7208_U_ic_body" />
  <axis  xyz="0 0 0" />
 </joint>
 <joint  name="JMM223_JTMU7079_JTMU7079_JTMU7079_JTMU7079_JTMU7079_JTMU7079_JTMU7079_JTMU7079_JTMU7079_JTMU7079_JTMU7079_JTMU7079_JTMU7079_JTMU7079_JTMU7079_JTMU7079_JTMU7079_JTMU7079_JTMU7079_JTMU7079_JTMU7079_JTMU7079_JTMU7079_IMU7208_U_ic_medium_2"  type="fixed" >
  <origin  rpy="0 0 0"  xyz="0 0 -0.0094" />
  <parent  link="JMM223_JTMU7079_JTMU7079_JTMU7079_JTMU7079_JTMU7079_JTMU7079_JTMU7079_JTMU7079_JTMU7079_JTMU7079_JTMU7079_JTMU7079_JTMU7079_JTMU7079_JTMU7079_JTMU7079_JTMU7079_JTMU7079_JTMU7079_JTMU7079_JTMU7079_JTMU7079_JTMU7079_IMU7208_U_ic_body" />
  <child  link="JMM223_JTMU7079_JTMU7079_JTMU7079_JTMU7079_JTMU7079_JTMU7079_JTMU7079_JTMU7079_JTMU7079_JTMU7079_JTMU7079_JTMU7079_JTMU7079_JTMU7079_JTMU7079_JTMU7079_JTMU7079_JTMU7079_JTMU7079_JTMU7079_JTMU7079_JTMU7079_JTMU7079_IMU7208_U_ic_in" />
  <axis  xyz="0 0 0" />
 </joint>
 <joint  name="JMM223_JTMU7079_JTMU7079_JTMU7079_JTMU7079_JTMU7079_JTMU7079_JTMU7079_JTMU7079_JTMU7079_JTMU7079_JTMU7079_JTMU7079_JTMU7079_JTMU7079_JTMU7079_JTMU7079_JTMU7079_JTMU7079_JTMU7079_JTMU7079_JTMU7079_JTMU7079_JTMU7085_U_tj_medium_1"  type="revolute" >
  <origin  rpy="0.0 0.0 3.141592653589793"  xyz="0.0 0.0 0.0" />
  <parent  link="JMM223_JTMU7079_JTMU7079_JTMU7079_JTMU7079_JTMU7079_JTMU7079_JTMU7079_JTMU7079_JTMU7079_JTMU7079_JTMU7079_JTMU7079_JTMU7079_JTMU7079_JTMU7079_JTMU7079_JTMU7079_JTMU7079_JTMU7079_JTMU7079_JTMU7079_JTMU7079_JTMU7079_IMU7208_U_ic_in" />
  <child  link="JMM223_JTMU7079_JTMU7079_JTMU7079_JTMU7079_JTMU7079_JTMU7079_JTMU7079_JTMU7079_JTMU7079_JTMU7079_JTMU7079_JTMU7079_JTMU7079_JTMU7079_JTMU7079_JTMU7079_JTMU7079_JTMU7079_JTMU7079_JTMU7079_JTMU7079_JTMU7079_JTMU7085_U_tj_body" />
  <axis  xyz="0 0 1" />
  <limit  velocity="0.33"  upper="3.1416"  lower="-3.1416"  effort="25.5" />
 </joint>
 <joint  name="JMM223_JTMU7079_JTMU7079_JTMU7079_JTMU7079_JTMU7079_JTMU7079_JTMU7079_JTMU7079_JTMU7079_JTMU7079_JTMU7079_JTMU7079_JTMU7079_JTMU7079_JTMU7079_JTMU7079_JTMU7079_JTMU7079_JTMU7079_JTMU7079_JTMU7079_JTMU7079_JTMU7085_U_tj_medium_2"  type="fixed" >
  <origin  rpy="0 1.5707963267949 0"  xyz="-0.047 0 -0.0635" />
  <parent  link="JMM223_JTMU7079_JTMU7079_JTMU7079_JTMU7079_JTMU7079_JTMU7079_JTMU7079_JTMU7079_JTMU7079_JTMU7079_JTMU7079_JTMU7079_JTMU7079_JTMU7079_JTMU7079_JTMU7079_JTMU7079_JTMU7079_JTMU7079_JTMU7079_JTMU7079_JTMU7079_JTMU7085_U_tj_body" />
  <child  link="JMM223_JTMU7079_JTMU7079_JTMU7079_JTMU7079_JTMU7079_JTMU7079_JTMU7079_JTMU7079_JTMU7079_JTMU7079_JTMU7079_JTMU7079_JTMU7079_JTMU7079_JTMU7079_JTMU7079_JTMU7079_JTMU7079_JTMU7079_JTMU7079_JTMU7079_JTMU7079_JTMU7085_U_tj_in" />
  <axis  xyz="0 -1 0" />
 </joint>
 <joint  name="JMM223_JTMU7079_JTMU7079_JTMU7079_JTMU7079_JTMU7079_JTMU7079_JTMU7079_JTMU7079_JTMU7079_JTMU7079_JTMU7079_JTMU7079_JTMU7079_JTMU7079_JTMU7079_JTMU7079_JTMU7079_JTMU7079_JTMU7079_JTMU7079_JTMU7079_IMU7209_U_ic_medium_1"  type="fixed" >
  <origin  rpy="0 0 0"  xyz="0 0 0" />
  <parent  link="JMM223_JTMU7079_JTMU7079_JTMU7079_JTMU7079_JTMU7079_JTMU7079_JTMU7079_JTMU7079_JTMU7079_JTMU7079_JTMU7079_JTMU7079_JTMU7079_JTMU7079_JTMU7079_JTMU7079_JTMU7079_JTMU7079_JTMU7079_JTMU7079_JTMU7079_JTMU7079_JTMU7085_U_tj_in" />
  <child  link="JMM223_JTMU7079_JTMU7079_JTMU7079_JTMU7079_JTMU7079_JTMU7079_JTMU7079_JTMU7079_JTMU7079_JTMU7079_JTMU7079_JTMU7079_JTMU7079_JTMU7079_JTMU7079_JTMU7079_JTMU7079_JTMU7079_JTMU7079_JTMU7079_JTMU7079_IMU7209_U_ic_body" />
  <axis  xyz="0 0 0" />
 </joint>
 <joint  name="JMM223_JTMU7079_JTMU7079_JTMU7079_JTMU7079_JTMU7079_JTMU7079_JTMU7079_JTMU7079_JTMU7079_JTMU7079_JTMU7079_JTMU7079_JTMU7079_JTMU7079_JTMU7079_JTMU7079_JTMU7079_JTMU7079_JTMU7079_JTMU7079_JTMU7079_IMU7209_U_ic_medium_2"  type="fixed" >
  <origin  rpy="0 0 0"  xyz="0 0 -0.0094" />
  <parent  link="JMM223_JTMU7079_JTMU7079_JTMU7079_JTMU7079_JTMU7079_JTMU7079_JTMU7079_JTMU7079_JTMU7079_JTMU7079_JTMU7079_JTMU7079_JTMU7079_JTMU7079_JTMU7079_JTMU7079_JTMU7079_JTMU7079_JTMU7079_JTMU7079_JTMU7079_IMU7209_U_ic_body" />
  <child  link="JMM223_JTMU7079_JTMU7079_JTMU7079_JTMU7079_JTMU7079_JTMU7079_JTMU7079_JTMU7079_JTMU7079_JTMU7079_JTMU7079_JTMU7079_JTMU7079_JTMU7079_JTMU7079_JTMU7079_JTMU7079_JTMU7079_JTMU7079_JTMU7079_JTMU7079_IMU7209_U_ic_in" />
  <axis  xyz="0 0 0" />
 </joint>
 <joint  name="JMM223_JTMU7079_JTMU7079_JTMU7079_JTMU7079_JTMU7079_JTMU7079_JTMU7079_JTMU7079_JTMU7079_JTMU7079_JTMU7079_JTMU7079_JTMU7079_JTMU7079_JTMU7079_JTMU7079_JTMU7079_JTMU7079_JTMU7079_JTMU7079_JTMU7086_U_tj_medium_1"  type="revolute" >
  <origin  rpy="0.0 0.0 3.141592653589793"  xyz="0.0 0.0 0.0" />
  <parent  link="JMM223_JTMU7079_JTMU7079_JTMU7079_JTMU7079_JTMU7079_JTMU7079_JTMU7079_JTMU7079_JTMU7079_JTMU7079_JTMU7079_JTMU7079_JTMU7079_JTMU7079_JTMU7079_JTMU7079_JTMU7079_JTMU7079_JTMU7079_JTMU7079_JTMU7079_IMU7209_U_ic_in" />
  <child  link="JMM223_JTMU7079_JTMU7079_JTMU7079_JTMU7079_JTMU7079_JTMU7079_JTMU7079_JTMU7079_JTMU7079_JTMU7079_JTMU7079_JTMU7079_JTMU7079_JTMU7079_JTMU7079_JTMU7079_JTMU7079_JTMU7079_JTMU7079_JTMU7079_JTMU7086_U_tj_body" />
  <axis  xyz="0 0 1" />
  <limit  velocity="0.33"  upper="3.1416"  lower="-3.1416"  effort="25.5" />
 </joint>
 <joint  name="JMM223_JTMU7079_JTMU7079_JTMU7079_JTMU7079_JTMU7079_JTMU7079_JTMU7079_JTMU7079_JTMU7079_JTMU7079_JTMU7079_JTMU7079_JTMU7079_JTMU7079_JTMU7079_JTMU7079_JTMU7079_JTMU7079_JTMU7079_JTMU7079_JTMU7086_U_tj_medium_2"  type="fixed" >
  <origin  rpy="0 1.5707963267949 0"  xyz="-0.047 0 -0.0635" />
  <parent  link="JMM223_JTMU7079_JTMU7079_JTMU7079_JTMU7079_JTMU7079_JTMU7079_JTMU7079_JTMU7079_JTMU7079_JTMU7079_JTMU7079_JTMU7079_JTMU7079_JTMU7079_JTMU7079_JTMU7079_JTMU7079_JTMU7079_JTMU7079_JTMU7079_JTMU7086_U_tj_body" />
  <child  link="JMM223_JTMU7079_JTMU7079_JTMU7079_JTMU7079_JTMU7079_JTMU7079_JTMU7079_JTMU7079_JTMU7079_JTMU7079_JTMU7079_JTMU7079_JTMU7079_JTMU7079_JTMU7079_JTMU7079_JTMU7079_JTMU7079_JTMU7079_JTMU7079_JTMU7086_U_tj_in" />
  <axis  xyz="0 -1 0" />
 </joint>
 <joint  name="JMM223_JTMU7079_JTMU7079_JTMU7079_JTMU7079_JTMU7079_JTMU7079_JTMU7079_JTMU7079_JTMU7079_JTMU7079_JTMU7079_JTMU7079_JTMU7079_JTMU7079_JTMU7079_JTMU7079_JTMU7079_JTMU7079_JTMU7079_IMU7210_U_ic_medium_1"  type="fixed" >
  <origin  rpy="0 0 0"  xyz="0 0 0" />
  <parent  link="JMM223_JTMU7079_JTMU7079_JTMU7079_JTMU7079_JTMU7079_JTMU7079_JTMU7079_JTMU7079_JTMU7079_JTMU7079_JTMU7079_JTMU7079_JTMU7079_JTMU7079_JTMU7079_JTMU7079_JTMU7079_JTMU7079_JTMU7079_JTMU7079_JTMU7086_U_tj_in" />
  <child  link="JMM223_JTMU7079_JTMU7079_JTMU7079_JTMU7079_JTMU7079_JTMU7079_JTMU7079_JTMU7079_JTMU7079_JTMU7079_JTMU7079_JTMU7079_JTMU7079_JTMU7079_JTMU7079_JTMU7079_JTMU7079_JTMU7079_JTMU7079_IMU7210_U_ic_body" />
  <axis  xyz="0 0 0" />
 </joint>
 <joint  name="JMM223_JTMU7079_JTMU7079_JTMU7079_JTMU7079_JTMU7079_JTMU7079_JTMU7079_JTMU7079_JTMU7079_JTMU7079_JTMU7079_JTMU7079_JTMU7079_JTMU7079_JTMU7079_JTMU7079_JTMU7079_JTMU7079_JTMU7079_IMU7210_U_ic_medium_2"  type="fixed" >
  <origin  rpy="0 0 0"  xyz="0 0 -0.0094" />
  <parent  link="JMM223_JTMU7079_JTMU7079_JTMU7079_JTMU7079_JTMU7079_JTMU7079_JTMU7079_JTMU7079_JTMU7079_JTMU7079_JTMU7079_JTMU7079_JTMU7079_JTMU7079_JTMU7079_JTMU7079_JTMU7079_JTMU7079_JTMU7079_IMU7210_U_ic_body" />
  <child  link="JMM223_JTMU7079_JTMU7079_JTMU7079_JTMU7079_JTMU7079_JTMU7079_JTMU7079_JTMU7079_JTMU7079_JTMU7079_JTMU7079_JTMU7079_JTMU7079_JTMU7079_JTMU7079_JTMU7079_JTMU7079_JTMU7079_JTMU7079_IMU7210_U_ic_in" />
  <axis  xyz="0 0 0" />
 </joint>
 <joint  name="JMM223_JTMU7079_JTMU7079_JTMU7079_JTMU7079_JTMU7079_JTMU7079_JTMU7079_JTMU7079_JTMU7079_JTMU7079_JTMU7079_JTMU7079_JTMU7079_JTMU7079_JTMU7079_JTMU7079_JTMU7079_JTMU7079_JTMU7087_U_tj_medium_1"  type="revolute" >
  <origin  rpy="0.0 0.0 3.141592653589793"  xyz="0.0 0.0 0.0" />
  <parent  link="JMM223_JTMU7079_JTMU7079_JTMU7079_JTMU7079_JTMU7079_JTMU7079_JTMU7079_JTMU7079_JTMU7079_JTMU7079_JTMU7079_JTMU7079_JTMU7079_JTMU7079_JTMU7079_JTMU7079_JTMU7079_JTMU7079_JTMU7079_IMU7210_U_ic_in" />
  <child  link="JMM223_JTMU7079_JTMU7079_JTMU7079_JTMU7079_JTMU7079_JTMU7079_JTMU7079_JTMU7079_JTMU7079_JTMU7079_JTMU7079_JTMU7079_JTMU7079_JTMU7079_JTMU7079_JTMU7079_JTMU7079_JTMU7079_JTMU7087_U_tj_body" />
  <axis  xyz="0 0 1" />
  <limit  velocity="0.33"  upper="3.1416"  lower="-3.1416"  effort="25.5" />
 </joint>
 <joint  name="JMM223_JTMU7079_JTMU7079_JTMU7079_JTMU7079_JTMU7079_JTMU7079_JTMU7079_JTMU7079_JTMU7079_JTMU7079_JTMU7079_JTMU7079_JTMU7079_JTMU7079_JTMU7079_JTMU7079_JTMU7079_JTMU7079_JTMU7087_U_tj_medium_2"  type="fixed" >
  <origin  rpy="0 1.5707963267949 0"  xyz="-0.047 0 -0.0635" />
  <parent  link="JMM223_JTMU7079_JTMU7079_JTMU7079_JTMU7079_JTMU7079_JTMU7079_JTMU7079_JTMU7079_JTMU7079_JTMU7079_JTMU7079_JTMU7079_JTMU7079_JTMU7079_JTMU7079_JTMU7079_JTMU7079_JTMU7079_JTMU7087_U_tj_body" />
  <child  link="JMM223_JTMU7079_JTMU7079_JTMU7079_JTMU7079_JTMU7079_JTMU7079_JTMU7079_JTMU7079_JTMU7079_JTMU7079_JTMU7079_JTMU7079_JTMU7079_JTMU7079_JTMU7079_JTMU7079_JTMU7079_JTMU7079_JTMU7087_U_tj_in" />
  <axis  xyz="0 -1 0" />
 </joint>
 <joint  name="JMM223_JTMU7079_JTMU7079_JTMU7079_JTMU7079_JTMU7079_JTMU7079_JTMU7079_JTMU7079_JTMU7079_JTMU7079_JTMU7079_JTMU7079_JTMU7079_JTMU7079_JTMU7079_JTMU7079_JTMU7079_IMU7211_U_ic_medium_1"  type="fixed" >
  <origin  rpy="0 0 0"  xyz="0 0 0" />
  <parent  link="JMM223_JTMU7079_JTMU7079_JTMU7079_JTMU7079_JTMU7079_JTMU7079_JTMU7079_JTMU7079_JTMU7079_JTMU7079_JTMU7079_JTMU7079_JTMU7079_JTMU7079_JTMU7079_JTMU7079_JTMU7079_JTMU7079_JTMU7087_U_tj_in" />
  <child  link="JMM223_JTMU7079_JTMU7079_JTMU7079_JTMU7079_JTMU7079_JTMU7079_JTMU7079_JTMU7079_JTMU7079_JTMU7079_JTMU7079_JTMU7079_JTMU7079_JTMU7079_JTMU7079_JTMU7079_JTMU7079_IMU7211_U_ic_body" />
  <axis  xyz="0 0 0" />
 </joint>
 <joint  name="JMM223_JTMU7079_JTMU7079_JTMU7079_JTMU7079_JTMU7079_JTMU7079_JTMU7079_JTMU7079_JTMU7079_JTMU7079_JTMU7079_JTMU7079_JTMU7079_JTMU7079_JTMU7079_JTMU7079_JTMU7079_IMU7211_U_ic_medium_2"  type="fixed" >
  <origin  rpy="0 0 0"  xyz="0 0 -0.0094" />
  <parent  link="JMM223_JTMU7079_JTMU7079_JTMU7079_JTMU7079_JTMU7079_JTMU7079_JTMU7079_JTMU7079_JTMU7079_JTMU7079_JTMU7079_JTMU7079_JTMU7079_JTMU7079_JTMU7079_JTMU7079_JTMU7079_IMU7211_U_ic_body" />
  <child  link="JMM223_JTMU7079_JTMU7079_JTMU7079_JTMU7079_JTMU7079_JTMU7079_JTMU7079_JTMU7079_JTMU7079_JTMU7079_JTMU7079_JTMU7079_JTMU7079_JTMU7079_JTMU7079_JTMU7079_JTMU7079_IMU7211_U_ic_in" />
  <axis  xyz="0 0 0" />
 </joint>
 <joint  name="JMM223_JTMU7079_JTMU7079_JTMU7079_JTMU7079_JTMU7079_JTMU7079_JTMU7079_JTMU7079_JTMU7079_JTMU7079_JTMU7079_JTMU7079_JTMU7079_JTMU7079_JTMU7079_JTMU7079_JTMU7088_U_tj_medium_1"  type="revolute" >
  <origin  rpy="0.0 0.0 3.141592653589793"  xyz="0.0 0.0 0.0" />
  <parent  link="JMM223_JTMU7079_JTMU7079_JTMU7079_JTMU7079_JTMU7079_JTMU7079_JTMU7079_JTMU7079_JTMU7079_JTMU7079_JTMU7079_JTMU7079_JTMU7079_JTMU7079_JTMU7079_JTMU7079_JTMU7079_IMU7211_U_ic_in" />
  <child  link="JMM223_JTMU7079_JTMU7079_JTMU7079_JTMU7079_JTMU7079_JTMU7079_JTMU7079_JTMU7079_JTMU7079_JTMU7079_JTMU7079_JTMU7079_JTMU7079_JTMU7079_JTMU7079_JTMU7079_JTMU7088_U_tj_body" />
  <axis  xyz="0 0 1" />
  <limit  velocity="0.33"  upper="3.1416"  lower="-3.1416"  effort="25.5" />
 </joint>
 <joint  name="JMM223_JTMU7079_JTMU7079_JTMU7079_JTMU7079_JTMU7079_JTMU7079_JTMU7079_JTMU7079_JTMU7079_JTMU7079_JTMU7079_JTMU7079_JTMU7079_JTMU7079_JTMU7079_JTMU7079_JTMU7088_U_tj_medium_2"  type="fixed" >
  <origin  rpy="0 1.5707963267949 0"  xyz="-0.047 0 -0.0635" />
  <parent  link="JMM223_JTMU7079_JTMU7079_JTMU7079_JTMU7079_JTMU7079_JTMU7079_JTMU7079_JTMU7079_JTMU7079_JTMU7079_JTMU7079_JTMU7079_JTMU7079_JTMU7079_JTMU7079_JTMU7079_JTMU7088_U_tj_body" />
  <child  link="JMM223_JTMU7079_JTMU7079_JTMU7079_JTMU7079_JTMU7079_JTMU7079_JTMU7079_JTMU7079_JTMU7079_JTMU7079_JTMU7079_JTMU7079_JTMU7079_JTMU7079_JTMU7079_JTMU7079_JTMU7088_U_tj_in" />
  <axis  xyz="0 -1 0" />
 </joint>
 <joint  name="JMM223_JTMU7079_JTMU7079_JTMU7079_JTMU7079_JTMU7079_JTMU7079_JTMU7079_JTMU7079_JTMU7079_JTMU7079_JTMU7079_JTMU7079_JTMU7079_JTMU7079_JTMU7079_IMU7212_U_ic_medium_1"  type="fixed" >
  <origin  rpy="0 0 0"  xyz="0 0 0" />
  <parent  link="JMM223_JTMU7079_JTMU7079_JTMU7079_JTMU7079_JTMU7079_JTMU7079_JTMU7079_JTMU7079_JTMU7079_JTMU7079_JTMU7079_JTMU7079_JTMU7079_JTMU7079_JTMU7079_JTMU7079_JTMU7088_U_tj_in" />
  <child  link="JMM223_JTMU7079_JTMU7079_JTMU7079_JTMU7079_JTMU7079_JTMU7079_JTMU7079_JTMU7079_JTMU7079_JTMU7079_JTMU7079_JTMU7079_JTMU7079_JTMU7079_JTMU7079_IMU7212_U_ic_body" />
  <axis  xyz="0 0 0" />
 </joint>
 <joint  name="JMM223_JTMU7079_JTMU7079_JTMU7079_JTMU7079_JTMU7079_JTMU7079_JTMU7079_JTMU7079_JTMU7079_JTMU7079_JTMU7079_JTMU7079_JTMU7079_JTMU7079_JTMU7079_IMU7212_U_ic_medium_2"  type="fixed" >
  <origin  rpy="0 0 0"  xyz="0 0 -0.0094" />
  <parent  link="JMM223_JTMU7079_JTMU7079_JTMU7079_JTMU7079_JTMU7079_JTMU7079_JTMU7079_JTMU7079_JTMU7079_JTMU7079_JTMU7079_JTMU7079_JTMU7079_JTMU7079_JTMU7079_IMU7212_U_ic_body" />
  <child  link="JMM223_JTMU7079_JTMU7079_JTMU7079_JTMU7079_JTMU7079_JTMU7079_JTMU7079_JTMU7079_JTMU7079_JTMU7079_JTMU7079_JTMU7079_JTMU7079_JTMU7079_JTMU7079_IMU7212_U_ic_in" />
  <axis  xyz="0 0 0" />
 </joint>
 <joint  name="JMM223_JTMU7079_JTMU7079_JTMU7079_JTMU7079_JTMU7079_JTMU7079_JTMU7079_JTMU7079_JTMU7079_JTMU7079_JTMU7079_JTMU7079_JTMU7079_JTMU7079_JTMU7089_U_tj_medium_1"  type="revolute" >
  <origin  rpy="0.0 0.0 3.141592653589793"  xyz="0.0 0.0 0.0" />
  <parent  link="JMM223_JTMU7079_JTMU7079_JTMU7079_JTMU7079_JTMU7079_JTMU7079_JTMU7079_JTMU7079_JTMU7079_JTMU7079_JTMU7079_JTMU7079_JTMU7079_JTMU7079_JTMU7079_IMU7212_U_ic_in" />
  <child  link="JMM223_JTMU7079_JTMU7079_JTMU7079_JTMU7079_JTMU7079_JTMU7079_JTMU7079_JTMU7079_JTMU7079_JTMU7079_JTMU7079_JTMU7079_JTMU7079_JTMU7079_JTMU7089_U_tj_body" />
  <axis  xyz="0 0 1" />
  <limit  velocity="0.33"  upper="3.1416"  lower="-3.1416"  effort="25.5" />
 </joint>
 <joint  name="JMM223_JTMU7079_JTMU7079_JTMU7079_JTMU7079_JTMU7079_JTMU7079_JTMU7079_JTMU7079_JTMU7079_JTMU7079_JTMU7079_JTMU7079_JTMU7079_JTMU7079_JTMU7089_U_tj_medium_2"  type="fixed" >
  <origin  rpy="0 1.5707963267949 0"  xyz="-0.047 0 -0.0635" />
  <parent  link="JMM223_JTMU7079_JTMU7079_JTMU7079_JTMU7079_JTMU7079_JTMU7079_JTMU7079_JTMU7079_JTMU7079_JTMU7079_JTMU7079_JTMU7079_JTMU7079_JTMU7079_JTMU7089_U_tj_body" />
  <child  link="JMM223_JTMU7079_JTMU7079_JTMU7079_JTMU7079_JTMU7079_JTMU7079_JTMU7079_JTMU7079_JTMU7079_JTMU7079_JTMU7079_JTMU7079_JTMU7079_JTMU7079_JTMU7089_U_tj_in" />
  <axis  xyz="0 -1 0" />
 </joint>
 <joint  name="JMM223_JTMU7079_JTMU7079_JTMU7079_JTMU7079_JTMU7079_JTMU7079_JTMU7079_JTMU7079_JTMU7079_JTMU7079_JTMU7079_JTMU7079_JTMU7079_IMU7213_U_ic_medium_1"  type="fixed" >
  <origin  rpy="0 0 0"  xyz="0 0 0" />
  <parent  link="JMM223_JTMU7079_JTMU7079_JTMU7079_JTMU7079_JTMU7079_JTMU7079_JTMU7079_JTMU7079_JTMU7079_JTMU7079_JTMU7079_JTMU7079_JTMU7079_JTMU7079_JTMU7089_U_tj_in" />
  <child  link="JMM223_JTMU7079_JTMU7079_JTMU7079_JTMU7079_JTMU7079_JTMU7079_JTMU7079_JTMU7079_JTMU7079_JTMU7079_JTMU7079_JTMU7079_JTMU7079_IMU7213_U_ic_body" />
  <axis  xyz="0 0 0" />
 </joint>
 <joint  name="JMM223_JTMU7079_JTMU7079_JTMU7079_JTMU7079_JTMU7079_JTMU7079_JTMU7079_JTMU7079_JTMU7079_JTMU7079_JTMU7079_JTMU7079_JTMU7079_IMU7213_U_ic_medium_2"  type="fixed" >
  <origin  rpy="0 0 0"  xyz="0 0 -0.0094" />
  <parent  link="JMM223_JTMU7079_JTMU7079_JTMU7079_JTMU7079_JTMU7079_JTMU7079_JTMU7079_JTMU7079_JTMU7079_JTMU7079_JTMU7079_JTMU7079_JTMU7079_IMU7213_U_ic_body" />
  <child  link="JMM223_JTMU7079_JTMU7079_JTMU7079_JTMU7079_JTMU7079_JTMU7079_JTMU7079_JTMU7079_JTMU7079_JTMU7079_JTMU7079_JTMU7079_JTMU7079_IMU7213_U_ic_in" />
  <axis  xyz="0 0 0" />
 </joint>
 <joint  name="JMM223_JTMU7079_JTMU7079_JTMU7079_JTMU7079_JTMU7079_JTMU7079_JTMU7079_JTMU7079_JTMU7079_JTMU7079_JTMU7079_JTMU7079_JTMU7090_U_tj_medium_1"  type="revolute" >
  <origin  rpy="0.0 0.0 3.141592653589793"  xyz="0.0 0.0 0.0" />
  <parent  link="JMM223_JTMU7079_JTMU7079_JTMU7079_JTMU7079_JTMU7079_JTMU7079_JTMU7079_JTMU7079_JTMU7079_JTMU7079_JTMU7079_JTMU7079_JTMU7079_IMU7213_U_ic_in" />
  <child  link="JMM223_JTMU7079_JTMU7079_JTMU7079_JTMU7079_JTMU7079_JTMU7079_JTMU7079_JTMU7079_JTMU7079_JTMU7079_JTMU7079_JTMU7079_JTMU7090_U_tj_body" />
  <axis  xyz="0 0 1" />
  <limit  velocity="0.33"  upper="3.1416"  lower="-3.1416"  effort="25.5" />
 </joint>
 <joint  name="JMM223_JTMU7079_JTMU7079_JTMU7079_JTMU7079_JTMU7079_JTMU7079_JTMU7079_JTMU7079_JTMU7079_JTMU7079_JTMU7079_JTMU7079_JTMU7090_U_tj_medium_2"  type="fixed" >
  <origin  rpy="0 1.5707963267949 0"  xyz="-0.047 0 -0.0635" />
  <parent  link="JMM223_JTMU7079_JTMU7079_JTMU7079_JTMU7079_JTMU7079_JTMU7079_JTMU7079_JTMU7079_JTMU7079_JTMU7079_JTMU7079_JTMU7079_JTMU7090_U_tj_body" />
  <child  link="JMM223_JTMU7079_JTMU7079_JTMU7079_JTMU7079_JTMU7079_JTMU7079_JTMU7079_JTMU7079_JTMU7079_JTMU7079_JTMU7079_JTMU7079_JTMU7090_U_tj_in" />
  <axis  xyz="0 -1 0" />
 </joint>
 <joint  name="JMM223_JTMU7079_JTMU7079_JTMU7079_JTMU7079_JTMU7079_JTMU7079_JTMU7079_JTMU7079_JTMU7079_JTMU7079_JTMU7079_IMU7214_U_ic_medium_1"  type="fixed" >
  <origin  rpy="0 0 0"  xyz="0 0 0" />
  <parent  link="JMM223_JTMU7079_JTMU7079_JTMU7079_JTMU7079_JTMU7079_JTMU7079_JTMU7079_JTMU7079_JTMU7079_JTMU7079_JTMU7079_JTMU7079_JTMU7090_U_tj_in" />
  <child  link="JMM223_JTMU7079_JTMU7079_JTMU7079_JTMU7079_JTMU7079_JTMU7079_JTMU7079_JTMU7079_JTMU7079_JTMU7079_JTMU7079_IMU7214_U_ic_body" />
  <axis  xyz="0 0 0" />
 </joint>
 <joint  name="JMM223_JTMU7079_JTMU7079_JTMU7079_JTMU7079_JTMU7079_JTMU7079_JTMU7079_JTMU7079_JTMU7079_JTMU7079_JTMU7079_IMU7214_U_ic_medium_2"  type="fixed" >
  <origin  rpy="0 0 0"  xyz="0 0 -0.0094" />
  <parent  link="JMM223_JTMU7079_JTMU7079_JTMU7079_JTMU7079_JTMU7079_JTMU7079_JTMU7079_JTMU7079_JTMU7079_JTMU7079_JTMU7079_IMU7214_U_ic_body" />
  <child  link="JMM223_JTMU7079_JTMU7079_JTMU7079_JTMU7079_JTMU7079_JTMU7079_JTMU7079_JTMU7079_JTMU7079_JTMU7079_JTMU7079_IMU7214_U_ic_in" />
  <axis  xyz="0 0 0" />
 </joint>
 <joint  name="JMM223_JTMU7079_JTMU7079_JTMU7079_JTMU7079_JTMU7079_JTMU7079_JTMU7079_JTMU7079_JTMU7079_JTMU7079_JTMU7091_U_tj_medium_1"  type="revolute" >
  <origin  rpy="0.0 0.0 3.141592653589793"  xyz="0.0 0.0 0.0" />
  <parent  link="JMM223_JTMU7079_JTMU7079_JTMU7079_JTMU7079_JTMU7079_JTMU7079_JTMU7079_JTMU7079_JTMU7079_JTMU7079_JTMU7079_IMU7214_U_ic_in" />
  <child  link="JMM223_JTMU7079_JTMU7079_JTMU7079_JTMU7079_JTMU7079_JTMU7079_JTMU7079_JTMU7079_JTMU7079_JTMU7079_JTMU7091_U_tj_body" />
  <axis  xyz="0 0 1" />
  <limit  velocity="0.33"  upper="3.1416"  lower="-3.1416"  effort="25.5" />
 </joint>
 <joint  name="JMM223_JTMU7079_JTMU7079_JTMU7079_JTMU7079_JTMU7079_JTMU7079_JTMU7079_JTMU7079_JTMU7079_JTMU7079_JTMU7091_U_tj_medium_2"  type="fixed" >
  <origin  rpy="0 1.5707963267949 0"  xyz="-0.047 0 -0.0635" />
  <parent  link="JMM223_JTMU7079_JTMU7079_JTMU7079_JTMU7079_JTMU7079_JTMU7079_JTMU7079_JTMU7079_JTMU7079_JTMU7079_JTMU7091_U_tj_body" />
  <child  link="JMM223_JTMU7079_JTMU7079_JTMU7079_JTMU7079_JTMU7079_JTMU7079_JTMU7079_JTMU7079_JTMU7079_JTMU7079_JTMU7091_U_tj_in" />
  <axis  xyz="0 -1 0" />
 </joint>
 <joint  name="JMM223_JTMU7079_JTMU7079_JTMU7079_JTMU7079_JTMU7079_JTMU7079_JTMU7079_JTMU7079_JTMU7079_IMU7215_U_ic_medium_1"  type="fixed" >
  <origin  rpy="0 0 0"  xyz="0 0 0" />
  <parent  link="JMM223_JTMU7079_JTMU7079_JTMU7079_JTMU7079_JTMU7079_JTMU7079_JTMU7079_JTMU7079_JTMU7079_JTMU7079_JTMU7091_U_tj_in" />
  <child  link="JMM223_JTMU7079_JTMU7079_JTMU7079_JTMU7079_JTMU7079_JTMU7079_JTMU7079_JTMU7079_JTMU7079_IMU7215_U_ic_body" />
  <axis  xyz="0 0 0" />
 </joint>
 <joint  name="JMM223_JTMU7079_JTMU7079_JTMU7079_JTMU7079_JTMU7079_JTMU7079_JTMU7079_JTMU7079_JTMU7079_IMU7215_U_ic_medium_2"  type="fixed" >
  <origin  rpy="0 0 0"  xyz="0 0 -0.0094" />
  <parent  link="JMM223_JTMU7079_JTMU7079_JTMU7079_JTMU7079_JTMU7079_JTMU7079_JTMU7079_JTMU7079_JTMU7079_IMU7215_U_ic_body" />
  <child  link="JMM223_JTMU7079_JTMU7079_JTMU7079_JTMU7079_JTMU7079_JTMU7079_JTMU7079_JTMU7079_JTMU7079_IMU7215_U_ic_in" />
  <axis  xyz="0 0 0" />
 </joint>
 <joint  name="JMM223_JTMU7079_JTMU7079_JTMU7079_JTMU7079_JTMU7079_JTMU7079_JTMU7079_JTMU7079_JTMU7092_U_tj_medium_1"  type="revolute" >
  <origin  rpy="0.0 0.0 3.141592653589793"  xyz="0.0 0.0 0.0" />
  <parent  link="JMM223_JTMU7079_JTMU7079_JTMU7079_JTMU7079_JTMU7079_JTMU7079_JTMU7079_JTMU7079_JTMU7079_IMU7215_U_ic_in" />
  <child  link="JMM223_JTMU7079_JTMU7079_JTMU7079_JTMU7079_JTMU7079_JTMU7079_JTMU7079_JTMU7079_JTMU7092_U_tj_body" />
  <axis  xyz="0 0 1" />
  <limit  velocity="0.33"  upper="3.1416"  lower="-3.1416"  effort="25.5" />
 </joint>
 <joint  name="JMM223_JTMU7079_JTMU7079_JTMU7079_JTMU7079_JTMU7079_JTMU7079_JTMU7079_JTMU7079_JTMU7092_U_tj_medium_2"  type="fixed" >
  <origin  rpy="0 1.5707963267949 0"  xyz="-0.047 0 -0.0635" />
  <parent  link="JMM223_JTMU7079_JTMU7079_JTMU7079_JTMU7079_JTMU7079_JTMU7079_JTMU7079_JTMU7079_JTMU7092_U_tj_body" />
  <child  link="JMM223_JTMU7079_JTMU7079_JTMU7079_JTMU7079_JTMU7079_JTMU7079_JTMU7079_JTMU7079_JTMU7092_U_tj_in" />
  <axis  xyz="0 -1 0" />
 </joint>
 <joint  name="JMM223_JTMU7079_JTMU7079_JTMU7079_JTMU7079_JTMU7079_JTMU7079_JTMU7079_IMU7216_U_ic_medium_1"  type="fixed" >
  <origin  rpy="0 0 0"  xyz="0 0 0" />
  <parent  link="JMM223_JTMU7079_JTMU7079_JTMU7079_JTMU7079_JTMU7079_JTMU7079_JTMU7079_JTMU7079_JTMU7092_U_tj_in" />
  <child  link="JMM223_JTMU7079_JTMU7079_JTMU7079_JTMU7079_JTMU7079_JTMU7079_JTMU7079_IMU7216_U_ic_body" />
  <axis  xyz="0 0 0" />
 </joint>
 <joint  name="JMM223_JTMU7079_JTMU7079_JTMU7079_JTMU7079_JTMU7079_JTMU7079_JTMU7079_IMU7216_U_ic_medium_2"  type="fixed" >
  <origin  rpy="0 0 0"  xyz="0 0 -0.0094" />
  <parent  link="JMM223_JTMU7079_JTMU7079_JTMU7079_JTMU7079_JTMU7079_JTMU7079_JTMU7079_IMU7216_U_ic_body" />
  <child  link="JMM223_JTMU7079_JTMU7079_JTMU7079_JTMU7079_JTMU7079_JTMU7079_JTMU7079_IMU7216_U_ic_in" />
  <axis  xyz="0 0 0" />
 </joint>
 <joint  name="JMM223_JTMU7079_JTMU7079_JTMU7079_JTMU7079_JTMU7079_JTMU7079_JTMU7093_U_tj_medium_1"  type="revolute" >
  <origin  rpy="0.0 0.0 3.141592653589793"  xyz="0.0 0.0 0.0" />
  <parent  link="JMM223_JTMU7079_JTMU7079_JTMU7079_JTMU7079_JTMU7079_JTMU7079_JTMU7079_IMU7216_U_ic_in" />
  <child  link="JMM223_JTMU7079_JTMU7079_JTMU7079_JTMU7079_JTMU7079_JTMU7079_JTMU7093_U_tj_body" />
  <axis  xyz="0 0 1" />
  <limit  velocity="0.33"  upper="3.1416"  lower="-3.1416"  effort="25.5" />
 </joint>
 <joint  name="JMM223_JTMU7079_JTMU7079_JTMU7079_JTMU7079_JTMU7079_JTMU7079_JTMU7093_U_tj_medium_2"  type="fixed" >
  <origin  rpy="0 1.5707963267949 0"  xyz="-0.047 0 -0.0635" />
  <parent  link="JMM223_JTMU7079_JTMU7079_JTMU7079_JTMU7079_JTMU7079_JTMU7079_JTMU7093_U_tj_body" />
  <child  link="JMM223_JTMU7079_JTMU7079_JTMU7079_JTMU7079_JTMU7079_JTMU7079_JTMU7093_U_tj_in" />
  <axis  xyz="0 -1 0" />
 </joint>
 <joint  name="JMM223_JTMU7079_JTMU7079_JTMU7079_JTMU7079_JTMU7079_IMU7217_U_ic_medium_1"  type="fixed" >
  <origin  rpy="0 0 0"  xyz="0 0 0" />
  <parent  link="JMM223_JTMU7079_JTMU7079_JTMU7079_JTMU7079_JTMU7079_JTMU7079_JTMU7093_U_tj_in" />
  <child  link="JMM223_JTMU7079_JTMU7079_JTMU7079_JTMU7079_JTMU7079_IMU7217_U_ic_body" />
  <axis  xyz="0 0 0" />
 </joint>
 <joint  name="JMM223_JTMU7079_JTMU7079_JTMU7079_JTMU7079_JTMU7079_IMU7217_U_ic_medium_2"  type="fixed" >
  <origin  rpy="0 0 0"  xyz="0 0 -0.0094" />
  <parent  link="JMM223_JTMU7079_JTMU7079_JTMU7079_JTMU7079_JTMU7079_IMU7217_U_ic_body" />
  <child  link="JMM223_JTMU7079_JTMU7079_JTMU7079_JTMU7079_JTMU7079_IMU7217_U_ic_in" />
  <axis  xyz="0 0 0" />
 </joint>
 <joint  name="JMM223_JTMU7079_JTMU7079_JTMU7079_JTMU7079_JTMU7094_U_tj_medium_1"  type="revolute" >
  <origin  rpy="0.0 0.0 3.141592653589793"  xyz="0.0 0.0 0.0" />
  <parent  link="JMM223_JTMU7079_JTMU7079_JTMU7079_JTMU7079_JTMU7079_IMU7217_U_ic_in" />
  <child  link="JMM223_JTMU7079_JTMU7079_JTMU7079_JTMU7079_JTMU7094_U_tj_body" />
  <axis  xyz="0 0 1" />
  <limit  velocity="0.33"  upper="3.1416"  lower="-3.1416"  effort="25.5" />
 </joint>
 <joint  name="JMM223_JTMU7079_JTMU7079_JTMU7079_JTMU7079_JTMU7094_U_tj_medium_2"  type="fixed" >
  <origin  rpy="0 1.5707963267949 0"  xyz="-0.047 0 -0.0635" />
  <parent  link="JMM223_JTMU7079_JTMU7079_JTMU7079_JTMU7079_JTMU7094_U_tj_body" />
  <child  link="JMM223_JTMU7079_JTMU7079_JTMU7079_JTMU7079_JTMU7094_U_tj_in" />
  <axis  xyz="0 -1 0" />
 </joint>
 <joint  name="JMM223_JTMU7079_JTMU7079_JTMU7079_IMU7218_U_ic_medium_1"  type="fixed" >
  <origin  rpy="0 0 0"  xyz="0 0 0" />
  <parent  link="JMM223_JTMU7079_JTMU7079_JTMU7079_JTMU7079_JTMU7094_U_tj_in" />
  <child  link="JMM223_JTMU7079_JTMU7079_JTMU7079_IMU7218_U_ic_body" />
  <axis  xyz="0 0 0" />
 </joint>
 <joint  name="JMM223_JTMU7079_JTMU7079_JTMU7079_IMU7218_U_ic_medium_2"  type="fixed" >
  <origin  rpy="0 0 0"  xyz="0 0 -0.0094" />
  <parent  link="JMM223_JTMU7079_JTMU7079_JTMU7079_IMU7218_U_ic_body" />
  <child  link="JMM223_JTMU7079_JTMU7079_JTMU7079_IMU7218_U_ic_in" />
  <axis  xyz="0 0 0" />
 </joint>
 <joint  name="JMM223_JTMU7079_JTMU7079_JTMU7095_U_tj_medium_1"  type="revolute" >
  <origin  rpy="0.0 0.0 3.141592653589793"  xyz="0.0 0.0 0.0" />
  <parent  link="JMM223_JTMU7079_JTMU7079_JTMU7079_IMU7218_U_ic_in" />
  <child  link="JMM223_JTMU7079_JTMU7079_JTMU7095_U_tj_body" />
  <axis  xyz="0 0 1" />
  <limit  velocity="0.33"  upper="3.1416"  lower="-3.1416"  effort="25.5" />
 </joint>
 <joint  name="JMM223_JTMU7079_JTMU7079_JTMU7095_U_tj_medium_2"  type="fixed" >
  <origin  rpy="0 1.5707963267949 0"  xyz="-0.047 0 -0.0635" />
  <parent  link="JMM223_JTMU7079_JTMU7079_JTMU7095_U_tj_body" />
  <child  link="JMM223_JTMU7079_JTMU7079_JTMU7095_U_tj_in" />
  <axis  xyz="0 -1 0" />
 </joint>
 <joint  name="JMM223_JTMU7079_IMU7219_U_ic_medium_1"  type="fixed" >
  <origin  rpy="0 0 0"  xyz="0 0 0" />
  <parent  link="JMM223_JTMU7079_JTMU7079_JTMU7095_U_tj_in" />
  <child  link="JMM223_JTMU7079_IMU7219_U_ic_body" />
  <axis  xyz="0 0 0" />
 </joint>
 <joint  name="JMM223_JTMU7079_IMU7219_U_ic_medium_2"  type="fixed" >
  <origin  rpy="0 0 0"  xyz="0 0 -0.0094" />
  <parent  link="JMM223_JTMU7079_IMU7219_U_ic_body" />
  <child  link="JMM223_JTMU7079_IMU7219_U_ic_in" />
  <axis  xyz="0 0 0" />
 </joint>
</robot>
